Workbook

Sheet EREDMÉNYEK
B1: January | C1: April | D1: July | E1: October | M1: parfumes: | S1: small luxury
A2: all the data | M2: cosmetics | S2: =AVERAGE(N1:Q6) -> #DIV/0!
A3: skkirt lengths | M3: lipstick
M4: lotions (skin care, hand creams)
M5: nail polist,
M6: candles
M8: bags | S8: high luxury
M9: watches | S9: =AVERAGE(N8:Q13) -> #DIV/0!
M10: dining
M11: jewellery
M12: travel
M13: hats
G15: hemline index
B16: =AVERAGE(#REF!) -> #REF! | C16: =AVERAGE(#REF!) -> #REF! | D16: =AVERAGE(#REF!) -> #REF! | E16: =AVERAGE(#REF!) -> #REF! | G16: =AVERAGE(B16:E16) -> #REF!
A22: HEMLINE INDEX | N22: LIPSTICK INDEX
C23: Reversed | O23: HIGH | P23: LOW | AA23: Subtracting low luxuries from high value luxuries
A24: 1952 | B24: =VALUE('1952'!G22) -> 4.25 | C24: =VALUE(6-B24) -> 1.75 | N24: 1952 | O24: =VALUE('1952'!S9) -> 21 | P24: =VALUE('1952'!S2) -> 1 | AA24: 1952 | AB24: =VALUE(O24-P24) -> 20
A25: 1953 | B25: =VALUE('1953'!G16) -> 4.2361111 | C25: =VALUE(6-B25) -> 1.7638889 | N25: 1953 | O25: =VALUE('1953'!S9) -> 25 | P25: =VALUE('1953'!S2) -> 0 | AA25: 1953 | AB25: =VALUE(O25-P25) -> 25
A26: 1954 | B26: =VALUE('1954'!G15) -> 4.0416667 | C26: =VALUE(6-B26) -> 1.9583333 | N26: 1954 | O26: =VALUE('1954'!S9) -> 8 | P26: =VALUE('1954'!S2) -> 0 | AA26: 1954 | AB26: =VALUE(O26-P26) -> 8
A27: 1955 | B27: =VALUE('1955'!G28) -> 3.4583333 | C27: =VALUE(6-B27) -> 2.5416667 | N27: 1955 | O27: =VALUE('1955'!S9) -> 5 | P27: =VALUE('1955'!S2) -> 0 | AA27: 1955 | AB27: =VALUE(O27-P27) -> 5
A28: 1956 | B28: =VALUE('1956'!G24) -> 4.0567669 | C28: =VALUE(6-B28) -> 1.9432331 | N28: 1956 | O28: =VALUE('1956'!S9) -> 35 | P28: =VALUE('1956'!S2) -> 2 | AA28: 1956 | AB28: =VALUE(O28-P28) -> 33
A29: 1957 | B29: =VALUE('1957'!G38) -> 3.9179864 | C29: =VALUE(6-B29) -> 2.0820136 | N29: 1957 | O29: =VALUE('1957'!S9) -> 37 | P29: =VALUE('1957'!S2) -> 4 | AA29: 1957 | AB29: =VALUE(O29-P29) -> 33
A30: 1958 | B30: =VALUE('1958'!G24) -> 3.5504386 | C30: =VALUE(6-B30) -> 2.4495614 | N30: 1958 | O30: =VALUE('1958'!S9) -> 33 | P30: =VALUE('1958'!S2) -> 3 | AA30: 1958 | AB30: =VALUE(O30-P30) -> 30
A31: 1959 | B31: =VALUE('1959'!G30) -> 3.7306498 | C31: =VALUE(6-B31) -> 2.2693502 | N31: 1959 | O31: =VALUE('1959'!S9) -> 35 | P31: =VALUE('1959'!S2) -> 1 | AA31: 1959 | AB31: =VALUE(O31-P31) -> 34
A32: 1960 | B32: =VALUE('1960'!G27) -> 3.5606625 | C32: =VALUE(6-B32) -> 2.4393375 | N32: 1960 | O32: =VALUE('1960'!S9) -> 22 | P32: =VALUE('1960'!S2) -> 1 | AA32: 1960 | AB32: =VALUE(O32-P32) -> 21
A33: 1961 | B33: =VALUE('1961'!G28) -> 3.4319048 | C33: =VALUE(6-B33) -> 2.5680952 | N33: 1961 | O33: =VALUE('1961'!S9) -> 23 | P33: =VALUE('1961'!S2) -> 0 | AA33: 1961 | AB33: =VALUE(O33-P33) -> 23
A34: 1962 | B34: =VALUE('1962'!G18) -> 3.5104167 | C34: =VALUE(6-B34) -> 2.4895833 | N34: 1962 | O34: =VALUE('1962'!S9) -> 20 | P34: =VALUE('1962'!S2) -> 0 | AA34: 1962 | AB34: =VALUE(O34-P34) -> 20
A35: 1963 | B35: =VALUE('1963'!G15) -> 3.3847403 | C35: =VALUE(6-B35) -> 2.6152597 | N35: 1963 | O35: =VALUE('1963'!S9) -> 45 | P35: =VALUE('1963'!S2) -> 0 | AA35: 1963 | AB35: =VALUE(O35-P35) -> 45
A36: 1964 | B36: =VALUE('1964'!G22) -> 3.6805556 | C36: =VALUE(6-B36) -> 2.3194444 | N36: 1964 | O36: =VALUE('1964'!S9) -> 44 | P36: =VALUE('1964'!S2) -> 1 | AA36: 1964 | AB36: =VALUE(O36-P36) -> 43
A37: 1965 | B37: =VALUE('1965'!G16) -> 3.296131 | C37: =VALUE(6-B37) -> 2.703869 | N37: 1965 | O37: =VALUE('1965'!S9) -> 38 | P37: =VALUE('1965'!S2) -> 1 | AA37: 1965 | AB37: =VALUE(O37-P37) -> 37
A38: 1966 | B38: =VALUE('1966'!G22) -> 3.5964912 | C38: =VALUE(6-B38) -> 2.4035088 | N38: 1966 | O38: =VALUE('1966'!S9) -> 20 | P38: =VALUE('1966'!S2) -> 1 | AA38: 1966 | AB38: =VALUE(O38-P38) -> 19
A39: 1967 | B39: =VALUE('1967'!G20) -> 2.9744318 | C39: =VALUE(6-B39) -> 3.0255682 | N39: 1967 | O39: =VALUE('1967'!S9) -> 35 | P39: =VALUE('1967'!S2) -> 0 | AA39: 1967 | AB39: =VALUE(O39-P39) -> 35
A40: 1968 | B40: =VALUE('1968'!G15) -> 2.4214286 | C40: =VALUE(6-B40) -> 3.5785714 | N40: 1968 | O40: =VALUE('1968'!S9) -> 24 | P40: =VALUE('1968'!S2) -> 1 | AA40: 1968 | AB40: =VALUE(O40-P40) -> 23
A41: 1969 | B41: =VALUE('1969'!G11) -> 1.9357143 | C41: =VALUE(6-B41) -> 4.0642857 | N41: 1969 | O41: =VALUE('1969'!S9) -> 11 | P41: =VALUE('1969'!S2) -> 1 | AA41: 1969 | AB41: =VALUE(O41-P41) -> 10
A42: 1970 | B42: =VALUE('1970'!G22) -> 3.775 | C42: =VALUE(6-B42) -> 2.225 | N42: 1970 | O42: =VALUE('1970'!S9) -> 27 | P42: =VALUE('1970'!S2) -> 1 | AA42: 1970 | AB42: =VALUE(O42-P42) -> 26
A43: 1971 | B43: =VALUE('1971'!G25) -> 3.3942308 | C43: =VALUE(6-B43) -> 2.6057692 | N43: 1971 | O43: =VALUE('1971'!S9) -> 22 | P43: =VALUE('1971'!S2) -> 0 | AA43: 1971 | AB43: =VALUE(O43-P43) -> 22
A44: 1972 | B44: =VALUE('1972'!G16) -> 3.5979167 | C44: =VALUE(6-B44) -> 2.4020833 | N44: 1972 | O44: =VALUE('1972'!S9) -> 20 | P44: =VALUE('1972'!S2) -> 1 | AA44: 1972 | AB44: =VALUE(O44-P44) -> 19
A45: 1973 | B45: =VALUE('1973'!G14) -> 2.7276786 | C45: =VALUE(6-B45) -> 3.2723214 | N45: 1973 | O45: =VALUE('1973'!S9) -> 21 | P45: =VALUE('1973'!S2) -> 0 | AA45: 1973 | AB45: =VALUE(O45-P45) -> 21
A46: 1974 | B46: =VALUE('1974'!G25) -> 2.8943272 | C46: =VALUE(6-B46) -> 3.1056728 | N46: 1974 | O46: =VALUE('1974'!S9) -> 26 | P46: =VALUE('1974'!S2) -> 0 | AA46: 1974 | AB46: =VALUE(O46-P46) -> 26
A47: 1975 | B47: =VALUE('1975'!G21) -> 3.3641748 | C47: =VALUE(6-B47) -> 2.6358252 | N47: 1975 | O47: =VALUE('1975'!S9) -> 37 | P47: =VALUE('1975'!S2) -> 5 | AA47: 1975 | AB47: =VALUE(O47-P47) -> 32
...

Sheet 1952
B1: January | C1: April | D1: July | E1: October | M1: parfumes: | S1: small luxury
A2: all the data | B2: 4 | C2: 4 | D2: 4 | E2: 5 | M2: cosmetics | Q2: 1 | S2: =SUM(N1:Q6) -> 1
A3: skkirt lengths | B3: 3 | C3: 4 | D3: 4 | E3: 5 | M3: lipstick
B4: 4 | C4: 4 | D4: 3 | E4: 4 | M4: lotions (skin care, hand creams)
B5: 5 | D5: 4 | E5: 4 | M5: nail polist,
B6: 4 | D6: 4 | E6: 4 | M6: candles
B7: 4 | D7: 4 | E7: 4
B8: 4 | D8: 4 | E8: 5 | M8: bags | S8: high luxury
B9: 4 | D9: 4 | E9: 4 | M9: watches | S9: =SUM(N8:Q13) -> 21
B10: 4 | D10: 4 | E10: 6 | M10: dining
B11: 4 | D11: 4 | M11: jewellery
B12: 4 | D12: 4 | M12: travel
B13: 4 | D13: 4 | M13: hats | N13: 4 | O13: 6 | P13: 1 | Q13: 10
D14: 6
D15: 6
D16: 6
D17: 5
D18: 5
D19: 5
G21: hemline index
B22: =AVERAGE(B2:B20) -> 4 | C22: =AVERAGE(C2:C20) -> 4 | D22: =AVERAGE(D2:D20) -> 4.4444444 | E22: =AVERAGE(E2:E20) -> 4.5555556 | G22: =AVERAGE(B22:E22) -> 4.25

Sheet 1953
B1: January | C1: April | D1: July | E1: October | M1: parfumes: | S1: small luxury
A2: all the data | B2: 3 | C2: 4 | D2: 4 | E2: 4 | M2: cosmetics | S2: 0
A3: skkirt lengths | B3: 5 | C3: 4 | D3: 4 | E3: 4 | M3: lipstick
B4: 4 | C4: 5 | E4: 5 | M4: lotions (skin care, hand creams)
B5: 4 | C5: 5 | E5: 6 | M5: nail polist,
B6: 4 | E6: 5 | M6: candles
B7: 5 | E7: 4
B8: 4 | E8: 4 | M8: bags | N8: 1 | S8: high luxury
B9: 4 | E9: 4 | M9: watches | S9: =SUM(N8:Q13) -> 25
B10: 4 | E10: 4 | M10: dining
E11: 4 | M11: jewellery
E12: 4 | M12: travel | O12: 2
E13: 4 | M13: hats | N13: 4 | O13: 13 | Q13: 5
G15: hemline index
B16: =AVERAGE(B2:B14) -> 4.1111111 | C16: =AVERAGE(C2:C14) -> 4.5 | D16: =AVERAGE(D2:D14) -> 4 | E16: =AVERAGE(E2:E14) -> 4.3333333 | G16: =AVERAGE(B16:E16) -> 4.2361111

Sheet 1954
B1: January | C1: April | D1: July | E1: October | M1: parfumes: | S1: small luxury
A2: all the data | B2: 3 | C2: 4 | D2: 4 | E2: 4 | M2: cosmetics | S2: 0
A3: skkirt lengths | B3: 4 | C3: 4 | D3: 3 | E3: 4 | M3: lipstick
B4: 5 | C4: 4 | D4: 4 | E4: 4 | M4: lotions (skin care, hand creams)
C5: 4 | D5: 4 | E5: 4 | M5: nail polist,
C6: 4 | D6: 4 | E6: 4 | M6: candles
C7: 4 | D7: 4 | E7: 4
E8: 4 | M8: bags | S8: high luxury
E9: 6 | M9: watches | S9: =SUM(N8:Q13) -> 8
E10: 5 | M10: dining
M11: jewellery
M12: travel
M13: hats | N13: 2 | O13: 1 | Q13: 5
G14: hemline index
B15: =AVERAGE(B2:B13) -> 4 | C15: =AVERAGE(C2:C13) -> 4 | D15: =AVERAGE(D2:D13) -> 3.8333333 | E15: =AVERAGE(E2:E13) -> 4.3333333 | G15: =AVERAGE(B15:E15) -> 4.0416667

Sheet 1955
B1: January | C1: April | D1: July | E1: October | M1: parfumes: | S1: small luxury
A2: all the data | D2: 3 | E2: 4 | M2: cosmetics | S2: 0
A3: skkirt lengths | D3: 3 | E3: 4 | M3: lipstick
D4: 3 | E4: 4 | M4: lotions (skin care, hand creams)
D5: 1 | E5: 4 | M5: nail polist,
D6: 1 | E6: 4 | M6: candles
D7: 1 | E7: 4
D8: 1 | E8: 4 | M8: bags | S8: high luxury
D9: 1 | E9: 4 | M9: watches | S9: =SUM(N8:Q13) -> 5
D10: 1 | E10: 4 | M10: dining
D11: 1 | M11: jewellery
D12: 1 | M12: travel
D13: 1 | M13: hats | P13: 4 | Q13: 1
D14: 1
D15: 1
D16: 4
D17: 4
D18: 6
D19: 5
D20: 5
D21: 6
D22: 6
D23: 4
D24: 4
D25: 6
G27: hemline index
D28: =AVERAGE(D2:D26) -> 2.9166667 | E28: =AVERAGE(E2:E26) -> 4 | G28: =AVERAGE(B28:E28) -> 3.4583333

Sheet 1956
B1: January | C1: April | D1: July | E1: October | M1: parfumes: | S1: small luxury
A2: all the data | B2: 4 | C2: 4 | D2: 3 | E2: 4 | M2: cosmetics | N2: 2 | S2: =SUM(N1:Q6) -> 2
A3: skkirt lengths | B3: 4 | C3: 4 | D3: 6 | E3: 4 | M3: lipstick
B4: 4 | C4: 3 | D4: 4 | E4: 4 | M4: lotions (skin care, hand creams)
B5: 4 | C5: 4 | D5: 4 | E5: 5 | M5: nail polist,
B6: 4 | C6: 4 | D6: 4 | E6: 4 | M6: candles
B7: 4 | C7: 4 | D7: 4 | E7: 6
B8: 4 | C8: 4 | D8: 4 | E8: 6 | M8: bags | S8: high luxury
B9: 4 | C9: 4 | E9: 5 | M9: watches | S9: =SUM(N8:Q13) -> 35
B10: 4 | C10: 4 | E10: 4 | M10: dining
C11: 4 | E11: 5 | M11: jewellery | N11: 5 | O11: 3 | P11: 1
C12: 4 | E12: 5 | M12: travel
C13: 4 | E13: 5 | M13: hats | N13: 7 | O13: 9 | P13: 4 | Q13: 6
C14: 4 | E14: 3
C15: 4 | E15: 4
C16: 3 | E16: 4
C17: 3 | E17: 4
C18: 3 | E18: 4
C19: 3 | E19: 4
C20: 3 | E20: 4
E21: 4
G23: hemline index
B24: =AVERAGE(B2:B22) -> 4 | C24: =AVERAGE(C2:C22) -> 3.6842105 | D24: =AVERAGE(D2:D22) -> 4.1428571 | E24: =AVERAGE(E2:E22) -> 4.4 | G24: =AVERAGE(B24:E24) -> 4.0567669

Sheet 1957
B1: January | C1: April | D1: July | E1: October | M1: parfumes: | S1: small luxury
A2: all the data | B2: 4 | C2: 4 | D2: 1 | E2: 5 | M2: cosmetics | O2: 1 | P2: 2 | Q2: 1 | S2: =SUM(N1:Q6) -> 4
A3: skkirt lengths | B3: 4 | C3: 4 | D3: 4 | E3: 4 | M3: lipstick
B4: 3 | C4: 4 | D4: 4 | E4: 4 | M4: lotions (skin care, hand creams)
B5: 4 | C5: 4 | D5: 4 | E5: 4 | M5: nail polist,
B6: 4 | C6: 4 | D6: 4 | E6: 4 | M6: candles
B7: 4 | C7: 4 | D7: 4 | E7: 4
B8: 4 | C8: 4 | D8: 1 | E8: 4 | M8: bags | N8: 4 | S8: high luxury
B9: 4 | C9: 4 | D9: 4 | E9: 5 | M9: watches | S9: =SUM(N8:Q13) -> 37
B10: 4 | C10: 4 | D10: 4 | E10: 6 | M10: dining
B11: 4 | C11: 4 | D11: 5 | E11: 4 | M11: jewellery | O11: 1 | Q11: 3
B12: 4 | C12: 4 | E12: 3 | M12: travel
B13: 6 | C13: 4 | E13: 3 | M13: hats | N13: 5 | O13: 14 | P13: 4 | Q13: 6
B14: 4 | C14: 4 | E14: 5
B15: 4 | C15: 4
B16: 4 | C16: 4
B17: 3 | C17: 4
B18: 3 | C18: 4
B19: 4 | C19: 4
B20: 5 | C20: 4
B21: 4 | C21: 3
B22: 4 | C22: 3
C23: 4
C24: 4
C25: 4
C26: 4
C27: 4
C28: 4
C29: 4
C30: 4
C31: 4
C32: 4
C33: 4
C34: 4
C35: 4
G37: hemline index
B38: =AVERAGE(B2:B36) -> 4 | C38: =AVERAGE(C2:C36) -> 3.9411765 | D38: =AVERAGE(D2:D36) -> 3.5 | E38: =AVERAGE(E2:E36) -> 4.2307692 | G38: =AVERAGE(B38:E38) -> 3.9179864

Sheet 1958
B1: January | C1: April | D1: July | E1: October | M1: parfumes: | S1: small luxury
A2: all the data | B2: 4 | C2: 4 | D2: 3 | E2: 4 | M2: cosmetics | N2: 1 | P2: 1 | Q2: 1 | S2: =SUM(N1:Q6) -> 3
A3: skkirt lengths | B3: 4 | C3: 4 | D3: 3 | E3: 4 | M3: lipstick
B4: 1 | C4: 5 | D4: 3 | E4: 3 | M4: lotions (skin care, hand creams)
B5: 1 | C5: 5 | D5: 3 | E5: 3 | M5: nail polist,
B6: 4 | C6: 4 | D6: 3 | E6: 3 | M6: candles
B7: 4 | C7: 4 | D7: 3 | E7: 4
B8: 4 | C8: 4 | D8: 4 | E8: 4 | M8: bags | O8: 7 | S8: high luxury
B9: 4 | C9: 4 | D9: 4 | E9: 4 | M9: watches | S9: =SUM(N8:Q13) -> 33
B10: 4 | C10: 4 | D10: 4 | E10: 3 | M10: dining
C11: 4 | D11: 4 | E11: 4 | M11: jewellery | O11: 2
C12: 4 | D12: 5 | E12: 4 | M12: travel | N12: 1
C13: 4 | D13: 3 | E13: 4 | M13: hats | N13: 9 | O13: 8 | P13: 2 | Q13: 4
C14: 4 | D14: 3 | E14: 4
C15: 4 | D15: 3 | E15: 3
C16: 4 | D16: 3 | E16: 3
C17: 4 | D17: 3 | E17: 3
C18: 4 | D18: 3 | E18: 3
C19: 4 | D19: 2 | E19: 3
C20: 3 | D20: 5
C21: 3
G23: hemline index
B24: =AVERAGE(B2:B22) -> 3.3333333 | C24: =AVERAGE(C2:C22) -> 4 | D24: =AVERAGE(D2:D22) -> 3.3684211 | E24: =AVERAGE(E2:E22) -> 3.5 | G24: =AVERAGE(B24:E24) -> 3.5504386

Sheet 1959
B1: January | C1: April | D1: July | E1: October | M1: parfumes: | S1: small luxury
A2: all the data | B2: 4 | C2: 4 | D2: 5 | E2: 4 | M2: cosmetics | Q2: 1 | S2: =SUM(N1:Q6) -> 1
A3: skkirt lengths | B3: 3 | C3: 4 | D3: 5 | E3: 3 | M3: lipstick
B4: 4 | C4: 4 | D4: 4 | E4: 3 | M4: lotions (skin care, hand creams)
B5: 3 | C5: 4 | D5: 4 | E5: 3 | M5: nail polist,
B6: 3 | C6: 4 | D6: 4 | E6: 4 | M6: candles
B7: 4 | C7: 4 | D7: 4 | E7: 3
B8: 3 | C8: 4 | D8: 3 | E8: 5 | M8: bags | O8: 1 | P8: 3 | S8: high luxury
B9: 3 | C9: 4 | D9: 2 | M9: watches | S9: =SUM(N8:Q13) -> 35
B10: 4 | C10: 4 | D10: 3 | M10: dining
B11: 3 | C11: 4 | D11: 3 | M11: jewellery
B12: 4 | C12: 4 | D12: 3 | M12: travel
B13: 4 | C13: 4 | D13: 4 | M13: hats | N13: 11 | O13: 7 | P13: 11 | Q13: 2
C14: 4 | D14: 4
C15: 4 | D15: 3
C16: 4 | D16: 3
C17: 4 | D17: 3
C18: 5 | D18: 4
C19: 4 | D19: 4
C20: 4 | D20: 4
C21: 4 | D21: 4
C22: 4 | D22: 4
C23: 4 | D23: 4
C24: 4 | D24: 4
D25: 5
D26: 5
D27: 4
G29: hemline index
B30: =AVERAGE(B2:B27) -> 3.5 | C30: =AVERAGE(C2:C27) -> 4.0434783 | D30: =AVERAGE(D2:D27) -> 3.8076923 | E30: =AVERAGE(E2:E27) -> 3.5714286 | G30: =AVERAGE(B30:E30) -> 3.7306498

Sheet 1960
B1: January | C1: April | D1: July | E1: October | M1: parfumes: | S1: small luxury
A2: all the data | B2: 4 | C2: 4 | D2: 4 | E2: 4 | M2: cosmetics | P2: 1 | S2: =SUM(N1:Q6) -> 1
A3: skkirt lengths | B3: 4 | C3: 4 | D3: 4 | E3: 3 | M3: lipstick
B4: 4 | C4: 4 | D4: 4 | E4: 4 | M4: lotions (skin care, hand creams)
B5: 4 | C5: 4 | D5: 4 | E5: 4 | M5: nail polist,
B6: 3 | C6: 4 | D6: 4 | E6: 5 | M6: candles
B7: 3 | C7: 4 | D7: 4 | E7: 4
B8: 3 | C8: 4 | D8: 4 | E8: 4 | M8: bags | N8: 1 | O8: 1 | S8: high luxury
B9: 3 | C9: 4 | D9: 3 | E9: 3 | M9: watches | S9: =SUM(N8:Q13) -> 22
B10: 3 | C10: 4 | D10: 3 | E10: 3 | M10: dining
B11: 3 | C11: 4 | D11: 4 | E11: 3 | M11: jewellery | N11: 4 | Q11: 3
B12: 2 | C12: 4 | D12: 4 | E12: 3 | M12: travel
B13: 2 | C13: 4 | D13: 4 | E13: 3 | M13: hats | N13: 2 | O13: 3 | Q13: 8
B14: 2 | C14: 4 | D14: 4 | E14: 3
B15: 2 | C15: 4 | D15: 4 | E15: 6
C16: 3 | D16: 4 | E16: 4
C17: 3 | D17: 3
C18: 3 | D18: 2
C19: 3 | D19: 1
C20: 3 | D20: 1
C21: 4 | D21: 5
C22: 6 | D22: 5
D23: 5
D24: 4
G26: hemline index
B27: =AVERAGE(B2:B25) -> 3 | C27: =AVERAGE(C2:C25) -> 3.8571429 | D27: =AVERAGE(D2:D25) -> 3.6521739 | E27: =AVERAGE(E2:E25) -> 3.7333333 | G27: =AVERAGE(B27:E27) -> 3.5606625

Sheet 1961
B1: January | C1: April | D1: July | E1: October | M1: parfumes: | S1: small luxury
A2: all the data | B2: 4 | C2: 3 | D2: 4 | E2: 4 | M2: cosmetics | S2: 0
A3: skkirt lengths | B3: 5 | C3: 4 | D3: 3 | E3: 1 | M3: lipstick
B4: 3 | C4: 4 | D4: 3 | E4: 4 | M4: lotions (skin care, hand creams)
B5: 3 | C5: 4 | D5: 4 | M5: nail polist,
B6: 3 | C6: 3 | D6: 3 | M6: candles
B7: 4 | C7: 3 | D7: 3
B8: 3 | C8: 3 | M8: bags | S8: high luxury
B9: 3 | C9: 4 | M9: watches | O9: 1 | S9: =SUM(N8:Q13) -> 23
B10: 3 | C10: 3 | M10: dining
B11: 3 | C11: 3 | M11: jewellery
B12: 3 | C12: 3 | M12: travel
B13: 4 | C13: 3 | M13: hats | N13: 2 | O13: 7 | P13: 13
B14: 6 | C14: 3
B15: 5 | C15: 3
C16: 4
C17: 4
C18: 4
C19: 3
C20: 4
C21: 5
C22: 5
C23: 4
C24: 4
C25: 5
C26: 4
G27: hemline index
B28: =AVERAGE(B2:B26) -> 3.7142857 | C28: =AVERAGE(C2:C26) -> 3.68 | D28: =AVERAGE(D2:D26) -> 3.3333333 | E28: =AVERAGE(E2:E26) -> 3 | G28: =AVERAGE(B28:E28) -> 3.4319048

Sheet 1962
B1: January | C1: April | D1: July | E1: October | M1: parfumes: | S1: small luxury
A2: all the data | B2: 5 | C2: 3 | D2: 4 | E2: 4 | M2: cosmetics | S2: 0
A3: skkirt lengths | B3: 3 | C3: 3 | D3: 4 | E3: 4 | M3: lipstick
B4: 4 | C4: 3 | D4: 4 | E4: 4 | M4: lotions (skin care, hand creams)
B5: 6 | C5: 3 | D5: 4 | E5: 4 | M5: nail polist,
B6: 4 | C6: 3 | D6: 3 | E6: 4 | M6: candles
B7: 4 | C7: 3 | D7: 4 | E7: 4
C8: 2 | D8: 3 | E8: 4 | M8: bags | N8: 2 | S8: high luxury
C9: 3 | D9: 3 | E9: 3 | M9: watches | S9: =SUM(N8:Q13) -> 20
D10: 3 | E10: 3 | M10: dining
D11: 3 | E11: 3 | M11: jewellery | N11: 1
D12: 1 | E12: 3 | M12: travel
D13: 4 | E13: 3 | M13: hats | N13: 10 | O13: 3 | P13: 4
E14: 3
E15: 3
G17: hemline index
B18: =AVERAGE(B2:B16) -> 4.3333333 | C18: =AVERAGE(C2:C16) -> 2.875 | D18: =AVERAGE(D2:D16) -> 3.3333333 | E18: =AVERAGE(E2:E16) -> 3.5 | G18: =AVERAGE(B18:E18) -> 3.5104167

Sheet 1963
B1: January | C1: April | D1: July | E1: October | M1: parfumes: | S1: small luxury
A2: all the data | B2: 4 | C2: 4 | D2: 4 | E2: 4 | M2: cosmetics | S2: 0
A3: skkirt lengths | B3: 3 | C3: 4 | D3: 3 | E3: 4 | M3: lipstick
B4: 2 | C4: 3 | E4: 3 | M4: lotions (skin care, hand creams)
B5: 3 | C5: 3 | E5: 5 | M5: nail polist,
B6: 2 | C6: 3 | M6: candles
B7: 3 | C7: 3
B8: 3 | C8: 3 | M8: bags | S8: high luxury
C9: 3 | M9: watches | S9: =SUM(N8:Q13) -> 45
C10: 3 | M10: dining
C11: 3 | M11: jewellery | O11: 3 | P11: 2
C12: 3 | M12: travel | N12: 1 | P12: 1
M13: hats | N13: 11 | O13: 3 | P13: 7 | Q13: 17
G14: hemline index
B15: =AVERAGE(B2:B13) -> 2.8571429 | C15: =AVERAGE(C2:C13) -> 3.1818182 | D15: =AVERAGE(D2:D13) -> 3.5 | E15: =AVERAGE(E2:E13) -> 4 | G15: =AVERAGE(B15:E15) -> 3.3847403

Sheet 1964
B1: January | C1: April | D1: July | E1: October | M1: parfumes: | S1: small luxury
A2: all the data | B2: 3 | C2: 5 | D2: 3 | E2: 3 | M2: cosmetics | N2: 1 | S2: =SUM(N1:Q6) -> 1
A3: skkirt lengths | B3: 3 | C3: 5 | D3: 4 | E3: 3 | M3: lipstick
B4: 3 | C4: 5 | D4: 3 | E4: 3 | M4: lotions (skin care, hand creams)
B5: 3 | C5: 6 | D5: 3 | E5: 3 | M5: nail polist,
B6: 3 | C6: 6 | D6: 4 | E6: 4 | M6: candles
B7: 3 | C7: 6 | D7: 5 | E7: 4
B8: 3 | C8: 6 | D8: 4 | E8: 4 | M8: bags | P8: 2 | Q8: 4 | S8: high luxury
B9: 1 | C9: 3 | D9: 4 | E9: 4 | M9: watches | S9: =SUM(N8:Q13) -> 44
B10: 3 | C10: 3 | D10: 3 | E10: 4 | M10: dining
B11: 4 | C11: 3 | E11: 4 | M11: jewellery | N11: 7
B12: 3 | C12: 3 | E12: 4 | M12: travel
B13: 5 | C13: 3 | E13: 3 | M13: hats | N13: 6 | O13: 2 | P13: 3 | Q13: 20
B14: 6 | C14: 3 | E14: 3
B15: 6 | C15: 3 | E15: 3
C16: 3 | E16: 5
C17: 3 | E17: 3
C18: 3 | E18: 4
C19: 3 | E19: 3
G21: hemline index
B22: =AVERAGE(B2:B20) -> 3.5 | C22: =AVERAGE(C2:C20) -> 4 | D22: =AVERAGE(D2:D20) -> 3.6666667 | E22: =AVERAGE(E2:E20) -> 3.5555556 | G22: =AVERAGE(B22:E22) -> 3.6805556

Sheet 1965
B1: January | C1: April | D1: July | E1: October | M1: parfumes: | S1: small luxury
A2: all the data | B2: 3 | C2: 4 | D2: 4 | E2: 3 | M2: cosmetics | N2: 1 | S2: =SUM(N1:Q6) -> 1
A3: skkirt lengths | B3: 3 | C3: 4 | D3: 4 | E3: 2 | M3: lipstick
B4: 3 | C4: 6 | D4: 5 | M4: lotions (skin care, hand creams)
B5: 3 | C5: 6 | D5: 4 | M5: nail polist,
B6: 3 | C6: 3 | D6: 3 | M6: candles
B7: 3 | C7: 4 | D7: 3
B8: 4 | C8: 4 | D8: 6 | M8: bags | S8: high luxury
C9: 4 | D9: 2 | M9: watches | S9: =SUM(N8:Q13) -> 38
D10: 2 | M10: dining
D11: 1 | M11: jewellery | N11: 1 | P11: 1
D12: 1 | M12: travel
D13: 3 | M13: hats | N13: 5 | O13: 10 | P13: 12 | Q13: 9
G15: hemline index
B16: =AVERAGE(B2:B14) -> 3.1428571 | C16: =AVERAGE(C2:C14) -> 4.375 | D16: =AVERAGE(D2:D14) -> 3.1666667 | E16: =AVERAGE(E2:E14) -> 2.5 | G16: =AVERAGE(B16:E16) -> 3.296131

Sheet 1966
B1: January | C1: April | D1: July | E1: October | M1: parfumes: | S1: small luxury
A2: all the data | B2: 6 | C2: 4 | D2: 3 | E2: 2 | M2: cosmetics | Q2: 1 | S2: =SUM(N1:Q6) -> 1
A3: skkirt lengths | B3: 6 | C3: 3 | D3: 3 | E3: 2 | M3: lipstick
B4: 5 | C4: 3 | D4: 3 | E4: 2 | M4: lotions (skin care, hand creams)
B5: 5 | C5: 3 | D5: 3 | E5: 2 | M5: nail polist,
B6: 6 | C6: 3 | D6: 6 | E6: 2 | M6: candles
B7: 3 | C7: 3 | D7: 4 | E7: 2
B8: 4 | C8: 3 | D8: 6 | E8: 4 | M8: bags | S8: high luxury
C9: 3 | D9: 6 | E9: 4 | M9: watches | O9: 1 | S9: =SUM(N8:Q13) -> 20
C10: 3 | E10: 4 | M10: dining
C11: 3 | E11: 4 | M11: jewellery | O11: 1
C12: 3 | E12: 1 | M12: travel
C13: 3 | E13: 1 | M13: hats | N13: 6 | O13: 2 | P13: 2 | Q13: 8
E14: 1
E15: 1
E16: 1
E17: 1
E18: 1
E19: 1
E20: 3
G21: hemline index
B22: =AVERAGE(B2:B20) -> 5 | C22: =AVERAGE(C2:C20) -> 3.0833333 | D22: =AVERAGE(D2:D20) -> 4.25 | E22: =AVERAGE(E2:E20) -> 2.0526316 | G22: =AVERAGE(B22:E22) -> 3.5964912

Sheet 1967
B1: January | C1: April | D1: July | E1: October | M1: parfumes: | S1: small luxury
A2: all the data | B2: 5 | C2: 3 | D2: 3 | E2: 3 | M2: cosmetics | S2: 0
A3: skkirt lengths | B3: 3 | C3: 3 | D3: 6 | E3: 3 | M3: lipstick
B4: 3 | C4: 2 | D4: 5 | E4: 3 | M4: lotions (skin care, hand creams)
B5: 3 | C5: 2 | D5: 4 | E5: 4 | M5: nail polist,
B6: 3 | D6: 4 | E6: 2 | M6: candles
B7: 3 | D7: 2
B8: 3 | D8: 2 | M8: bags | P8: 2 | S8: high luxury
B9: 3 | D9: 2 | M9: watches | S9: =SUM(N8:Q13) -> 35
B10: 3 | D10: 2 | M10: dining
B11: 3 | D11: 3 | M11: jewellery | P11: 3
B12: 4 | D12: 3 | M12: travel
B13: 3 | M13: hats | N13: 9 | O13: 5 | P13: 7 | Q13: 9
B14: 3
B15: 3
B16: 3
B17: 2
G19: hemline index
B20: =AVERAGE(B2:B18) -> 3.125 | C20: =AVERAGE(C2:C18) -> 2.5 | D20: =AVERAGE(D2:D18) -> 3.2727273 | E20: =AVERAGE(E2:E18) -> 3 | G20: =AVERAGE(B20:E20) -> 2.9744318

Sheet 1968
B1: January | C1: April | D1: July | E1: October | M1: parfumes: | S1: small luxury
A2: all the data | B2: 2 | C2: 3 | D2: 4 | E2: 5 | M2: cosmetics | Q2: 1 | S2: =SUM(N1:Q6) -> 1
A3: skkirt lengths | B3: 3 | C3: 3 | D3: 4 | E3: 6 | M3: lipstick
B4: 2 | C4: 2 | D4: 2 | E4: 2 | M4: lotions (skin care, hand creams)
B5: 3 | D5: 2 | E5: 2 | M5: nail polist,
B6: 2 | D6: 1 | E6: 1 | M6: candles
B7: 2 | D7: 1 | E7: 1
B8: 2 | D8: 2 | E8: 2 | M8: bags | S8: high luxury
B9: 1 | E9: 1 | M9: watches | S9: =SUM(N8:Q13) -> 24
B10: 4 | E10: 1 | M10: dining
E11: 3 | M11: jewellery
M12: travel
M13: hats | N13: 10 | O13: 7 | P13: 5 | Q13: 2
G14: hemline index
B15: =AVERAGE(B2:B13) -> 2.3333333 | C15: =AVERAGE(C2:C13) -> 2.6666667 | D15: =AVERAGE(D2:D13) -> 2.2857143 | E15: =AVERAGE(E2:E13) -> 2.4 | G15: =AVERAGE(B15:E15) -> 2.4214286

Sheet 1969
B1: January | C1: April | D1: July | E1: October | M1: parfumes: | S1: small luxury
A2: all the data | B2: 2 | C2: 2 | D2: 2 | E2: 2 | M2: cosmetics | Q2: 1 | S2: =SUM(N1:Q6) -> 1
A3: skkirt lengths | B3: 2 | C3: 2 | E3: 2 | M3: lipstick
B4: 2 | C4: 1 | E4: 2 | M4: lotions (skin care, hand creams)
B5: 1 | C5: 2 | E5: 2 | M5: nail polist,
B6: 1 | C6: 3 | E6: 2 | M6: candles
E7: 2
E8: 3 | M8: bags | S8: high luxury
M9: watches | S9: =SUM(N8:Q13) -> 11
G10: hemline index | M10: dining
B11: =AVERAGE(B2:B9) -> 1.6 | C11: =AVERAGE(C2:C9) -> 2 | D11: =AVERAGE(D2:D9) -> 2 | E11: =AVERAGE(E2:E9) -> 2.1428571 | G11: =AVERAGE(B11:E11) -> 1.9357143 | M11: jewellery
M12: travel
M13: hats | N13: 3 | O13: 5 | Q13: 3

Sheet 1970
B1: January | C1: April | D1: July | E1: October | M1: parfumes: | S1: small luxury
A2: all the data | B2: 5 | C2: 2 | D2: 3 | E2: 4 | M2: cosmetics | S2: =SUM(N1:Q6) -> 1
A3: skkirt lengths | C3: 2 | D3: 3 | E3: 3 | M3: lipstick
C4: 2 | D4: 3 | E4: 3 | M4: lotions (skin care, hand creams)
C5: 6 | D5: 3 | E5: 3 | M5: nail polist,
C6: 6 | D6: 2 | E6: 4 | M6: candles | O6: 1
C7: 6 | D7: 3 | E7: 3
C8: 6 | D8: 3 | E8: 3 | M8: bags | S8: high luxury
C9: 6 | D9: 3 | E9: 3 | M9: watches | S9: =SUM(N8:Q13) -> 27
C10: 6 | D10: 3 | E10: 3 | M10: dining
C11: 6 | D11: 3 | E11: 3 | M11: jewellery | Q11: 1
C12: 4 | D12: 3 | E12: 3 | M12: travel | N12: 1
C13: 2 | D13: 2 | E13: 3 | M13: hats | N13: 9 | O13: 3 | P13: 7 | Q13: 6
D14: 2 | E14: 3
D15: 1 | E15: 2
D16: 2 | E16: 6
E17: 2
E18: 2
E19: 2
E20: 2
G21: hemline index
B22: =AVERAGE(B2:B20) -> 5 | C22: =AVERAGE(C2:C20) -> 4.5 | D22: =AVERAGE(D2:D20) -> 2.6 | E22: =AVERAGE(E2:E20) -> 3 | G22: =AVERAGE(B22:E22) -> 3.775

Sheet 1971
B1: January | C1: April | D1: July | E1: October | M1: parfumes: | S1: small luxury
A2: all the data | B2: 3 | C2: 3 | D2: 6 | M2: cosmetics | S2: 0
A3: skkirt lengths | B3: 3 | C3: 3 | D3: 4 | M3: lipstick
B4: 4 | C4: 3 | D4: 3 | M4: lotions (skin care, hand creams)
B5: 3 | C5: 3 | D5: 3 | M5: nail polist,
B6: 4 | C6: 3 | D6: 4 | M6: candles
B7: 4 | C7: 3 | D7: 3
B8: 5 | C8: 3 | D8: 3 | M8: bags | S8: high luxury
B9: 5 | C9: 3 | D9: 2 | M9: watches | S9: =SUM(N8:Q13) -> 22
C10: 3 | D10: 2 | M10: dining
C11: 3 | D11: 3 | M11: jewellery | Q11: 3
C12: 4 | D12: 2 | M12: travel
C13: 3 | D13: 4 | M13: hats | N13: 3 | O13: 5 | P13: 5 | Q13: 6
C14: 3 | D14: 4
C15: 4
C16: 4
C17: 3
C18: 2
C19: 2
C20: 2
C21: 3
C22: 3
G24: hemline index
B25: =AVERAGE(B2:B23) -> 3.875 | C25: =AVERAGE(C2:C23) -> 3 | D25: =AVERAGE(D2:D23) -> 3.3076923 | G25: =AVERAGE(B25:E25) -> 3.3942308

Sheet 1972
B1: January | C1: April | D1: July | E1: October | M1: parfumes: | S1: small luxury
A2: all the data | B2: 4 | C2: 4 | D2: 4 | E2: 5 | M2: cosmetics | N2: 1 | S2: =SUM(N1:Q6) -> 1
A3: skkirt lengths | B3: 2 | C3: 3 | D3: 4 | E3: 4 | M3: lipstick
B4: 3 | C4: 5 | D4: 4 | E4: 5 | M4: lotions (skin care, hand creams)
B5: 5 | C5: 4 | D5: 4 | E5: 5 | M5: nail polist,
B6: 4 | C6: 2 | D6: 4 | E6: 3 | M6: candles
C7: 4 | D7: 4 | E7: 3
C8: 3 | D8: 4 | E8: 3 | M8: bags | S8: high luxury
C9: 2 | D9: 4 | M9: watches | S9: =SUM(N8:Q13) -> 20
D10: 3 | M10: dining
D11: 1 | M11: jewellery | O11: 1
D12: 3 | M12: travel
D13: 2 | M13: hats | N13: 3 | O13: 8 | P13: 5 | Q13: 3
G15: hemline index
B16: =AVERAGE(B2:B14) -> 3.6 | C16: =AVERAGE(C2:C14) -> 3.375 | D16: =AVERAGE(D2:D14) -> 3.4166667 | E16: =AVERAGE(E2:E14) -> 4 | G16: =AVERAGE(B16:E16) -> 3.5979167

Sheet 1973
B1: January | C1: April | D1: July | E1: October | M1: parfumes: | S1: small luxury
A2: all the data | B2: 2 | C2: 5 | D2: 2 | E2: 2 | M2: cosmetics | S2: 0
A3: skkirt lengths | B3: 3 | C3: 3 | D3: 1 | E3: 2 | M3: lipstick
B4: 3 | C4: 3 | D4: 1 | M4: lotions (skin care, hand creams)
B5: 5 | C5: 2 | D5: 3 | M5: nail polist,
B6: 5 | C6: 3 | D6: 5 | M6: candles
B7: 3 | C7: 4 | D7: 2
B8: 2 | C8: 5 | D8: 2 | M8: bags | Q8: 2 | S8: high luxury
B9: 2 | C9: 4 | M9: watches | S9: =SUM(N8:Q13) -> 21
B10: 2 | M10: dining
M11: jewellery | N11: 1 | P11: 1
M12: travel
G13: hemline index | M13: hats | N13: 1 | O13: 2 | P13: 2 | Q13: 12
B14: =AVERAGE(B2:B12) -> 3 | C14: =AVERAGE(C2:C12) -> 3.625 | D14: =AVERAGE(D2:D12) -> 2.2857143 | E14: =AVERAGE(E2:E12) -> 2 | G14: =AVERAGE(B14:E14) -> 2.7276786

Sheet 1974
B1: January | C1: April | D1: July | E1: October | M1: parfumes: | S1: small luxury
A2: all the data | B2: 2 | C2: 3 | D2: 4 | E2: 4 | M2: cosmetics | S2: 0
A3: skkirt lengths | B3: 2 | C3: 3 | D3: 3 | E3: 4 | M3: lipstick
B4: 2 | C4: 3 | D4: 3 | E4: 4 | M4: lotions (skin care, hand creams)
B5: 2 | C5: 3 | D5: 2 | E5: 3 | M5: nail polist,
B6: 2 | C6: 2 | D6: 3 | E6: 6 | M6: candles
B7: 3 | C7: 2 | D7: 3 | E7: 6
C8: 3 | D8: 3 | E8: 6 | M8: bags | S8: high luxury
C9: 2 | D9: 3 | E9: 6 | M9: watches | O9: 1 | S9: =SUM(N8:Q13) -> 26
C10: 2 | D10: 3 | E10: 6 | M10: dining
C11: 2 | D11: 3 | E11: 5 | M11: jewellery | N11: 1 | P11: 1
C12: 2 | D12: 3 | E12: 6 | M12: travel | N12: 1
C13: 2 | D13: 2 | E13: 5 | M13: hats | N13: 6 | P13: 8 | Q13: 8
C14: 4 | D14: 2 | E14: 2
D15: 2 | E15: 2
D16: 3 | E16: 3
D17: 3 | E17: 2
D18: 2 | E18: 3
D19: 3 | E19: 3
D20: 1 | E20: 3
D21: 2
D22: 4
G24: hemline index
B25: =AVERAGE(B2:B23) -> 2.1666667 | C25: =AVERAGE(C2:C23) -> 2.5384615 | D25: =AVERAGE(D2:D23) -> 2.7142857 | E25: =AVERAGE(E2:E23) -> 4.1578947 | G25: =AVERAGE(B25:E25) -> 2.8943272

Sheet 1975
B1: January | C1: April | D1: July | E1: October | M1: parfumes: | N1: 1 | S1: small luxury
A2: all the data | B2: 4 | C2: 3 | D2: 1 | E2: 2 | M2: cosmetics | P2: 3 | Q2: 1 | S2: =SUM(N1:Q6) -> 5
A3: skkirt lengths | B3: 5 | C3: 3 | D3: 3 | E3: 2 | M3: lipstick
B4: 6 | C4: 3 | D4: 4 | E4: 3 | M4: lotions (skin care, hand creams)
B5: 4 | C5: 3 | D5: 3 | E5: 4 | M5: nail polist,
B6: 4 | C6: 3 | D6: 5 | E6: 4 | M6: candles
B7: 1 | C7: 4 | D7: 5 | E7: 4
B8: 2 | D8: 3 | E8: 3 | M8: bags | S8: high luxury
B9: 2 | D9: 1 | E9: 3 | M9: watches | Q9: 1 | S9: =SUM(N8:Q13) -> 37
B10: 2 | D10: 6 | E10: 3 | M10: dining
B11: 2 | E11: 3 | M11: jewellery
B12: 6 | E12: 4 | M12: travel
B13: 5 | E13: 4 | M13: hats | N13: 29 | O13: 1 | P13: 1 | Q13: 5
B14: 2 | E14: 4
B15: 2 | E15: 4
B16: 2 | E16: 4
B17: 5 | E17: 4
E18: 4
G20: hemline index
B21: =AVERAGE(B2:B19) -> 3.375 | C21: =AVERAGE(C2:C19) -> 3.1666667 | D21: =AVERAGE(D2:D19) -> 3.4444444 | E21: =AVERAGE(E2:E19) -> 3.4705882 | G21: =AVERAGE(B21:E21) -> 3.3641748

Sheet 1976
B1: January | C1: April | D1: July | E1: October | M1: parfumes: | S1: small luxury
A2: all the data | B2: 2 | C2: 4 | D2: 3 | E2: 2 | M2: cosmetics | O2: 2 | P2: 1 | S2: =SUM(N1:Q6) -> 3
A3: skkirt lengths | B3: 4 | C3: 4 | D3: 3 | E3: 2 | M3: lipstick
B4: 4 | C4: 3 | D4: 5 | E4: 4 | M4: lotions (skin care, hand creams)
B5: 4 | C5: 3 | D5: 6 | E5: 5 | M5: nail polist,
B6: 3 | C6: 3 | D6: 4 | E6: 4 | M6: candles
B7: 3 | C7: 3 | D7: 5 | E7: 3
C8: 3 | D8: 4 | E8: 2 | M8: bags | O8: 1 | S8: high luxury
C9: 4 | D9: 2 | E9: 3 | M9: watches | P9: 4 | S9: =SUM(N8:Q13) -> 41
C10: 4 | D10: 2 | E10: 4 | M10: dining | O10: 1
C11: 3 | E11: 4 | M11: jewellery | Q11: 1
C12: 3 | E12: 4 | M12: travel
C13: 3 | E13: 5 | M13: hats | N13: 16 | O13: 5 | P13: 3 | Q13: 10
C14: 3 | E14: 6
C15: 3 | E15: 1
C16: 3
C17: 3
C18: 4
G20: hemline index
B21: =AVERAGE(B2:B19) -> 3.3333333 | C21: =AVERAGE(C2:C19) -> 3.2941176 | D21: =AVERAGE(D2:D19) -> 3.7777778 | E21: =AVERAGE(E2:E19) -> 3.5 | G21: =AVERAGE(B21:E21) -> 3.4763072

Sheet 1977
B1: January | C1: April | D1: July | E1: October | M1: parfumes: | S1: small luxury
A2: all the data | B2: 6 | C2: 6 | D2: 4 | E2: 3 | M2: cosmetics | P2: 1 | S2: =SUM(N1:Q6) -> 1
A3: skkirt lengths | B3: 6 | D3: 3 | E3: 3 | M3: lipstick
B4: 4 | D4: 6 | E4: 4 | M4: lotions (skin care, hand creams)
B5: 6 | D5: 3 | E5: 4 | M5: nail polist,
B6: 4 | D6: 3 | E6: 4 | M6: candles
B7: 4 | D7: 4
B8: 4 | D8: 4 | M8: bags | N8: 4 | O8: 2 | S8: high luxury
D9: 3 | M9: watches | S9: =SUM(N8:Q13) -> 46
M10: dining
M11: jewellery | O11: 4 | P11: 1 | Q11: 1
M12: travel
M13: hats | N13: 5 | O13: 14 | P13: 5 | Q13: 10
G14: hemline index
B15: =AVERAGE(B2:B13) -> 4.8571429 | C15: =AVERAGE(C2:C13) -> 6 | D15: =AVERAGE(D2:D13) -> 3.75 | E15: =AVERAGE(E2:E13) -> 3.6 | G15: =AVERAGE(B15:E15) -> 4.5517857

Sheet 1978
B1: January | C1: April | D1: July | E1: October | M1: parfumes: | S1: small luxury
A2: all the data | B2: 4 | C2: 3 | D2: 2 | E2: 4 | M2: cosmetics | N2: 1 | S2: =SUM(N1:Q6) -> 3
A3: skkirt lengths | B3: 5 | C3: 3 | D3: 3 | E3: 4 | M3: lipstick | O3: 1 | P3: 1
B4: 6 | C4: 3 | D4: 4 | E4: 4 | M4: lotions (skin care, hand creams)
B5: 6 | C5: 3 | D5: 4 | E5: 3 | M5: nail polist,
B6: 6 | C6: 4 | D6: 2 | E6: 2 | M6: candles
B7: 6 | E7: 2
B8: 6 | E8: 2 | M8: bags | S8: high luxury
B9: 4 | E9: 2 | M9: watches | P9: 4 | S9: =SUM(N8:Q13) -> 25
B10: 4 | E10: 3 | M10: dining
B11: 4 | E11: 4 | M11: jewellery | P11: 1
B12: 3 | M12: travel
B13: 4 | M13: hats | N13: 9 | O13: 7 | Q13: 4
B14: 4
B15: 4
B16: 4
G18: hemline index
B19: =AVERAGE(B2:B17) -> 4.6666667 | C19: =AVERAGE(C2:C17) -> 3.2 | D19: =AVERAGE(D2:D17) -> 3 | E19: =AVERAGE(E2:E17) -> 3 | G19: =AVERAGE(B19:E19) -> 3.4666667

Sheet 1979
B1: January | C1: April | D1: July | E1: October | M1: parfumes: | S1: small luxury
A2: all the data | B2: 6 | C2: 4 | D2: 4 | E2: 5 | M2: cosmetics | S2: 0
A3: skkirt lengths | C3: 5 | D3: 4 | E3: 3 | M3: lipstick
C4: 6 | D4: 4 | E4: 4 | M4: lotions (skin care, hand creams)
C5: 6 | D5: 4 | E5: 3 | M5: nail polist,
C6: 5 | D6: 4 | E6: 4 | M6: candles
C7: 4 | D7: 5 | E7: 3
C8: 4 | D8: 5 | E8: 3 | M8: bags | P8: 1 | S8: high luxury
C9: 4 | D9: 5 | E9: 3 | M9: watches | S9: =SUM(N8:Q13) -> 48
C10: 4 | D10: 5 | E10: 3 | M10: dining
D11: 5 | E11: 4 | M11: jewellery | N11: 1 | O11: 1
D12: 4 | E12: 4 | M12: travel | N12: 1
D13: 4 | E13: 5 | M13: hats | N13: 3 | O13: 35 | Q13: 6
D14: 4
D15: 4
D16: 3
D17: 3
D18: 3
D19: 3
D20: 3
D21: 4
D22: 5
D23: 6
G25: hemline index
B26: =AVERAGE(B2:B24) -> 6 | C26: =AVERAGE(C2:C24) -> 4.6666667 | D26: =AVERAGE(D2:D24) -> 4.1363636 | E26: =AVERAGE(E2:E24) -> 3.6666667 | G26: =AVERAGE(B26:E26) -> 4.6174242

Sheet 1980
B1: January | C1: April | D1: July | E1: October | M1: parfumes: | S1: small luxury
A2: all the data | B2: 3 | C2: 6 | D2: 3 | E2: 4 | M2: cosmetics | S2: 0
A3: skkirt lengths | B3: 3 | C3: 4 | D3: 3 | E3: 5 | M3: lipstick
B4: 3 | C4: 4 | D4: 3 | E4: 5 | M4: lotions (skin care, hand creams)
B5: 3 | C5: 4 | E5: 4 | M5: nail polist,
B6: 3 | C6: 5 | M6: candles
B7: 3 | C7: 3
C8: 3 | M8: bags | S8: high luxury
C9: 3 | M9: watches | S9: =SUM(N8:Q13) -> 30
C10: 4 | M10: dining
C11: 4 | M11: jewellery
C12: 4 | M12: travel
C13: 4 | M13: hats | N13: 15 | O13: 10 | P13: 5
G16: hemline index
B17: =AVERAGE(B2:B15) -> 3 | C17: =AVERAGE(C2:C15) -> 4 | D17: =AVERAGE(D2:D15) -> 3 | E17: =AVERAGE(E2:E15) -> 4.5 | G17: =AVERAGE(B17:E17) -> 3.625

Sheet 1981
B1: January | C1: April | D1: July | E1: October | M1: parfumes: | S1: small luxury
A2: all the data | B2: 5 | C2: 3 | D2: 4 | E2: 3 | M2: cosmetics | S2: 0
A3: skkirt lengths | C3: 3 | D3: 4 | E3: 3 | M3: lipstick
C4: 3 | D4: 4 | E4: 3 | M4: lotions (skin care, hand creams)
C5: 3 | D5: 4 | E5: 3 | M5: nail polist,
C6: 3 | D6: 4 | E6: 3 | M6: candles
D7: 3 | E7: 3
D8: 3 | E8: 3 | M8: bags | O8: 1 | S8: high luxury
D9: 5 | E9: 3 | M9: watches | S9: =SUM(N8:Q13) -> 13
D10: 3 | E10: 6 | M10: dining | N10: 1 | O10: 1 | P10: 1
D11: 3 | E11: 6 | M11: jewellery | O11: 1 | P11: 1 | Q11: 2
D12: 3 | E12: 5 | M12: travel | O12: 1 | P12: 1 | Q12: 1
D13: 3 | M13: hats | O13: 2
D14: 3
D15: 3
D16: 3
D17: 3
D18: 2
D19: 2
D20: 5
G22: hemline index
B23: =AVERAGE(B2:B21) -> 5 | C23: =AVERAGE(C2:C21) -> 3 | D23: =AVERAGE(D2:D21) -> 3.3684211 | E23: =AVERAGE(E2:E21) -> 3.7272727 | G23: =AVERAGE(B23:E23) -> 3.7739234

Sheet 1982
B1: January | C1: April | D1: July | E1: October | M1: parfumes: | S1: small luxury
A2: all the data | B2: 3 | C2: 4 | D2: 3 | E2: 4 | M2: cosmetics | S2: =SUM(N1:Q6) -> 2
A3: skkirt lengths | B3: 3 | C3: 4 | D3: 4 | E3: 3 | M3: lipstick
B4: 3 | C4: 4 | D4: 4 | E4: 3 | M4: lotions (skin care, hand creams)
B5: 4 | C5: 3 | D5: 4 | E5: 3 | M5: nail polist, | Q5: 2
B6: 2 | C6: 4 | D6: 3 | M6: candles
B7: 2 | D7: 3
B8: 2 | D8: 3 | M8: bags | P8: 1 | Q8: 1 | S8: high luxury
M9: watches | S9: =SUM(N8:Q13) -> 27
M10: dining | N10: 1 | O10: 2 | P10: 3 | Q10: 4
M11: jewellery | O11: 4 | P11: 7 | Q11: 1
M12: travel | P12: 2
G13: hemline index | M13: hats | O13: 1
B14: =AVERAGE(B2:B12) -> 2.7142857 | C14: =AVERAGE(C2:C12) -> 3.8 | D14: =AVERAGE(D2:D12) -> 3.4285714 | E14: =AVERAGE(E2:E12) -> 3.25 | G14: =AVERAGE(B14:E14) -> 3.2982143

Sheet 1983
B1: January | C1: April | D1: July | E1: October | M1: parfumes: | S1: small luxury
A2: all the data | B2: 4 | C2: 4 | D2: 4 | E2: 4 | M2: cosmetics | O2: 1 | S2: =SUM(N1:Q6) -> 2
A3: skkirt lengths | B3: 3 | D3: 4 | E3: 4 | M3: lipstick | O3: 1
B4: 3 | D4: 4 | E4: 1 | M4: lotions (skin care, hand creams)
B5: 3 | D5: 4 | E5: 1 | M5: nail polist,
D6: 4 | E6: 2 | M6: candles
D7: 3 | E7: 2
D8: 4 | E8: 2 | M8: bags | S8: high luxury
E9: 3 | M9: watches | S9: =SUM(N8:Q13) -> 21
E10: 3 | M10: dining | N10: 1 | O10: 5 | P10: 2
M11: jewellery | N11: 1 | O11: 1 | P11: 5 | Q11: 3
G12: hemline index | M12: travel | O12: 1 | P12: 2
B13: =AVERAGE(B2:B11) -> 3.25 | C13: =AVERAGE(C2:C11) -> 4 | D13: =AVERAGE(D2:D11) -> 3.8571429 | E13: =AVERAGE(E2:E11) -> 2.4444444 | G13: =AVERAGE(B13:E13) -> 3.3878968 | M13: hats

Sheet 1984
B1: January | C1: April | D1: July | E1: October | M1: parfumes: | S1: small luxury
A2: all the data | B2: 3 | C2: 4 | D2: 4 | E2: 4 | M2: cosmetics | S2: =SUM(N1:Q6) -> 1
A3: skkirt lengths | B3: 4 | D3: 4 | E3: 4 | M3: lipstick | Q3: 1
B4: 4 | D4: 4 | E4: 3 | M4: lotions (skin care, hand creams)
B5: 4 | D5: 3 | E5: 3 | M5: nail polist,
B6: 4 | D6: 3 | E6: 3 | M6: candles
B7: 4 | D7: 3 | E7: 3
B8: 4 | D8: 3 | E8: 3 | M8: bags | N8: 6 | Q8: 6 | S8: high luxury
B9: 4 | D9: 2 | E9: 3 | M9: watches | S9: =SUM(N8:Q13) -> 38
B10: 4 | D10: 2 | E10: 3 | M10: dining | N10: 3 | O10: 1 | P10: 3 | Q10: 2
B11: 2 | D11: 3 | M11: jewellery | N11: 3 | Q11: 2
D12: 4 | M12: travel | N12: 1 | O12: 1 | P12: 2 | Q12: 2
D13: 4 | M13: hats | Q13: 6
D14: 4
D15: 4
D16: 4
D17: 4
D18: 4
D19: 4
G22: hemline index
B23: =AVERAGE(B2:B21) -> 3.7 | C23: =AVERAGE(C2:C21) -> 4 | D23: =AVERAGE(D2:D21) -> 3.5 | E23: =AVERAGE(E2:E21) -> 3.2222222 | G23: =AVERAGE(B23:E23) -> 3.6055556

Sheet 1985
B1: January | C1: April | D1: July | E1: October | M1: parfumes: | S1: small luxury
A2: all the data | B2: 3 | C2: 4 | D2: 4 | E2: 4 | M2: cosmetics | O2: 1 | S2: =SUM(N1:Q6) -> 1
A3: skkirt lengths | B3: 3 | C3: 5 | D3: 4 | E3: 4 | M3: lipstick
B4: 3 | C4: 5 | D4: 4 | E4: 4 | M4: lotions (skin care, hand creams)
C5: 5 | D5: 3 | E5: 4 | M5: nail polist,
C6: 5 | D6: 4 | E6: 4 | M6: candles
D7: 4 | E7: 4
D8: 4 | E8: 4 | M8: bags | N8: 6 | O8: 1 | S8: high luxury
D9: 4 | E9: 4 | M9: watches | N9: 1 | S9: =SUM(N8:Q13) -> 34
D10: 2 | E10: 4 | M10: dining | N10: 3 | O10: 3 | P10: 1 | Q10: 3
D11: 2 | E11: 4 | M11: jewellery | N11: 2 | Q11: 3
D12: 4 | E12: 4 | M12: travel | O12: 3 | P12: 5 | Q12: 3
D13: 4 | E13: 4 | M13: hats
D14: 4 | E14: 4
D15: 4 | E15: 4
E16: 4
E17: 4
E18: 4
E19: 4
E20: 4
G22: hemline index
B23: =AVERAGE(B2:B21) -> 3 | C23: =AVERAGE(C2:C21) -> 4.8 | D23: =AVERAGE(D2:D21) -> 3.6428571 | E23: =AVERAGE(E2:E21) -> 4 | G23: =AVERAGE(B23:E23) -> 3.8607143

Sheet 1986
B1: January | C1: April | D1: July | E1: October | M1: parfumes: | S1: small luxury
A2: all the data | B2: 3 | C2: 4 | D2: 4 | E2: 3 | M2: cosmetics | Q2: 1 | S2: =SUM(N1:Q6) -> 1
A3: skkirt lengths | C3: 4 | D3: 4 | E3: 3 | M3: lipstick
C4: 4 | D4: 4 | M4: lotions (skin care, hand creams)
C5: 4 | D5: 4 | M5: nail polist,
C6: 4 | D6: 4 | M6: candles
C7: 4 | D7: 4
C8: 4 | D8: 4 | M8: bags | O8: 1 | P8: 1 | S8: high luxury
D9: 4 | M9: watches | S9: =SUM(N8:Q13) -> 37
D10: 4 | M10: dining | Q10: 3
D11: 4 | M11: jewellery | N11: 4 | O11: 6 | P11: 3
D12: 4 | M12: travel | N12: 1 | O12: 2 | Q12: 1
D13: 4 | M13: hats | N13: 4 | O13: 11
D14: 4
D15: 4
G18: hemline index
B19: =AVERAGE(B2:B17) -> 3 | C19: =AVERAGE(C2:C17) -> 4 | D19: =AVERAGE(D2:D17) -> 4 | E19: =AVERAGE(E2:E17) -> 3 | G19: =AVERAGE(B19:E19) -> 3.5

Sheet 1987
B1: January | C1: April | D1: July | E1: October | M1: parfumes: | S1: small luxury
A2: all the data | B2: 5 | C2: 4 | D2: 4 | E2: 4 | M2: cosmetics | N2: 2 | S2: =SUM(N1:Q6) -> 2
A3: skkirt lengths | B3: 4 | C3: 4 | D3: 4 | M3: lipstick
B4: 4 | C4: 3 | D4: 4 | M4: lotions (skin care, hand creams)
B5: 4 | C5: 3 | D5: 4 | M5: nail polist,
D6: 4 | M6: candles
D7: 3
D8: 3 | M8: bags | O8: 2 | P8: 1 | S8: high luxury
D9: 4 | M9: watches | S9: =SUM(N8:Q13) -> 32
D10: 4 | M10: dining | N10: 3 | O10: 2 | P10: 4 | Q10: 1
D11: 4 | M11: jewellery | O11: 2 | P11: 2 | Q11: 1
D12: 4 | M12: travel | N12: 1 | O12: 1 | Q12: 5
D13: 4 | M13: hats | O13: 3 | P13: 3 | Q13: 1
D14: 4
D15: 4
G17: hemline index
B18: =AVERAGE(B2:B16) -> 4.25 | C18: =AVERAGE(C2:C16) -> 3.5 | D18: =AVERAGE(D2:D16) -> 3.8571429 | E18: =AVERAGE(E2:E16) -> 4 | G18: =AVERAGE(B18:E18) -> 3.9017857

Sheet 1988
B1: January | C1: April | D1: July | E1: October | M1: parfumes: | S1: small luxury
A2: all the data | B2: 4 | C2: 5 | D2: 5 | E2: 3 | M2: cosmetics | S2: 0
A3: skkirt lengths | B3: 4 | C3: 4 | D3: 4 | E3: 3 | M3: lipstick
B4: 5 | C4: 4 | D4: 4 | E4: 3 | M4: lotions (skin care, hand creams)
B5: 5 | C5: 4 | D5: 4 | E5: 3 | M5: nail polist,
D6: 4 | E6: 3 | M6: candles
D7: 4 | E7: 3
D8: 4 | E8: 3 | M8: bags | S8: high luxury
D9: 4 | E9: 3 | M9: watches | O9: 1 | S9: =SUM(N8:Q13) -> 25
E10: 4 | M10: dining | Q10: 1
E11: 3 | M11: jewellery | N11: 4 | O11: 4 | P11: 5 | Q11: 1
E12: 3 | M12: travel | N12: 1 | O12: 1 | P12: 1 | Q12: 1
M13: hats | N13: 1 | O13: 3 | P13: 1
G15: hemline index
B16: =AVERAGE(B2:B14) -> 4.5 | C16: =AVERAGE(C2:C14) -> 4.25 | D16: =AVERAGE(D2:D14) -> 4.125 | E16: =AVERAGE(E2:E14) -> 3.0909091 | G16: =AVERAGE(B16:E16) -> 3.9914773

Sheet 1989
B1: January | C1: April | D1: July | E1: October | M1: parfumes: | S1: small luxury
A2: all the data | B2: 4 | C2: 3 | D2: 4 | E2: 5 | M2: cosmetics | S2: 0
A3: skkirt lengths | B3: 5 | C3: 2 | D3: 4 | E3: 4 | M3: lipstick
B4: 4 | C4: 3 | D4: 4 | E4: 4 | M4: lotions (skin care, hand creams)
B5: 3 | C5: 3 | D5: 3 | E5: 4 | M5: nail polist,
B6: 3 | C6: 4 | D6: 3 | E6: 5 | M6: candles
D7: 3 | E7: 4
D8: 3 | E8: 4 | M8: bags | S8: high luxury
E9: 3 | M9: watches | S9: =SUM(N8:Q13) -> 32
M10: dining | N10: 2 | O10: 2 | P10: 1
M11: jewellery | N11: 4 | O11: 7 | P11: 2 | Q11: 3
M12: travel | N12: 1 | O12: 3 | P12: 4 | Q12: 1
G13: hemline index | M13: hats | O13: 1 | Q13: 1
B14: =AVERAGE(B2:B12) -> 3.8 | C14: =AVERAGE(C2:C12) -> 3 | D14: =AVERAGE(D2:D12) -> 3.4285714 | E14: =AVERAGE(E2:E12) -> 4.125 | G14: =AVERAGE(B14:E14) -> 3.5883929

Sheet 1990
B1: January | C1: April | D1: July | E1: October | M1: parfumes: | S1: small luxury
A2: all the data | B2: 4 | C2: 4 | E2: 4 | M2: cosmetics | S2: 0
A3: skkirt lengths | B3: 4 | C3: 4 | E3: 4 | M3: lipstick
C4: 4 | E4: 3 | M4: lotions (skin care, hand creams)
C5: 4 | E5: 5 | M5: nail polist,
C6: 4 | E6: 2 | M6: candles
C7: 5 | E7: 2
C8: 5 | E8: 4 | M8: bags | S8: high luxury
C9: 4 | E9: 3 | M9: watches | S9: =SUM(N8:Q13) -> 27
M10: dining | N10: 1 | Q10: 1
G11: hemline index | M11: jewellery | N11: 4 | O11: 6 | P11: 5 | Q11: 3
B12: =AVERAGE(B2:B9) -> 4 | C12: =AVERAGE(C2:C9) -> 4.25 | E12: =AVERAGE(E2:E9) -> 3.375 | G12: =AVERAGE(B12:E12) -> 3.875 | M12: travel | O12: 1
M13: hats | O13: 3 | P13: 3

Sheet 1991
E1: October | M1: parfumes: | S1: small luxury
A2: all the data | E2: 4 | M2: cosmetics | S2: 0
A3: skkirt lengths | E3: 4 | M3: lipstick
E4: 4 | M4: lotions (skin care, hand creams)
E5: 4 | M5: nail polist,
E6: 3 | M6: candles
E7: 4
E8: 4 | M8: bags | S8: high luxury
E9: 4 | M9: watches | S9: =SUM(N8:Q13) -> 5
E10: 4 | M10: dining
E11: 4 | M11: jewellery | Q11: 2
E12: 4 | M12: travel
E13: 3 | M13: hats | Q13: 3
E14: 3
E15: 4
E16: 3
E17: 4
E18: 4
G20: hemline index
E21: =AVERAGE(E2:E18) -> 3.7647059 | G21: =AVERAGE(B21:E21) -> 3.7647059

Sheet 1992
B1: January | C1: April | D1: July | E1: October | M1: parfumes: | S1: small luxury
A2: all the data | B2: 4 | C2: 2 | M2: cosmetics | O2: 1 | S2: =SUM(N1:Q6) -> 1
A3: skkirt lengths | B3: 5 | C3: 4 | M3: lipstick
M4: lotions (skin care, hand creams)
M5: nail polist,
M6: candles
G8: hemline index | M8: bags | S8: high luxury
B9: =AVERAGE(B2:B3) -> 4.5 | C9: =AVERAGE(C2:C3) -> 3 | G9: =AVERAGE(B9:E9) -> 3.75 | M9: watches | S9: =SUM(N8:Q13) -> 19
M10: dining
M11: jewellery | N11: 3 | O11: 1
M12: travel | N12: 1
M13: hats | N13: 6 | O13: 8
