Workbook

Sheet Results
B1: January | C1: April | D1: July | E1: October | M1: parfumes: | S1: small luxury
A2: all the data | M2: cosmetics | S2: =AVERAGE(N1:Q6) -> #DIV/0!
A3: skkirt lengths | M3: lipstick
M4: lotions (skin care, hand creams)
M5: nail polist,
M6: candles
M8: bags | S8: high luxury
M9: watches | S9: =AVERAGE(N8:Q13) -> #DIV/0!
M10: dining
M11: jewellery
M12: travel
M13: hats
H15: hemline index
B16: AVERAGE | C16: =AVERAGE(#REF!) -> #REF! | D16: =AVERAGE(#REF!) -> #REF! | E16: =AVERAGE(#REF!) -> #REF! | F16: =AVERAGE(#REF!) -> #REF! | H16: =AVERAGE(C16:F16) -> #REF!
A21: HEMLINE INDEXES | M21: LIPSTICK INDEX
C22: Reversed | N22: Small | O22: High | AA22: Subtracting low luxuries from high value luxuries
A23: 1957 | B23: =VALUE('1957'!G42) -> 3.6222222 | C23: =VALUE(6-B23) -> 2.3777778 | M23: 1957 | N23: =VALUE('1957'!N2) -> 5 | O23: =VALUE('1957'!N9) -> 47 | AA23: 1957 | AB23: =O23-N23 -> 42
A24: 1958 | B24: =VALUE('1958'!G47) -> 3.2639137 | C24: =VALUE(6-B24) -> 2.7360863 | M24: 1958 | N24: =VALUE('1958'!N2) -> 3 | O24: =VALUE('1958'!N9) -> 91 | AA24: 1958 | AB24: =O24-N24 -> 88
A25: 1959 | B25: =VALUE('1959'!G79) -> 3.3778958 | C25: =VALUE(6-B25) -> 2.6221042 | M25: 1959 | N25: =VALUE('1959'!N2) -> 8 | O25: =VALUE('1959'!N9) -> 46 | AA25: 1959 | AB25: =O25-N25 -> 38
A26: 1960 | B26: =VALUE('1960'!G42) -> 3.2278139 | C26: =VALUE(6-B26) -> 2.7721861 | M26: 1960 | N26: =VALUE('1960'!N2) -> 4 | O26: =VALUE('1960'!N9) -> 71 | AA26: 1960 | AB26: =O26-N26 -> 67
A27: 1961 | B27: =VALUE('1961'!G48) -> 3.1498127 | C27: =VALUE(6-B27) -> 2.8501873 | M27: 1961 | N27: =VALUE('1961'!N2) -> 8 | O27: =VALUE('1961'!N9) -> 66 | AA27: 1961 | AB27: =O27-N27 -> 58
A28: 1962 | B28: =VALUE('1962'!G44) -> 3.1744851 | C28: =VALUE(6-B28) -> 2.8255149 | M28: 1962 | N28: =VALUE('1962'!N2) -> 1 | O28: =VALUE('1962'!N9) -> 58 | AA28: 1962 | AB28: =O28-N28 -> 57
A29: 1963 | B29: =VALUE('1963'!G39) -> 3.1470588 | C29: =VALUE(6-B29) -> 2.8529412 | M29: 1963 | N29: =VALUE('1963'!N2) -> 1 | O29: =VALUE('1963'!N9) -> 21 | AA29: 1963 | AB29: =O29-N29 -> 20
A30: 1964 | B30: =VALUE('1964'!G50) -> 2.9318182 | C30: =VALUE(6-B30) -> 3.0681818 | M30: 1964 | N30: =VALUE('1964'!N2) -> 1 | O30: =VALUE('1964'!N9) -> 33 | AA30: 1964 | AB30: =O30-N30 -> 32
A31: 1965 | B31: =VALUE('1965'!G45) -> 3.1897436 | C31: =VALUE(6-B31) -> 2.8102564 | M31: 1965 | N31: =VALUE('1965'!N2) -> 4 | O31: =VALUE('1965'!N9) -> 24 | AA31: 1965 | AB31: =O31-N31 -> 20
A32: 1966 | B32: =VALUE('1966'!G57) -> 2.7940115 | C32: =VALUE(6-B32) -> 3.2059885 | M32: 1966 | N32: =VALUE('1966'!N2) -> 0 | O32: =VALUE('1966'!N9) -> 45 | AA32: 1966 | AB32: =O32-N32 -> 45
A33: 1967 | B33: =VALUE('1967'!G53) -> 2.5475543 | C33: =VALUE(6-B33) -> 3.4524457 | M33: 1967 | N33: =VALUE('1967'!N2) -> 2 | O33: =VALUE('1967'!N9) -> 18 | AA33: 1967 | AB33: =O33-N33 -> 16
A34: 1968 | B34: =VALUE('1968'!G63) -> 2.2939241 | C34: =VALUE(6-B34) -> 3.7060759 | M34: 1968 | N34: =VALUE('1968'!N2) -> 1 | O34: =VALUE('1968'!N9) -> 34 | AA34: 1968 | AB34: =O34-N34 -> 33
A35: 1969 | B35: =VALUE('1969'!G49) -> 1.9533206 | C35: =VALUE(6-B35) -> 4.0466794 | M35: 1969 | N35: =VALUE('1969'!N2) -> 9 | O35: =VALUE('1969'!N9) -> 65 | AA35: 1969 | AB35: =O35-N35 -> 56
A36: 1970 | B36: =VALUE('1970'!G51) -> 2.9312624 | C36: =VALUE(6-B36) -> 3.0687376 | M36: 1970 | N36: =VALUE('1970'!N2) -> 10 | O36: =VALUE('1970'!N9) -> 49 | AA36: 1970 | AB36: =O36-N36 -> 39
A37: 1971 | B37: =VALUE('1971'!G58) -> 3.5524953 | C37: =VALUE(6-B37) -> 2.4475047 | M37: 1971 | N37: =VALUE('1971'!N2) -> 2 | O37: =VALUE('1971'!N9) -> 82 | AA37: 1971 | AB37: =O37-N37 -> 80
A38: 1972 | B38: =VALUE('1972'!G51) -> 3.01926 | C38: =VALUE(6-B38) -> 2.98074 | M38: 1972 | N38: =VALUE('1972'!N2) -> 1 | O38: =VALUE('1972'!N9) -> 60 | AA38: 1972 | AB38: =O38-N38 -> 59
A39: 1973 | B39: =VALUE('1973'!G40) -> 2.6832088 | C39: =VALUE(6-B39) -> 3.3167912 | M39: 1973 | N39: =VALUE('1973'!N2) -> 3 | O39: =VALUE('1973'!N9) -> 54 | AA39: 1973 | AB39: =O39-N39 -> 51
A40: 1974 | B40: =VALUE('1974'!G68) -> 3.759084 | C40: =VALUE(6-B40) -> 2.240916 | M40: 1974 | N40: =VALUE('1974'!N2) -> 4 | O40: =VALUE('1974'!N9) -> 55 | AA40: 1974 | AB40: =O40-N40 -> 51
A41: 1975 | B41: =VALUE('1975'!G74) -> 3.9104497 | C41: =VALUE(6-B41) -> 2.0895503 | M41: 1975 | N41: =VALUE('1975'!N2) -> 5 | O41: =VALUE('1975'!N9) -> 78 | AA41: 1975 | AB41: =O41-N41 -> 73
A42: 1976 | B42: =VALUE('1976'!G68) -> 3.9118893 | C42: =VALUE(6-B42) -> 2.0881107 | M42: 1976 | N42: =VALUE('1976'!N2) -> 11 | O42: =VALUE('1976'!N9) -> 134 | AA42: 1976 | AB42: =O42-N42 -> 123
A43: 1977 | B43: =VALUE('1977'!G74) -> 3.7560394 | C43: =VALUE(6-B43) -> 2.2439606 | M43: 1977 | N43: =VALUE('1977'!N2) -> 19 | O43: =VALUE('1977'!N9) -> 137 | AA43: 1977 | AB43: =O43-N43 -> 118
A44: 1978 | B44: =VALUE('1978'!G76) -> 3.9382754 | C44: =VALUE(6-B44) -> 2.0617246 | M44: 1978 | N44: =VALUE('1978'!N2) -> 10 | O44: =VALUE('1978'!N9) -> 212 | AA44: 1978 | AB44: =O44-N44 -> 202
A45: 1979 | B45: =VALUE('1979'!G82) -> 4.116014 | C45: =VALUE(6-B45) -> 1.883986 | M45: 1979 | N45: =VALUE('1979'!N2) -> 12 | O45: =VALUE('1979'!N9) -> 167 | AA45: 1979 | AB45: =O45-N45 -> 155
A46: 1980 | B46: =VALUE('1980'!G78) -> 3.6742422 | C46: =VALUE(6-B46) -> 2.3257578 | M46: 1980 | N46: =VALUE('1980'!N2) -> 2 | O46: =VALUE('1980'!N9) -> 207 | AA46: 1980 | AB46: =O46-N46 -> 205
...

Sheet 1957
A1: 32 | B1: January | C1: April | D1: July | E1: October | H1: parfumes: | N1: small luxury
A2: all the data | B2: 4 | C2: 4 | D2: 4 | E2: 4 | H2: cosmetics | N2: =SUM(I1:L6) -> 5
A3: skkirt lengths | B3: 4 | C3: 4 | D3: 4 | E3: 4 | H3: lipstick
B4: 5 | C4: 4 | D4: 4 | E4: 4 | H4: lotions, skin care, hand creams | I4: 1 | K4: 4
B5: 3 | C5: 4 | D5: 1 | E5: 4 | H5: nail polist,
B6: 4 | C6: 4 | D6: 1 | E6: 4 | H6: candles
B7: 4 | C7: 6 | D7: 4 | E7: 4
B8: 4 | C8: 4 | D8: 4 | E8: 3 | H8: bags | K8: 6 | L8: 3 | N8: high luxury
B9: 4 | C9: 4 | D9: 4 | E9: 3 | H9: watches | L9: 1 | N9: =SUM(I8:L13) -> 47
B10: 4 | C10: 4 | D10: 3 | E10: 3 | H10: dining
B11: 4 | C11: 4 | D11: 4 | E11: 3 | H11: jewellery | J11: 1 | L11: 2
B12: 4 | C12: 4 | D12: 1 | E12: 3 | H12: travel
B13: 4 | C13: 4 | D13: 4 | E13: 3 | H13: hats | J13: 6 | K13: 5 | L13: 23
B14: 4 | C14: 4 | D14: 4 | E14: 3
B15: 4 | C15: 4 | D15: 4 | E15: 4
B16: 4 | C16: 4 | D16: 4 | E16: 4
B17: 4 | C17: 4 | D17: 4 | E17: 4
B18: 4 | C18: 4 | D18: 4 | E18: 3
B19: 4 | C19: 4 | D19: 4 | E19: 3
B20: 4 | C20: 4 | D20: 4 | E20: 3
B21: 4 | C21: 4 | D21: 3 | E21: 4
B22: 5 | C22: 4 | D22: 5 | E22: 4
B23: 6 | C23: 4 | D23: 4 | E23: 4
B24: 3 | C24: 4 | D24: 4 | E24: 3
B25: 2 | C25: 4 | D25: 1 | E25: 3
... B31: 4 | C31: 2 | D31: 4 | E31: 6
B32: 3 | C32: 2 | E32: 4
C33: 2 | E33: 4
C34: 2 | E34: 3
C35: 2 | E35: 3
C36: 4 | E36: 4
C37: 4
G41: hemline index
A42: AVERAGE | B42: =AVERAGE(B2:B40) -> 4 | C42: =AVERAGE(C2:C40) -> 3.7222222 | D42: =AVERAGE(D2:D40) -> 3.3666667 | E42: =AVERAGE(E2:E40) -> 3.4 | G42: =AVERAGE(B42:E42) -> 3.6222222

Sheet 1958
A1: 32 | B1: January | C1: MÁJUS | D1: July | E1: October | H1: parfumes: | I1: 1 | K1: 1 | N1: small luxury
A2: all the data | B2: 5 | C2: 3 | D2: 3 | E2: 4 | H2: cosmetics | I2: 1 | N2: =SUM(I1:L6) -> 3
A3: skkirt lengths | B3: 6 | C3: 4 | D3: 4 | E3: 4 | H3: lipstick
B4: 4 | C4: 4 | D4: 1 | E4: 4 | H4: lotions, skin care, hand creams
B5: 4 | C5: 3 | D5: 4 | E5: 4 | H5: nail polist,
B6: 4 | C6: 3 | D6: 4 | E6: 4 | H6: candles
B7: 4 | C7: 3 | D7: 4 | E7: 4
B8: 5 | C8: 3 | D8: 6 | E8: 5 | H8: bags | J8: 8 | K8: 6 | L8: 3 | N8: high luxury
B9: 5 | C9: 3 | D9: 3 | E9: 6 | H9: watches | N9: =SUM(I8:L13) -> 91
B10: 4 | C10: 3 | D10: 3 | E10: 3 | H10: dining
B11: 3 | C11: 3 | D11: 3 | E11: 3 | H11: jewellery | I11: 6 | J11: 5 | K11: 8 | L11: 1
B12: 4 | C12: 3 | D12: 3 | E12: 3 | H12: travel
B13: 3 | C13: 3 | D13: 3 | E13: 4 | H13: hats | I13: 6 | J13: 15 | K13: 13 | L13: 20
B14: 3 | C14: 3 | D14: 3 | E14: 4
B15: 3 | C15: 3 | D15: 1 | E15: 4
B16: 3 | C16: 4 | D16: 3 | E16: 4
B17: 3 | C17: 4 | D17: 3 | E17: 4
B18: 3 | C18: 1 | D18: 3 | E18: 4
B19: 4 | C19: 1 | D19: 3 | E19: 4
B20: 3 | C20: 3 | D20: 4 | E20: 3
B21: 3 | C21: 1 | D21: 4 | E21: 3
B22: 3 | C22: 1 | D22: 4 | E22: 3
B23: 3 | C23: 1 | D23: 4 | E23: 3
B24: 4 | C24: 1 | D24: 3 | E24: 3
B25: 4 | C25: 4 | D25: 1 | E25: 3
B26: 4 | C26: 4 | D26: 3 | E26: 4
B27: 3 | C27: 4 | E27: 3
B28: 3 | C28: 3 | E28: 3
B29: 3 | C29: 3 | E29: 1
B30: 1 | C30: 4 | E30: 1
B31: 1 | C31: 6 | E31: 3
B32: 1 | C32: 1 | E32: 3
B33: 1 | C33: 1 | E33: 3
B34: 3 | E34: 6
B35: 3 | E35: 1
B36: 4 | E36: 6
B37: 6 | E37: 5
E38: 4
E39: 4
E40: 3
...

Sheet 1959
B1: January | C1: MÁRCIUS | D1: SZEPTEMBER | H1: parfumes: | N1: small luxury
A2: all the data | B2: 3 | C2: 5 | D2: 3 | H2: cosmetics | I2: 1 | J2: 6 | K2: 1 | N2: =SUM(I1:L6) -> 8
A3: skkirt lengths | B3: 4 | C3: 3 | D3: 4 | H3: lipstick
B4: 3 | C4: 3 | D4: 4 | H4: lotions, skin care, hand creams
B5: 3 | C5: 3 | D5: 4 | H5: nail polist,
B6: 3 | C6: 3 | D6: 3 | H6: candles
B7: 3 | C7: 3 | D7: 3
B8: 3 | C8: 4 | D8: 3 | H8: bags | I8: 1 | J8: 2 | K8: 4 | N8: high luxury
B9: 3 | C9: 4 | D9: 3 | H9: watches | N9: =SUM(I8:L13) -> 46
B10: 3 | C10: 4 | D10: 3 | H10: dining
B11: 4 | C11: 4 | D11: 4 | H11: jewellery | I11: 1 | J11: 1
B12: 4 | C12: 4 | D12: 4 | H12: travel
B13: 4 | C13: 4 | D13: 4 | H13: hats | I13: 5 | J13: 11 | K13: 21
B14: 4 | C14: 4 | D14: 4
B15: 4 | C15: 4 | D15: 4
B16: 4 | C16: 4 | D16: 3
B17: 4 | C17: 4 | D17: 3
B18: 3 | C18: 3 | D18: 3
B19: 3 | C19: 3 | D19: 3
B20: 3 | C20: 3 | D20: 3
B21: 3 | C21: 3 | D21: 3
B22: 3 | C22: 3 | D22: 3
B23: 3 | C23: 3 | D23: 3
B24: 3 | C24: 3 | D24: 3
B25: 3 | C25: 3 | D25: 3
... B43: 5 | C43: 3 | D43: 1
B44: 1 | C44: 3
B45: 1 | C45: 4
B46: 1 | C46: 4
B47: 1 | C47: 4
B48: 3 | C48: 6
B49: 2 | C49: 6
C50: 4
C51: 4
C52: 3
C53: 4
C54: 4
C55: 6
C56: 2
C57: 3
...

Sheet 1960
B1: January | C1: April | D1: July | E1: October | H1: parfumes: | I1: 1 | N1: small luxury
A2: all the data | B2: 5 | C2: 3 | D2: 4 | E2: 3 | H2: cosmetics | J2: 1 | K2: 1 | N2: =SUM(I1:L6) -> 4
A3: skkirt lengths | B3: 6 | C3: 3 | D3: 4 | E3: 3 | H3: lipstick | I3: 1
B4: 3 | C4: 3 | D4: 4 | E4: 4 | H4: lotions, skin care, hand creams
B5: 3 | C5: 4 | D5: 4 | E5: 4 | H5: nail polist,
B6: 3 | C6: 3 | D6: 3 | E6: 3 | H6: candles
B7: 4 | C7: 3 | D7: 3 | E7: 3
B8: 4 | C8: 3 | D8: 3 | E8: 3 | H8: bags | J8: 5 | K8: 2 | L8: 4 | N8: high luxury
B9: 3 | C9: 3 | D9: 4 | E9: 3 | H9: watches | N9: =SUM(I8:L13) -> 71
B10: 3 | C10: 3 | D10: 4 | E10: 3 | H10: dining
B11: 3 | C11: 3 | D11: 4 | E11: 3 | H11: jewellery | I11: 3 | J11: 4 | K11: 4 | L11: 1
B12: 3 | C12: 3 | D12: 4 | E12: 3 | H12: travel | I12: 1
B13: 3 | C13: 3 | D13: 4 | E13: 3 | H13: hats | I13: 11 | J13: 10 | K13: 11 | L13: 15
B14: 3 | C14: 3 | D14: 4 | E14: 3
B15: 3 | C15: 3 | D15: 4 | E15: 3
B16: 3 | C16: 4 | D16: 4 | E16: 3
B17: 1 | C17: 4 | D17: 4 | E17: 3
B18: 1 | C18: 1 | D18: 5 | E18: 3
B19: 3 | C19: 4 | D19: 3 | E19: 3
B20: 3 | C20: 4 | D20: 4 | E20: 3
B21: 3 | C21: 4 | D21: 4 | E21: 3
B22: 3 | C22: 4 | D22: 3 | E22: 3
B23: 3 | D23: 3 | E23: 3
D24: 1 | E24: 3
D25: 1 | E25: 3
D26: 3 | E26: 3
D27: 3 | E27: 3
D28: 3 | E28: 3
D29: 3 | E29: 4
D30: 4 | E30: 4
D31: 5 | E31: 2
D32: 4 | E32: 3
D33: 1 | E33: 3
D34: 1 | E34: 4
E35: 4
E36: 3
G41: hemline index
A42: AVERAGE | B42: =AVERAGE(B2:B40) -> 3.1363636 | C42: =AVERAGE(C2:C40) -> 3.2380952 | D42: =AVERAGE(D2:D40) -> 3.3939394 | E42: =AVERAGE(E2:E40) -> 3.1428571 | G42: =AVERAGE(B42:E42) -> 3.2278139

Sheet 1961
B1: FEBRUARY | C1: April | D1: July | E1: October | H1: parfumes: | I1: 1 | K1: 1 | N1: small luxury
A2: all the data | B2: 3 | C2: 2 | D2: 3 | E2: 2 | H2: cosmetics | J2: 1 | K2: 1 | N2: =SUM(I1:L6) -> 8
A3: skkirt lengths | B3: 3 | C3: 3 | D3: 3 | E3: 3 | H3: lipstick | I3: 1 | K3: 1
B4: 3 | C4: 4 | D4: 3 | E4: 3 | H4: lotions, skin care, hand creams | I4: 2
B5: 3 | C5: 4 | D5: 4 | E5: 3 | H5: nail polist,
B6: 3 | C6: 4 | D6: 4 | E6: 4 | H6: candles
B7: 3 | C7: 3 | D7: 3 | E7: 4
B8: 3 | C8: 3 | D8: 1 | E8: 4 | H8: bags | I8: 4 | J8: 8 | K8: 8 | L8: 1 | N8: high luxury
B9: 3 | C9: 3 | D9: 1 | E9: 4 | H9: watches | I9: 1 | N9: =SUM(I8:L13) -> 66
B10: 4 | C10: 4 | D10: 3 | E10: 4 | H10: dining
B11: 4 | C11: 4 | D11: 3 | E11: 3 | H11: jewellery | I11: 2 | K11: 3
B12: 4 | C12: 4 | D12: 3 | E12: 2 | H12: travel | I12: 1
B13: 3 | C13: 3 | D13: 3 | E13: 3 | H13: hats | I13: 3 | J13: 12 | K13: 9 | L13: 14
B14: 3 | C14: 3 | D14: 3 | E14: 3
B15: 4 | C15: 3 | D15: 3 | E15: 3
B16: 4 | C16: 3 | D16: 3 | E16: 3
B17: 3 | C17: 3 | D17: 4 | E17: 3
B18: 3 | C18: 3 | D18: 3 | E18: 3
B19: 3 | C19: 3 | D19: 3 | E19: 3
B20: 3 | C20: 3 | D20: 3 | E20: 3
B21: 3 | C21: 3 | D21: 3 | E21: 4
B22: 3 | C22: 4 | D22: 3 | E22: 4
B23: 3 | C23: 4 | D23: 2 | E23: 3
B24: 3 | C24: 6 | D24: 3 | E24: 3
B25: 3 | C25: 6 | D25: 1 | E25: 3
... B30: 6 | C30: 3 | D30: 3 | E30: 3
C31: 3 | D31: 3 | E31: 3
C32: 3 | D32: 3 | E32: 3
C33: 3 | D33: 3
C34: 3 | D34: 3
C35: 1 | D35: 3
C36: 1 | D36: 4
C37: 2 | D37: 3
D38: 3
D39: 3
D40: 1
G47: hemline index
A48: AVERAGE | B48: =AVERAGE(B2:B46) -> 3.2413793 | C48: =AVERAGE(C2:C46) -> 3.2222222 | D48: =AVERAGE(D2:D46) -> 2.974359 | E48: =AVERAGE(E2:E46) -> 3.1612903 | G48: =AVERAGE(B48:E48) -> 3.1498127

Sheet 1962
B1: DECEMBER | C1: April | D1: July | E1: October | H1: parfumes: | I1: 1 | N1: small luxury
A2: all the data | B2: 3 | E2: 3 | H2: cosmetics | N2: =SUM(I1:L6) -> 1
A3: skkirt lengths | B3: 3 | E3: 3 | H3: lipstick
B4: 3 | E4: 3 | H4: lotions, skin care, hand creams
B5: 3 | E5: 3 | H5: nail polist,
B6: 4 | E6: 3 | H6: candles
B7: 4 | E7: 3
B8: 4 | E8: 3 | H8: bags | I8: 3 | L8: 2 | N8: high luxury
B9: 4 | E9: 3 | H9: watches | N9: =SUM(I8:L13) -> 58
B10: 4 | E10: 3 | H10: dining
B11: 3 | E11: 3 | H11: jewellery | I11: 9
B12: 3 | E12: 3 | H12: travel
B13: 3 | E13: 3 | H13: hats | I13: 12 | L13: 32
B14: 3 | E14: 3
B15: 3 | E15: 3
B16: 3 | E16: 3
B17: 3 | E17: 3
B18: 3 | E18: 3
B19: 3 | E19: 3
B20: 3 | E20: 3
B21: 3 | E21: 6
B22: 3 | E22: 6
B23: 3 | E23: 4
B24: 3 | E24: 3
E25: 3
E26: 3
E27: 2
E28: 3
E29: 3
E30: 3
E31: 3
E32: 2
E33: 3
E34: 3
E35: 3
E36: 3
... E39: 3
G43: hemline index
A44: AVERAGE | B44: =AVERAGE(B2:B41) -> 3.2173913 | E44: =AVERAGE(E2:E41) -> 3.1315789 | G44: =AVERAGE(B44:E44) -> 3.1744851

Sheet 1963
B1: January | C1: April | D1: July | E1: SZEPTEMBER | H1: parfumes: | N1: small luxury
A2: all the data | E2: 3 | H2: cosmetics | L2: 1 | N2: =SUM(I1:L6) -> 1
A3: skkirt lengths | E3: 3 | H3: lipstick
E4: 4 | H4: lotions, skin care, hand creams
E5: 4 | H5: nail polist,
E6: 4 | H6: candles
E7: 4
E8: 3 | H8: bags | L8: 2 | N8: high luxury
E9: 3 | H9: watches | N9: =SUM(I8:L13) -> 21
E10: 3 | H10: dining
E11: 3 | H11: jewellery | L11: 2
E12: 3 | H12: travel
E13: 4 | H13: hats | L13: 17
E14: 4
E15: 3
E16: 3
E17: 3
E18: 3
E19: 3
E20: 3
E21: 3
E22: 3
E23: 3
E24: 3
E25: 3
... E35: 3
G38: hemline index
A39: AVERAGE | E39: =AVERAGE(E2:E37) -> 3.1470588 | G39: =AVERAGE(B39:E39) -> 3.1470588

Sheet 1964
B1: January | C1: April | D1: July | E1: October | H1: parfumes: | J1: 1 | N1: small luxury
A2: all the data | C2: 3 | H2: cosmetics | N2: =SUM(I1:L6) -> 1
A3: skkirt lengths | C3: 3 | H3: lipstick
C4: 3 | H4: lotions, skin care, hand creams
C5: 3 | H5: nail polist,
C6: 3 | H6: candles
C7: 3
C8: 2 | H8: bags | J8: 7 | N8: high luxury
C9: 3 | H9: watches | N9: =SUM(I8:L13) -> 33
C10: 2 | H10: dining
C11: 3 | H11: jewellery | J11: 5
C12: 3 | H12: travel
C13: 3 | H13: hats | J13: 21
C14: 3
C15: 3
C16: 3
C17: 3
C18: 3
C19: 3
C20: 3
C21: 2
C22: 3
C23: 3
C24: 3
C25: 3
... C45: 3
G49: hemline index
A50: AVERAGE | C50: =AVERAGE(C2:C47) -> 2.9318182 | G50: =AVERAGE(B50:E50) -> 2.9318182

Sheet 1965
B1: FEBRUARY | C1: April | D1: July | E1: October | H1: parfumes: | N1: small luxury
A2: all the data | B2: 3 | E2: 4 | H2: cosmetics | I2: 1 | L2: 2 | N2: =SUM(I1:L6) -> 4
A3: skkirt lengths | B3: 3 | E3: 4 | H3: lipstick | L3: 1
B4: 4 | E4: 3 | H4: lotions, skin care, hand creams
B5: 3 | E5: 3 | H5: nail polist,
B6: 3 | E6: 3 | H6: candles
B7: 3 | E7: 3
B8: 3 | E8: 3 | H8: bags | I8: 1 | L8: 5 | N8: high luxury
B9: 3 | E9: 3 | H9: watches | N9: =SUM(I8:L13) -> 24
B10: 3 | E10: 3 | H10: dining
B11: 3 | E11: 5 | H11: jewellery | I11: 2
B12: 3 | E12: 3 | H12: travel
B13: 3 | E13: 4 | H13: hats | I13: 7 | L13: 9
B14: 3 | E14: 3
B15: 3 | E15: 3
B16: 3 | E16: 3
B17: 3 | E17: 3
B18: 3 | E18: 3
B19: 3 | E19: 3
B20: 3 | E20: 3
B21: 3 | E21: 3
B22: 3 | E22: 3
B23: 3 | E23: 3
B24: 2 | E24: 3
B25: 3 | E25: 3
... B31: 6 | E31: 5
E32: 3
E33: 3
E34: 3
E35: 3
E36: 2
E37: 3
E38: 3
E39: 3
E40: 3
G44: hemline index
A45: AVERAGE | B45: =AVERAGE(B2:B43) -> 3.2 | E45: =AVERAGE(E2:E43) -> 3.1794872 | G45: =AVERAGE(B45:E45) -> 3.1897436

Sheet 1966
B1: January | C1: April | D1: July | E1: October | H1: parfumes: | N1: small luxury
A2: all the data | B2: 2 | C2: 3 | D2: 1 | E2: 2 | H2: cosmetics | N2: 0
A3: skkirt lengths | B3: 3 | C3: 3 | D3: 2 | E3: 2 | H3: lipstick
B4: 3 | C4: 3 | D4: 3 | E4: 3 | H4: lotions, skin care, hand creams
B5: 3 | C5: 3 | D5: 4 | E5: 3 | H5: nail polist,
B6: 2 | C6: 3 | D6: 3 | E6: 3 | H6: candles
B7: 3 | C7: 3 | D7: 4 | E7: 3
B8: 3 | C8: 2 | D8: 4 | E8: 3 | H8: bags | I8: 1 | J8: 3 | K8: 2 | L8: 1 | N8: high luxury
B9: 2 | C9: 3 | D9: 3 | E9: 2 | H9: watches | N9: =SUM(I8:L13) -> 45
B10: 3 | C10: 3 | D10: 2 | E10: 2 | H10: dining
B11: 3 | C11: 3 | D11: 2 | E11: 3 | H11: jewellery | I11: 4 | L11: 3
B12: 3 | C12: 3 | D12: 3 | E12: 3 | H12: travel
B13: 2 | C13: 3 | D13: 2 | E13: 3 | H13: hats | I13: 8 | J13: 4 | K13: 2 | L13: 17
B14: 3 | C14: 3 | D14: 2 | E14: 3
B15: 3 | C15: 2 | D15: 3 | E15: 3
B16: 3 | C16: 2 | D16: 3 | E16: 3
B17: 3 | C17: 2 | D17: 3 | E17: 3
B18: 3 | C18: 3 | D18: 2 | E18: 3
B19: 3 | C19: 3 | D19: 3 | E19: 3
B20: 3 | C20: 5 | D20: 1 | E20: 3
B21: 3 | C21: 2 | D21: 3 | E21: 3
B22: 3 | C22: 3 | D22: 3 | E22: 2
B23: 2 | C23: 3 | D23: 3 | E23: 3
B24: 2 | C24: 2 | D24: 3 | E24: 3
B25: 2 | C25: 2 | D25: 3 | E25: 3
B26: 3 | C26: 3 | D26: 3 | E26: 3
B27: 3 | C27: 3 | D27: 3
B28: 3 | C28: 3 | D28: 3
B29: 3 | C29: 2 | D29: 3
B30: 2 | C30: 3 | D30: 3
B31: 3 | C31: 3 | D31: 3
C32: 3 | D32: 2
C33: 2 | D33: 3
C34: 3 | D34: 2
C35: 2 | D35: 3
C36: 3 | D36: 3
C37: 3 | D37: 5
C38: 3 | D38: 3
C39: 3 | D39: 3
C40: 3
...

Sheet 1967
B1: FEBRUARY | C1: April | D1: July | E1: DECEMBER | H1: parfumes: | L1: 1 | N1: small luxury
A2: all the data | B2: 3 | E2: 2 | H2: cosmetics | N2: =SUM(I1:L6) -> 2
A3: skkirt lengths | B3: 3 | E3: 3 | H3: lipstick
B4: 2 | E4: 1 | H4: lotions, skin care, hand creams | I4: 1
B5: 2 | E5: 2 | H5: nail polist,
B6: 3 | E6: 3 | H6: candles
B7: 3 | E7: 3
B8: 2 | E8: 3 | H8: bags | L8: 1 | N8: high luxury
B9: 3 | E9: 3 | H9: watches | N9: =SUM(I8:L13) -> 18
B10: 3 | E10: 3 | H10: dining
B11: 3 | E11: 1 | H11: jewellery | L11: 1
B12: 3 | E12: 2 | H12: travel
B13: 3 | E13: 2 | H13: hats | I13: 10 | L13: 6
B14: 3 | E14: 2
B15: 3 | E15: 1
B16: 3 | E16: 1
B17: 3 | E17: 2
B18: 2 | E18: 3
B19: 2 | E19: 3
B20: 3 | E20: 2
B21: 3 | E21: 2
B22: 3 | E22: 2
B23: 2 | E23: 2
B24: 2 | E24: 2
B25: 3 | E25: 2
... B33: 2 | E33: 2
E34: 3
E35: 2
E36: 2
E37: 2
E38: 2
E39: 2
E40: 2
E41: 6
E42: 2
E43: 3
E44: 2
E45: 3
... E47: 3
G52: hemline index
...

Sheet 1968
B1: January | C1: April | D1: July | E1: October | H1: parfumes: | N1: small luxury
A2: all the data | B2: 2 | C2: 2 | D2: 1 | E2: 2 | H2: cosmetics | L2: 1 | N2: =SUM(I1:L6) -> 1
A3: skkirt lengths | B3: 2 | C3: 2 | D3: 2 | E3: 2 | H3: lipstick
B4: 2 | C4: 2 | D4: 1 | E4: 2 | H4: lotions, skin care, hand creams
B5: 2 | C5: 3 | D5: 2 | E5: 2 | H5: nail polist,
B6: 2 | C6: 2 | D6: 2 | E6: 3 | H6: candles
B7: 2 | C7: 2 | D7: 1 | E7: 2
B8: 2 | C8: 2 | D8: 1 | E8: 2 | H8: bags | K8: 2 | N8: high luxury
B9: 2 | C9: 2 | D9: 2 | E9: 2 | H9: watches | N9: =SUM(I8:L13) -> 34
B10: 2 | C10: 2 | D10: 2 | E10: 2 | H10: dining
B11: 2 | C11: 2 | D11: 2 | E11: 2 | H11: jewellery | I11: 3 | L11: 3
B12: 2 | C12: 3 | D12: 2 | E12: 1 | H12: travel | J12: 2
B13: 2 | C13: 3 | D13: 2 | E13: 2 | H13: hats | I13: 3 | J13: 12 | K13: 5 | L13: 4
B14: 2 | C14: 2 | D14: 2 | E14: 2
B15: 2 | C15: 2 | D15: 2 | E15: 2
B16: 2 | C16: 2 | D16: 2 | E16: 5
B17: 3 | C17: 2 | D17: 3 | E17: 2
B18: 2 | C18: 2 | D18: 2 | E18: 2
B19: 2 | C19: 2 | D19: 2 | E19: 2
B20: 2 | C20: 2 | D20: 3 | E20: 3
B21: 2 | C21: 2 | D21: 2 | E21: 3
B22: 3 | C22: 2 | D22: 1 | E22: 3
B23: 3 | C23: 3 | D23: 2 | E23: 3
B24: 2 | C24: 2 | D24: 3 | E24: 4
B25: 3 | C25: 2 | D25: 3 | E25: 2
... B47: 2 | C47: 2 | D47: 2 | E47: 2
B48: 2 | D48: 2 | E48: 2
B49: 5 | E49: 2
B50: 1 | E50: 3
B51: 2 | E51: 4
B52: 2
B53: 2
B54: 3
B55: 1
B56: 2
B57: 3
G62: hemline index
A63: AVERAGE | B63: =AVERAGE(B2:B61) -> 2.3392857 | C63: =AVERAGE(C2:C61) -> 2.3913043 | D63: =AVERAGE(D2:D61) -> 2.0851064 | E63: =AVERAGE(E2:E61) -> 2.36 | G63: =AVERAGE(B63:E63) -> 2.2939241

Sheet 1969
B1: January | C1: April | D1: July | E1: October | H1: parfumes: | N1: small luxury
A2: all the data | B2: 5 | C2: 2 | D2: 1 | E2: 2 | H2: cosmetics | L2: 4 | N2: =SUM(I1:L6) -> 9
A3: skkirt lengths | B3: 6 | C3: 2 | D3: 2 | E3: 1 | H3: lipstick
B4: 5 | C4: 2 | D4: 2 | E4: 2 | H4: lotions, skin care, hand creams | K4: 4
B5: 2 | C5: 2 | D5: 2 | E5: 4 | H5: nail polist, | J5: 1
B6: 2 | C6: 2 | D6: 1 | E6: 2 | H6: candles
B7: 2 | C7: 2 | D7: 2 | E7: 2
B8: 2 | C8: 2 | D8: 2 | E8: 2 | H8: bags | L8: 6 | N8: high luxury
B9: 2 | C9: 2 | D9: 1 | E9: 2 | H9: watches | N9: =SUM(I8:L13) -> 65
B10: 2 | C10: 2 | D10: 2 | E10: 1 | H10: dining
B11: 2 | C11: 3 | D11: 2 | E11: 3 | H11: jewellery | I11: 3 | K11: 3 | L11: 1
B12: 2 | C12: 3 | D12: 1 | E12: 4 | H12: travel | K12: 1
B13: 2 | C13: 3 | D13: 1 | E13: 2 | H13: hats | I13: 3 | J13: 23 | K13: 7 | L13: 18
B14: 2 | C14: 2 | D14: 1 | E14: 2
B15: 1 | C15: 3 | D15: 1 | E15: 2
B16: 2 | C16: 2 | D16: 1 | E16: 2
B17: 2 | C17: 2 | D17: 3 | E17: 2
B18: 2 | C18: 2 | D18: 2 | E18: 2
B19: 1 | C19: 2 | D19: 2 | E19: 2
B20: 2 | C20: 2 | D20: 6 | E20: 2
B21: 2 | C21: 2 | D21: 2 | E21: 2
B22: 2 | C22: 1 | D22: 2 | E22: 2
B23: 2 | C23: 1 | D23: 2 | E23: 2
B24: 2 | C24: 1 | D24: 2 | E24: 2
B25: 1 | C25: 2 | D25: 1 | E25: 2
... B27: 1 | C27: 1 | D27: 2 | E27: 1
B28: 2 | C28: 1 | E28: 2
B29: 2 | C29: 2 | E29: 3
B30: 2 | C30: 1 | E30: 1
B31: 2 | C31: 2 | E31: 1
B32: 2 | C32: 1 | E32: 1
B33: 2 | C33: 2 | E33: 2
B34: 2 | C34: 1 | E34: 1
B35: 2 | C35: 2 | E35: 2
B36: 2 | C36: 2 | E36: 2
B37: 2 | C37: 2 | E37: 2
B38: 2 | C38: 5 | E38: 1
B39: 1 | C39: 2 | E39: 1
... B41: 3 | C41: 2 | E41: 2
B42: 2 | C42: 2
...

Sheet 1970
B1: January | C1: April | D1: July | E1: October | H1: parfumes: | N1: small luxury
A2: all the data | B2: 2 | C2: 3 | D2: 1 | E2: 4 | H2: cosmetics | N2: =SUM(I1:L6) -> 10
A3: skkirt lengths | B3: 2 | C3: 1 | D3: 1 | E3: 4 | H3: lipstick | J3: 1 | K3: 9
B4: 2 | C4: 2 | D4: 1 | E4: 4 | H4: lotions, skin care, hand creams
B5: 2 | C5: 2 | D5: 2 | E5: 3 | H5: nail polist,
B6: 4 | C6: 3 | D6: 2 | E6: 3 | H6: candles
B7: 4 | C7: 4 | D7: 2 | E7: 4
B8: 2 | C8: 5 | D8: 3 | E8: 4 | H8: bags | J8: 2 | N8: high luxury
B9: 2 | C9: 1 | D9: 3 | E9: 4 | H9: watches | N9: =SUM(I8:L13) -> 49
B10: 3 | C10: 2 | D10: 3 | E10: 4 | H10: dining
B11: 2 | C11: 3 | D11: 4 | E11: 4 | H11: jewellery
B12: 2 | C12: 4 | D12: 4 | E12: 3 | H12: travel
B13: 2 | C13: 5 | D13: 4 | E13: 4 | H13: hats | I13: 14 | J13: 20 | K13: 2 | L13: 11
B14: 5 | C14: 6 | D14: 5 | E14: 3
B15: 2 | C15: 2 | D15: 2 | E15: 4
B16: 2 | C16: 5 | D16: 2 | E16: 4
B17: 4 | C17: 2 | D17: 3 | E17: 5
B18: 2 | C18: 2 | D18: 2 | E18: 3
B19: 2 | C19: 2 | D19: 3 | E19: 3
B20: 3 | C20: 2 | D20: 2 | E20: 3
B21: 3 | C21: 4 | D21: 4 | E21: 3
B22: 3 | C22: 6 | D22: 4 | E22: 5
B23: 2 | C23: 2 | D23: 4 | E23: 2
B24: 2 | C24: 2 | D24: 4 | E24: 2
B25: 2 | C25: 3 | D25: 3 | E25: 3
... B33: 2 | C33: 5 | D33: 2 | E33: 2
B34: 2 | C34: 4 | E34: 3
B35: 2 | C35: 4 | E35: 3
B36: 2 | C36: 4 | E36: 2
B37: 2 | C37: 4 | E37: 4
B38: 2 | C38: 4 | E38: 6
B39: 6 | C39: 4 | E39: 2
B40: 1 | C40: 2 | E40: 3
B41: 2 | C41: 2 | E41: 4
B42: 2 | C42: 2 | E42: 4
B43: 1 | C43: 2 | E43: 4
B44: 5 | C44: 2 | E44: 4
B45: 1 | C45: 2 | E45: 4
C46: 4
C47: 5
...

Sheet 1971
B1: January | C1: April | D1: July | E1: October | H1: parfumes: | K1: 2 | N1: small luxury
A2: all the data | B2: 2 | C2: 3 | D2: 2 | E2: 3 | H2: cosmetics | N2: =SUM(I1:L6) -> 2
A3: skkirt lengths | B3: 3 | C3: 3 | D3: 4 | E3: 3 | H3: lipstick
B4: 4 | C4: 3 | D4: 3 | E4: 3 | H4: lotions, skin care, hand creams
B5: 4 | C5: 5 | D5: 4 | E5: 6 | H5: nail polist,
B6: 4 | C6: 4 | D6: 4 | E6: 4 | H6: candles
B7: 4 | C7: 5 | D7: 4 | E7: 5
B8: 4 | C8: 5 | D8: 4 | E8: 3 | H8: bags | J8: 3 | K8: 2 | L8: 2 | N8: high luxury
B9: 4 | C9: 4 | D9: 4 | E9: 3 | H9: watches | N9: =SUM(I8:L13) -> 82
B10: 4 | C10: 3 | D10: 4 | E10: 3 | H10: dining
B11: 4 | C11: 3 | D11: 4 | E11: 3 | H11: jewellery | I11: 5 | J11: 5 | L11: 1
B12: 5 | C12: 4 | D12: 3 | E12: 5 | H12: travel
B13: 4 | C13: 3 | D13: 4 | E13: 3 | H13: hats | I13: 19 | J13: 8 | K13: 12 | L13: 25
B14: 3 | C14: 4 | D14: 4 | E14: 3
B15: 5 | C15: 4 | D15: 5 | E15: 3
B16: 5 | C16: 4 | D16: 3 | E16: 4
B17: 4 | C17: 3 | D17: 3 | E17: 4
B18: 4 | C18: 3 | D18: 1 | E18: 3
B19: 3 | C19: 3 | D19: 2 | E19: 3
B20: 4 | C20: 3 | D20: 5 | E20: 3
B21: 4 | C21: 3 | D21: 6 | E21: 3
B22: 4 | C22: 3 | D22: 3 | E22: 4
B23: 4 | C23: 4 | D23: 6 | E23: 3
B24: 2 | C24: 1 | D24: 3 | E24: 3
B25: 3 | C25: 3 | D25: 2 | E25: 3
... B33: 5 | C33: 3 | D33: 3 | E33: 3
B34: 1 | C34: 3 | D34: 3
B35: 5 | C35: 3 | D35: 3
B36: 4 | C36: 3 | D36: 3
B37: 4 | C37: 2 | D37: 3
B38: 5 | C38: 3 | D38: 3
B39: 6 | C39: 3 | D39: 1
B40: 4 | C40: 4 | D40: 1
B41: 4 | C41: 4 | D41: 1
B42: 2 | C42: 3 | D42: 1
C43: 4 | D43: 1
C44: 4 | D44: 3
C45: 3 | D45: 3
C46: 3
C47: 2
...

Sheet 1972
B1: January | C1: April | D1: July | E1: October | H1: parfumes: | I1: 1 | N1: small luxury
A2: all the data | B2: 3 | C2: 3 | D2: 3 | E2: 3 | H2: cosmetics | N2: =SUM(I1:L6) -> 1
A3: skkirt lengths | B3: 3 | C3: 3 | D3: 3 | E3: 3 | H3: lipstick
B4: 2 | C4: 3 | D4: 1 | E4: 3 | H4: lotions, skin care, hand creams
B5: 4 | C5: 3 | D5: 5 | E5: 3 | H5: nail polist,
B6: 4 | C6: 3 | D6: 3 | E6: 4 | H6: candles
B7: 3 | C7: 3 | D7: 5 | E7: 2
B8: 6 | C8: 3 | D8: 2 | E8: 2 | H8: bags | I8: 7 | J8: 1 | K8: 1 | N8: high luxury
B9: 2 | C9: 2 | D9: 2 | E9: 3 | H9: watches | N9: =SUM(I8:L13) -> 60
B10: 2 | C10: 3 | D10: 2 | E10: 3 | H10: dining
B11: 3 | C11: 3 | D11: 2 | E11: 3 | H11: jewellery | I11: 1 | L11: 3
B12: 3 | C12: 5 | D12: 3 | E12: 4 | H12: travel
B13: 3 | C13: 2 | D13: 3 | E13: 3 | H13: hats | I13: 9 | J13: 13 | K13: 9 | L13: 16
B14: 3 | C14: 1 | D14: 3 | E14: 4
B15: 3 | C15: 2 | D15: 3 | E15: 4
B16: 3 | C16: 3 | D16: 2 | E16: 4
B17: 3 | C17: 3 | D17: 3 | E17: 4
B18: 2 | C18: 3 | D18: 5 | E18: 2
B19: 2 | C19: 3 | D19: 5 | E19: 3
B20: 2 | C20: 3 | D20: 2 | E20: 4
B21: 3 | C21: 1 | D21: 2 | E21: 3
B22: 2 | C22: 2 | D22: 6 | E22: 3
B23: 2 | C23: 2 | D23: 1 | E23: 3
B24: 4 | C24: 3 | D24: 1 | E24: 3
B25: 5 | C25: 3 | D25: 5 | E25: 6
... B30: 3 | C30: 3 | D30: 2 | E30: 5
B31: 3 | D31: 1
B32: 3 | D32: 2
B33: 3 | D33: 3
B34: 3 | D34: 4
B35: 1 | D35: 2
B36: 1 | D36: 3
B37: 1
B38: 1
B39: 2
B40: 3
B41: 3
B42: 2
B43: 2
B44: 4
...

Sheet 1973
B1: January | C1: April | D1: July | E1: October | H1: parfumes: | N1: small luxury
A2: all the data | B2: 3 | C2: 2 | D2: 6 | E2: 4 | H2: cosmetics | J2: 1 | N2: =SUM(I1:L6) -> 3
A3: skkirt lengths | B3: 3 | C3: 1 | D3: 2 | E3: 4 | H3: lipstick
B4: 3 | C4: 2 | D4: 2 | E4: 3 | H4: lotions, skin care, hand creams | J4: 2
B5: 2 | C5: 2 | D5: 2 | E5: 3 | H5: nail polist,
B6: 5 | C6: 1 | D6: 3 | E6: 3 | H6: candles
B7: 3 | C7: 5 | D7: 3 | E7: 3
B8: 5 | C8: 2 | D8: 3 | E8: 2 | H8: bags | I8: 2 | J8: 3 | K8: 1 | N8: high luxury
B9: 1 | C9: 2 | D9: 3 | E9: 1 | H9: watches | N9: =SUM(I8:L13) -> 54
B10: 1 | C10: 3 | D10: 2 | E10: 5 | H10: dining
B11: 1 | C11: 3 | D11: 2 | E11: 2 | H11: jewellery | I11: 2 | K11: 6 | L11: 3
B12: 1 | C12: 2 | D12: 2 | E12: 2 | H12: travel
B13: 1 | C13: 2 | D13: 3 | E13: 3 | H13: hats | I13: 3 | J13: 11 | K13: 3 | L13: 20
B14: 2 | C14: 3 | D14: 3 | E14: 3
B15: 2 | C15: 3 | D15: 3 | E15: 3
B16: 3 | C16: 3 | D16: 2 | E16: 3
B17: 2 | C17: 1 | D17: 3 | E17: 2
B18: 2 | C18: 3 | D18: 3 | E18: 2
B19: 3 | C19: 2 | D19: 2 | E19: 3
B20: 5 | C20: 3 | D20: 1 | E20: 3
B21: 2 | C21: 3 | D21: 1 | E21: 4
B22: 2 | C22: 2 | D22: 1 | E22: 5
B23: 3 | C23: 1 | D23: 1 | E23: 3
B24: 3 | C24: 3 | D24: 2 | E24: 3
B25: 3 | C25: 3 | D25: 2 | E25: 3
B26: 2 | C26: 2 | D26: 3 | E26: 2
B27: 2 | D27: 5
B28: 3 | D28: 6
B29: 3 | D29: 6
B30: 3 | D30: 2
D31: 3
D32: 4
D33: 3
D34: 3
D35: 3
D36: 6
D37: 2
G39: hemline index
A40: AVERAGE | B40: =AVERAGE(B2:B38) -> 2.5517241 | C40: =AVERAGE(C2:C38) -> 2.36 | D40: =AVERAGE(D2:D38) -> 2.8611111 | E40: =AVERAGE(E2:E38) -> 2.96 | G40: =AVERAGE(B40:E40) -> 2.6832088

Sheet 1974
B1: January | C1: April | D1: July | E1: October | H1: parfumes: | J1: 1 | N1: small luxury
A2: all the data | B2: 3 | C2: 2 | D2: 3 | E2: 3 | H2: cosmetics | I2: 1 | N2: =SUM(I1:L6) -> 4
A3: skkirt lengths | B3: 3 | C3: 2 | D3: 6 | E3: 3 | H3: lipstick
B4: 4 | C4: 3 | D4: 3 | E4: 3 | H4: lotions, skin care, hand creams | J4: 1 | L4: 1
B5: 4 | C5: 3 | D5: 5 | E5: 3 | H5: nail polist,
B6: 4 | C6: 4 | D6: 6 | E6: 3 | H6: candles
B7: 3 | C7: 4 | D7: 5 | E7: 3
B8: 6 | C8: 4 | D8: 5 | E8: 3 | H8: bags | J8: 1 | L8: 1 | N8: high luxury
B9: 4 | C9: 6 | D9: 6 | E9: 6 | H9: watches | N9: =SUM(I8:L13) -> 55
B10: 4 | C10: 4 | D10: 2 | E10: 6 | H10: dining
B11: 4 | C11: 3 | D11: 3 | E11: 4 | H11: jewellery | I11: 2 | J11: 3 | K11: 1 | L11: 2
B12: 4 | C12: 3 | D12: 6 | E12: 4 | H12: travel
B13: 3 | C13: 5 | D13: 6 | E13: 4 | H13: hats | I13: 14 | J13: 15 | K13: 7 | L13: 9
B14: 3 | C14: 3 | D14: 3 | E14: 6
B15: 3 | C15: 3 | D15: 5 | E15: 4
B16: 4 | C16: 3 | D16: 6 | E16: 4
B17: 3 | C17: 3 | D17: 6 | E17: 5
B18: 5 | C18: 3 | D18: 6 | E18: 4
B19: 3 | C19: 3 | D19: 5 | E19: 3
B20: 5 | C20: 3 | D20: 3 | E20: 4
B21: 6 | C21: 3 | D21: 1 | E21: 4
B22: 3 | C22: 5 | D22: 5 | E22: 4
B23: 3 | C23: 4 | D23: 1 | E23: 4
B24: 3 | C24: 3 | D24: 3 | E24: 4
B25: 3 | C25: 3 | D25: 4 | E25: 4
... B29: 3 | C29: 4 | D29: 2 | E29: 4
C30: 3 | D30: 1 | E30: 4
C31: 3 | D31: 1 | E31: 6
C32: 5 | D32: 2 | E32: 4
C33: 6 | D33: 2 | E33: 4
C34: 3 | D34: 2 | E34: 4
C35: 5 | D35: 2
C36: 3 | D36: 3
C37: 3 | D37: 3
C38: 2 | D38: 2
C39: 1
C40: 5
C41: 6
C42: 5
C43: 5
...

Sheet 1975
B1: January | C1: April | D1: July | E1: October | H1: parfumes: | N1: small luxury
A2: all the data | B2: 4 | C2: 5 | D2: 3 | E2: 4 | H2: cosmetics | K2: 1 | N2: =SUM(I1:L6) -> 5
A3: skkirt lengths | B3: 4 | C3: 5 | D3: 3 | E3: 4 | H3: lipstick
B4: 4 | C4: 4 | D4: 3 | E4: 3 | H4: lotions, skin care, hand creams | I4: 2 | J4: 1
B5: 5 | C5: 4 | D5: 3 | E5: 4 | H5: nail polist, | K5: 1
B6: 4 | C6: 4 | D6: 3 | E6: 4 | H6: candles
B7: 3 | C7: 5 | D7: 3 | E7: 3
B8: 3 | C8: 4 | D8: 3 | E8: 3 | H8: bags | I8: 1 | J8: 4 | K8: 3 | N8: high luxury
B9: 3 | C9: 4 | D9: 3 | E9: 4 | H9: watches | N9: =SUM(I8:L13) -> 78
B10: 3 | C10: 3 | D10: 3 | E10: 4 | H10: dining
B11: 3 | C11: 4 | D11: 5 | E11: 4 | H11: jewellery | I11: 3 | J11: 2 | K11: 3 | L11: 5
B12: 3 | C12: 4 | D12: 5 | E12: 4 | H12: travel
B13: 3 | C13: 4 | D13: 5 | E13: 4 | H13: hats | I13: 15 | J13: 6 | K13: 11 | L13: 25
B14: 4 | C14: 4 | D14: 4 | E14: 4
B15: 6 | C15: 4 | D15: 5 | E15: 3
B16: 6 | C16: 5 | D16: 5 | E16: 3
B17: 3 | C17: 6 | D17: 6 | E17: 2
B18: 3 | C18: 1 | D18: 4 | E18: 3
B19: 4 | C19: 4 | D19: 4 | E19: 3 | H19: First colored copy in 1975 october
B20: 3 | C20: 6 | D20: 3 | E20: 4
B21: 3 | C21: 4 | D21: 3 | E21: 4
B22: 3 | C22: 4 | D22: 4 | E22: 4
B23: 2 | C23: 4 | D23: 4 | E23: 4
B24: 3 | C24: 4 | D24: 4 | E24: 3
B25: 2 | C25: 4 | D25: 4 | E25: 4
C26: 4 | D26: 4 | E26: 4
C27: 6 | D27: 4 | E27: 4
C28: 5 | D28: 4 | E28: 4
C29: 6 | D29: 4 | E29: 6
C30: 6 | D30: 4 | E30: 4
C31: 4 | D31: 4 | E31: 3
C32: 4 | D32: 4 | E32: 3
C33: 4 | D33: 4 | E33: 4
C34: 4 | D34: 6 | E34: 6
C35: 4 | D35: 6 | E35: 5
C36: 4 | D36: 6 | E36: 4
C37: 4 | D37: 6 | E37: 5
... C55: 4 | D55: 4 | E55: 6
C56: 4 | E56: 5
C57: 4 | E57: 6
...

Sheet 1976
B1: January | C1: April | D1: July | E1: October | H1: parfumes: | J1: 1 | L1: 1 | N1: small luxury
A2: all the data | B2: 4 | C2: 4 | D2: 4 | E2: 4 | H2: cosmetics | J2: 1 | K2: 2 | L2: 1 | N2: =SUM(I1:L6) -> 11
A3: skkirt lengths | B3: 4 | C3: 4 | D3: 4 | E3: 4 | H3: lipstick
B4: 4 | C4: 4 | D4: 3 | E4: 4 | H4: lotions, skin care, hand creams | I4: 4 | L4: 1
B5: 6 | C5: 4 | D5: 3 | E5: 3 | H5: nail polist,
B6: 4 | C6: 4 | D6: 3 | E6: 4 | H6: candles
B7: 4 | C7: 5 | D7: 5 | E7: 4
B8: 4 | C8: 4 | D8: 6 | E8: 3 | H8: bags | I8: 1 | J8: 4 | K8: 7 | L8: 11 | N8: high luxury
B9: 4 | C9: 4 | D9: 3 | E9: 1 | H9: watches | N9: =SUM(I8:L13) -> 134
B10: 4 | C10: 4 | D10: 6 | E10: 1 | H10: dining
B11: 4 | C11: 4 | D11: 5 | E11: 3 | H11: jewellery | J11: 3 | K11: 11 | L11: 2
B12: 6 | C12: 3 | D12: 3 | E12: 4 | H12: travel | I12: 1 | K12: 2
B13: 6 | C13: 3 | D13: 4 | E13: 3 | H13: hats | I13: 20 | J13: 19 | K13: 27 | L13: 26
B14: 6 | C14: 4 | D14: 3 | E14: 4
B15: 4 | C15: 4 | D15: 3 | E15: 4
B16: 4 | C16: 3 | D16: 3 | E16: 4
B17: 4 | C17: 4 | D17: 6 | E17: 3
B18: 5 | C18: 4 | D18: 3 | E18: 3
B19: 4 | C19: 4 | D19: 3 | E19: 6
B20: 4 | C20: 3 | D20: 3 | E20: 4
B21: 4 | C21: 4 | D21: 3 | E21: 5
B22: 4 | C22: 4 | D22: 4 | E22: 4
B23: 4 | C23: 4 | D23: 4 | E23: 4
B24: 4 | C24: 3 | D24: 4 | E24: 3
B25: 3 | C25: 3 | D25: 3 | E25: 3
... B40: 4 | C40: 4 | D40: 4 | E40: 4
B41: 4 | C41: 4 | D41: 3
B42: 4 | C42: 4 | D42: 3
B43: 4 | C43: 4 | D43: 4
B44: 4 | C44: 3 | D44: 3
B45: 4 | C45: 3 | D45: 3
B46: 5 | C46: 4 | D46: 4
B47: 6 | C47: 4 | D47: 3
B48: 6 | C48: 4 | D48: 3
B49: 4 | C49: 3 | D49: 3
B50: 4 | C50: 4 | D50: 3
B51: 4 | C51: 4 | D51: 6
B52: 3 | C52: 4 | D52: 5
... B56: 4 | C56: 3 | D56: 4
B57: 4 | C57: 4
...

Sheet 1977
B1: January | C1: April | D1: July | E1: October | H1: parfumes: | J1: 1 | N1: small luxury
A2: all the data | B2: 4 | C2: 4 | D2: 5 | E2: 3 | H2: cosmetics | I2: 1 | K2: 3 | L2: 4 | N2: =SUM(I1:L6) -> 19
A3: skkirt lengths | B3: 4 | C3: 4 | D3: 3 | E3: 4 | H3: lipstick | I3: 2
B4: 4 | C4: 4 | D4: 2 | E4: 4 | H4: lotions, skin care, hand creams | L4: 6
B5: 3 | C5: 4 | D5: 5 | E5: 3 | H5: nail polist, | K5: 2
B6: 3 | C6: 4 | D6: 4 | E6: 4 | H6: candles
B7: 4 | C7: 4 | D7: 4 | E7: 4
B8: 3 | C8: 4 | D8: 4 | E8: 4 | H8: bags | I8: 10 | J8: 1 | N8: high luxury
B9: 3 | C9: 4 | D9: 4 | E9: 4 | H9: watches | N9: =SUM(I8:L13) -> 137
B10: 3 | C10: 4 | D10: 4 | E10: 3 | H10: dining
B11: 3 | C11: 4 | D11: 4 | E11: 3 | H11: jewellery | I11: 5 | J11: 1 | L11: 3
B12: 4 | C12: 4 | D12: 4 | E12: 3 | H12: travel
B13: 4 | C13: 3 | D13: 4 | E13: 3 | H13: hats | I13: 33 | J13: 35 | K13: 17 | L13: 32
B14: 4 | C14: 4 | D14: 4 | E14: 3
B15: 4 | C15: 4 | D15: 3 | E15: 3
B16: 3 | C16: 3 | D16: 3 | E16: 4
B17: 4 | C17: 4 | D17: 4 | E17: 5
B18: 3 | C18: 4 | D18: 4 | E18: 4
B19: 3 | C19: 4 | D19: 4 | E19: 4
B20: 5 | C20: 3 | D20: 5 | E20: 4
B21: 4 | C21: 4 | D21: 3 | E21: 4
B22: 4 | C22: 4 | D22: 3 | E22: 4
B23: 4 | C23: 4 | D23: 3 | E23: 4
B24: 4 | C24: 4 | D24: 4 | E24: 4
B25: 3 | C25: 4 | D25: 4 | E25: 3
... B36: 5 | C36: 4 | D36: 3 | E36: 5
B37: 5 | C37: 4 | D37: 2
B38: 4 | C38: 4 | D38: 2
B39: 5 | C39: 4 | D39: 3
B40: 3 | C40: 4 | D40: 3
B41: 4 | C41: 4 | D41: 2
B42: 3 | C42: 4 | D42: 4
B43: 4 | C43: 4 | D43: 3
B44: 4 | C44: 6 | D44: 3
B45: 5 | C45: 6 | D45: 3
C46: 4 | D46: 3
C47: 6 | D47: 2
C48: 3 | D48: 3
C49: 4 | D49: 5
C50: 4 | D50: 3
...

Sheet 1978
B1: January | C1: April | D1: July | E1: October | H1: parfumes: | L1: 2 | N1: small luxury
A2: all the data | B2: 4 | C2: 5 | D2: 4 | E2: 4 | H2: cosmetics | J2: 1 | K2: 1 | L2: 5 | N2: =SUM(I1:L6) -> 10
A3: skkirt lengths | B3: 4 | C3: 4 | D3: 4 | E3: 4 | H3: lipstick
B4: 4 | C4: 4 | D4: 4 | E4: 4 | H4: lotions, skin care, hand creams
B5: 4 | C5: 4 | D5: 4 | E5: 3 | H5: nail polist, | I5: 1
B6: 4 | C6: 4 | D6: 4 | E6: 4 | H6: candles
B7: 4 | C7: 4 | D7: 4 | E7: 4
B8: 4 | C8: 4 | D8: 4 | E8: 4 | H8: bags | I8: 1 | J8: 3 | K8: 10 | L8: 8 | N8: high luxury
B9: 4 | C9: 4 | D9: 4 | E9: 4 | H9: watches | J9: 1 | K9: 1 | L9: 1 | N9: =SUM(I8:L13) -> 212
B10: 4 | C10: 3 | D10: 4 | E10: 5 | H10: dining
B11: 4 | C11: 4 | D11: 5 | E11: 4 | H11: jewellery | I11: 8 | J11: 2 | K11: 15 | L11: 1
B12: 4 | C12: 4 | D12: 3 | E12: 4 | H12: travel | I12: 1 | K12: 1 | L12: 1
B13: 4 | C13: 4 | D13: 3 | E13: 4 | H13: hats | I13: 67 | J13: 27 | K13: 18 | L13: 46
B14: 4 | C14: 4 | D14: 5 | E14: 3
B15: 4 | C15: 4 | D15: 2 | E15: 3
B16: 5 | C16: 4 | D16: 4 | E16: 3
B17: 4 | C17: 4 | D17: 4 | E17: 3
B18: 4 | C18: 4 | D18: 3 | E18: 4
B19: 4 | C19: 4 | D19: 4 | E19: 4
B20: 4 | C20: 4 | D20: 4 | E20: 4
B21: 5 | C21: 5 | D21: 5 | E21: 4
B22: 4 | C22: 4 | D22: 6 | E22: 5
B23: 5 | C23: 4 | D23: 4 | E23: 4
B24: 5 | C24: 4 | D24: 4 | E24: 4
B25: 5 | C25: 4 | D25: 5 | E25: 4
... B42: 4 | C42: 3 | D42: 4 | E42: 4
B43: 4 | C43: 4 | D43: 3
B44: 4 | C44: 3 | D44: 3
B45: 4 | C45: 4 | D45: 3
B46: 4 | C46: 3 | D46: 4
B47: 5 | C47: 3 | D47: 4
B48: 4 | C48: 4 | D48: 4
B49: 4 | C49: 5 | D49: 3
B50: 4 | C50: 3 | D50: 3
B51: 4 | C51: 5 | D51: 3
B52: 3 | C52: 6 | D52: 3
B53: 3 | C53: 4 | D53: 4
B54: 3 | C54: 4 | D54: 3
... B63: 3 | C63: 3 | D63: 5
B64: 4 | D64: 4
...

Sheet 1979
B1: January | C1: April | D1: July | E1: October | H1: parfumes: | J1: 1 | N1: small luxury
A2: all the data | B2: 3 | C2: 3 | D2: 6 | E2: 4 | H2: cosmetics | I2: 2 | J2: 2 | K2: 3 | L2: 1 | N2: =SUM(I1:L6) -> 12
A3: skkirt lengths | B3: 3 | C3: 4 | D3: 4 | E3: 4 | H3: lipstick
B4: 4 | C4: 4 | D4: 4 | E4: 4 | H4: lotions, skin care, hand creams | L4: 1
B5: 4 | C5: 4 | D5: 3 | E5: 4 | H5: nail polist,
B6: 4 | C6: 3 | D6: 4 | E6: 4 | H6: candles | I6: 1 | L6: 1
B7: 4 | C7: 4 | D7: 3 | E7: 4
B8: 4 | C8: 4 | D8: 3 | E8: 4 | H8: bags | I8: 4 | K8: 12 | L8: 8 | N8: high luxury
B9: 5 | C9: 3 | D9: 4 | E9: 4 | H9: watches | I9: 2 | K9: 1 | N9: =SUM(I8:L13) -> 167
B10: 4 | C10: 3 | D10: 4 | E10: 4 | H10: dining
B11: 4 | C11: 4 | D11: 5 | E11: 4 | H11: jewellery | I11: 4 | J11: 7 | K11: 4 | L11: 2
B12: 4 | C12: 3 | D12: 4 | E12: 4 | H12: travel | I12: 1 | K12: 1
B13: 4 | C13: 4 | D13: 4 | E13: 6 | H13: hats | I13: 37 | J13: 15 | K13: 35 | L13: 34
B14: 4 | C14: 4 | D14: 4 | E14: 6
B15: 4 | C15: 4 | D15: 4 | E15: 5
B16: 4 | C16: 4 | D16: 4 | E16: 4
B17: 4 | C17: 4 | D17: 4 | E17: 4
B18: 5 | C18: 4 | D18: 4 | E18: 4
B19: 5 | C19: 4 | D19: 4 | E19: 4
B20: 6 | C20: 5 | D20: 4 | E20: 4
B21: 4 | C21: 4 | D21: 4 | E21: 4
B22: 4 | C22: 4 | D22: 4 | E22: 4
B23: 4 | C23: 4 | D23: 3 | E23: 4
B24: 4 | C24: 4 | D24: 3 | E24: 4
B25: 4 | C25: 4 | D25: 4 | E25: 4
... B34: 3 | C34: 3 | D34: 4 | E34: 4
B35: 4 | C35: 4 | E35: 5
B36: 4 | C36: 3 | E36: 4
B37: 5 | C37: 3 | E37: 4
B38: 5 | C38: 5 | E38: 5
B39: 5 | C39: 5 | E39: 3
B40: 5 | C40: 5 | E40: 4
C41: 5 | E41: 4
C42: 5 | E42: 4
C43: 4 | E43: 4
C44: 5 | E44: 4
C45: 4 | E45: 3
C46: 4 | E46: 3
C47: 4 | E47: 3
C48: 5 | E48: 3
...

Sheet 1980
B1: January | C1: April | D1: July | E1: October | H1: parfumes: | N1: small luxury
A2: all the data | B2: 4 | C2: 4 | D2: 3 | E2: 4 | H2: cosmetics | L2: 2 | N2: =SUM(I1:L6) -> 2
A3: skkirt lengths | B3: 3 | C3: 4 | D3: 3 | E3: 5 | H3: lipstick
B4: 4 | C4: 4 | D4: 4 | E4: 3 | H4: lotions, skin care, hand creams
B5: 4 | C5: 4 | D5: 3 | E5: 5 | H5: nail polist,
B6: 4 | C6: 4 | D6: 3 | E6: 4 | H6: candles
B7: 4 | C7: 4 | D7: 3 | E7: 4
B8: 4 | C8: 4 | D8: 3 | E8: 5 | H8: bags | I8: 2 | J8: 6 | K8: 6 | L8: 2 | N8: high luxury
B9: 4 | C9: 4 | D9: 3 | E9: 4 | H9: watches | K9: 1 | N9: =SUM(I8:L13) -> 207
B10: 4 | C10: 4 | D10: 3 | E10: 5 | H10: dining
B11: 4 | C11: 4 | D11: 3 | E11: 4 | H11: jewellery | I11: 1 | J11: 1 | K11: 10 | L11: 8
B12: 4 | C12: 4 | D12: 3 | E12: 3 | H12: travel | K12: 1
B13: 4 | C13: 4 | D13: 3 | E13: 2 | H13: hats | I13: 36 | J13: 35 | K13: 32 | L13: 66
B14: 4 | C14: 4 | D14: 3 | E14: 4
B15: 6 | C15: 4 | D15: 3 | E15: 4
B16: 5 | C16: 3 | D16: 4 | E16: 4
B17: 3 | C17: 4 | D17: 4 | E17: 3
B18: 4 | C18: 4 | D18: 4 | E18: 3
B19: 4 | C19: 4 | D19: 4 | E19: 4
B20: 3 | C20: 4 | D20: 4 | E20: 4
B21: 3 | C21: 4 | D21: 4 | E21: 4
B22: 3 | C22: 4 | D22: 3 | E22: 4
B23: 4 | C23: 3 | D23: 4 | E23: 3
B24: 4 | C24: 4 | D24: 2 | E24: 3
B25: 4 | C25: 4 | D25: 4 | E25: 4
... B50: 3 | C50: 3 | D50: 4 | E50: 3
B51: 4 | D51: 4
B52: 4 | D52: 4
B53: 4 | D53: 4
D54: 4
D55: 3
D56: 4
D57: 4
D58: 4
D59: 4
D60: 4
D61: 5
D62: 4
D63: 4
D64: 5
...

Sheet 1981
B1: January | C1: April | D1: July | E1: October | H1: parfumes: | N1: small luxury
A2: all the data | B2: 4 | C2: 4 | D2: 4 | E2: 4 | H2: cosmetics | N2: 0
A3: skkirt lengths | B3: 3 | C3: 4 | D3: 1 | E3: 3 | H3: lipstick
B4: 3 | C4: 4 | D4: 2 | E4: 4 | H4: lotions, skin care, hand creams
B5: 4 | C5: 4 | D5: 3 | E5: 4 | H5: nail polist,
B6: 4 | C6: 4 | D6: 3 | E6: 4 | H6: candles
B7: 4 | C7: 4 | D7: 4 | E7: 3
B8: 3 | C8: 3 | D8: 3 | E8: 5 | H8: bags | I8: 1 | J8: 13 | N8: high luxury
B9: 4 | C9: 4 | D9: 2 | E9: 5 | H9: watches | N9: =SUM(I8:L13) -> 154
B10: 3 | C10: 3 | D10: 1 | E10: 6 | H10: dining
B11: 3 | C11: 3 | D11: 5 | E11: 2 | H11: jewellery | I11: 5 | J11: 5 | K11: 8 | L11: 5
B12: 4 | C12: 3 | D12: 5 | E12: 4 | H12: travel | K12: 1
B13: 4 | C13: 3 | D13: 5 | E13: 6 | H13: hats | I13: 33 | J13: 17 | K13: 31 | L13: 35
B14: 4 | C14: 3 | D14: 4 | E14: 4
B15: 4 | C15: 3 | D15: 4 | E15: 3
B16: 4 | C16: 3 | D16: 3 | E16: 4
B17: 6 | C17: 3 | D17: 6 | E17: 4
B18: 6 | C18: 4 | D18: 4 | E18: 4
B19: 6 | C19: 4 | D19: 4 | E19: 4
B20: 3 | C20: 4 | D20: 4 | E20: 3
B21: 3 | C21: 4 | D21: 4 | E21: 4
B22: 3 | C22: 4 | D22: 4 | E22: 4
B23: 4 | C23: 4 | D23: 6 | E23: 4
B24: 3 | C24: 4 | D24: 4 | E24: 4
B25: 3 | C25: 4 | D25: 5 | E25: 4
... B30: 3 | C30: 4 | D30: 3 | E30: 4
B31: 3 | C31: 3 | D31: 4
B32: 3 | C32: 3 | D32: 3
B33: 4 | C33: 3 | D33: 4
B34: 5 | C34: 3 | D34: 3
B35: 5 | C35: 3 | D35: 3
C36: 3 | D36: 3
C37: 4 | D37: 3
C38: 4 | D38: 3
C39: 4 | D39: 3
C40: 4 | D40: 3
C41: 6 | D41: 4
C42: 5 | D42: 3
C43: 4 | D43: 3
C44: 3 | D44: 6
...

Sheet 1982
B1: January | C1: April | D1: July | E1: October | H1: parfumes: | I1: 1 | N1: small luxury
A2: all the data | B2: 4 | C2: 2 | D2: 1 | E2: 1 | H2: cosmetics | I2: 3 | N2: =SUM(I1:L6) -> 4
A3: skkirt lengths | B3: 4 | C3: 4 | D3: 3 | E3: 2 | H3: lipstick
B4: 4 | C4: 4 | D4: 2 | E4: 3 | H4: lotions, skin care, hand creams
B5: 4 | C5: 3 | D5: 2 | E5: 3 | H5: nail polist,
B6: 4 | C6: 3 | D6: 4 | E6: 4 | H6: candles
B7: 3 | C7: 3 | D7: 4 | E7: 3
B8: 3 | C8: 3 | D8: 4 | E8: 4 | H8: bags | K8: 2 | N8: high luxury
B9: 3 | C9: 4 | D9: 3 | E9: 4 | H9: watches | N9: =SUM(I8:L13) -> 153
B10: 4 | C10: 4 | D10: 4 | E10: 2 | H10: dining
B11: 3 | C11: 4 | D11: 5 | E11: 3 | H11: jewellery | I11: 4 | J11: 14 | K11: 21 | L11: 15
B12: 4 | C12: 4 | D12: 4 | E12: 2 | H12: travel | I12: 2 | K12: 1
B13: 5 | C13: 3 | D13: 4 | E13: 5 | H13: hats | I13: 23 | J13: 24 | K13: 16 | L13: 31
B14: 3 | C14: 3 | D14: 4 | E14: 3
B15: 4 | C15: 5 | D15: 4 | E15: 4
B16: 3 | C16: 5 | D16: 4 | E16: 3
B17: 5 | C17: 6 | D17: 3 | E17: 3
B18: 3 | C18: 4 | D18: 3 | E18: 4
B19: 3 | C19: 4 | D19: 3 | E19: 4
B20: 3 | C20: 4 | D20: 4 | E20: 4
B21: 2 | C21: 4 | D21: 4 | E21: 3
B22: 4 | C22: 4 | D22: 3 | E22: 4
B23: 2 | C23: 3 | D23: 4 | E23: 4
B24: 4 | C24: 4 | D24: 4 | E24: 4
B25: 3 | C25: 4 | D25: 4 | E25: 3
... B28: 3 | C28: 4 | D28: 4 | E28: 4
B29: 4 | D29: 4 | E29: 4
B30: 4 | D30: 4 | E30: 4
B31: 6 | D31: 4 | E31: 4
B32: 6 | D32: 3 | E32: 4
B33: 2 | D33: 3 | E33: 4
B34: 3 | D34: 5 | E34: 3
B35: 3 | D35: 5 | E35: 4
B36: 5 | D36: 5 | E36: 4
B37: 3 | D37: 4 | E37: 3
B38: 4 | D38: 3 | E38: 3
B39: 4 | D39: 3 | E39: 3
B40: 4 | D40: 4 | E40: 2
B41: 4 | E41: 3
B42: 4 | E42: 3
...

Sheet 1983
B1: January | C1: April | D1: July | E1: October | H1: parfumes: | N1: small luxury
A2: all the data | B2: 4 | C2: 4 | D2: 2 | E2: 1 | H2: cosmetics | I2: 1 | N2: =SUM(I1:L6) -> 2
A3: skkirt lengths | B3: 4 | C3: 3 | D3: 5 | E3: 2 | H3: lipstick | I3: 1
B4: 5 | C4: 3 | D4: 4 | E4: 4 | H4: lotions, skin care, hand creams
B5: 2 | C5: 4 | D5: 3 | E5: 4 | H5: nail polist,
B6: 4 | C6: 3 | D6: 2 | E6: 4 | H6: candles
B7: 3 | C7: 3 | D7: 3 | E7: 4
B8: 3 | C8: 4 | D8: 1 | E8: 4 | H8: bags | N8: high luxury
B9: 3 | C9: 4 | D9: 2 | E9: 5 | H9: watches | K9: 1 | N9: =SUM(I8:L13) -> 127
B10: 4 | C10: 3 | D10: 1 | E10: 4 | H10: dining
B11: 4 | C11: 3 | D11: 2 | E11: 4 | H11: jewellery | I11: 5 | J11: 14 | K11: 9 | L11: 10
B12: 4 | C12: 4 | D12: 1 | E12: 4 | H12: travel | I12: 1
B13: 4 | C13: 4 | D13: 1 | E13: 4 | H13: hats | I13: 23 | J13: 27 | K13: 14 | L13: 23
B14: 4 | C14: 5 | D14: 4 | E14: 4
B15: 4 | C15: 4 | D15: 3 | E15: 4
B16: 4 | C16: 4 | D16: 4 | E16: 3
B17: 4 | C17: 2 | D17: 5 | E17: 4
B18: 6 | C18: 2 | D18: 3 | E18: 4
B19: 5 | C19: 4 | D19: 4 | E19: 4
B20: 3 | C20: 3 | D20: 5 | E20: 4
B21: 3 | C21: 3 | D21: 3 | E21: 5
B22: 3 | C22: 4 | D22: 4 | E22: 4
B23: 3 | C23: 4 | D23: 5 | E23: 4
B24: 3 | C24: 3 | D24: 2 | E24: 4
B25: 4 | C25: 4 | D25: 2 | E25: 3
... B35: 3 | C35: 6 | D35: 3 | E35: 3
B36: 4 | C36: 4 | E36: 3
B37: 4 | C37: 1 | E37: 3
C38: 4 | E38: 3
C39: 4 | E39: 3
C40: 1 | E40: 3
C41: 1 | E41: 4
E42: 3
E43: 3
E44: 4
E45: 4
E46: 4
E47: 2
E48: 5
E49: 6
...

Sheet 1984
B1: January | C1: April | D1: July | E1: October | H1: parfumes: | K1: 1 | L1: 1 | N1: small luxury
A2: all the data | B2: 4 | C2: 3 | D2: 4 | E2: 3 | H2: cosmetics | J2: 7 | L2: 1 | N2: =SUM(I1:L6) -> 10
A3: skkirt lengths | B3: 3 | C3: 3 | D3: 4 | E3: 3 | H3: lipstick
B4: 3 | C4: 3 | D4: 4 | E4: 3 | H4: lotions, skin care, hand creams
B5: 3 | C5: 3 | D5: 4 | E5: 4 | H5: nail polist,
B6: 3 | C6: 2 | D6: 4 | E6: 4 | H6: candles
B7: 3 | C7: 2 | D7: 2 | E7: 3
B8: 3 | C8: 5 | D8: 4 | E8: 4 | H8: bags | J8: 6 | K8: 2 | N8: high luxury
B9: 4 | C9: 3 | D9: 3 | E9: 3 | H9: watches | K9: 1 | N9: =SUM(I8:L13) -> 134
B10: 4 | C10: 2 | D10: 3 | E10: 4 | H10: dining
B11: 3 | C11: 2 | D11: 4 | E11: 3 | H11: jewellery | I11: 6 | J11: 3 | K11: 2 | L11: 17
B12: 4 | C12: 1 | D12: 5 | E12: 5 | H12: travel | J12: 3 | K12: 1
B13: 3 | C13: 6 | D13: 4 | E13: 3 | H13: hats | I13: 23 | J13: 33 | K13: 11 | L13: 26
B14: 3 | C14: 4 | D14: 3 | E14: 4
B15: 3 | C15: 4 | D15: 4 | E15: 4
B16: 3 | C16: 2 | D16: 4 | E16: 3
B17: 3 | C17: 1 | D17: 4 | E17: 4
B18: 4 | C18: 4 | D18: 1 | E18: 3
B19: 5 | C19: 4 | D19: 4 | E19: 6
B20: 3 | C20: 4 | D20: 4 | E20: 6
B21: 4 | C21: 4 | D21: 4 | E21: 4
B22: 4 | C22: 3 | D22: 4 | E22: 4
B23: 3 | C23: 3 | D23: 4 | E23: 3
B24: 3 | C24: 3 | D24: 4
B25: 5 | C25: 3 | D25: 4
B26: 3 | C26: 3 | D26: 4
B27: 6 | C27: 3 | D27: 4
B28: 2 | C28: 3 | D28: 4
B29: 1 | C29: 3 | D29: 4
B30: 3 | C30: 2 | D30: 4
B31: 6 | C31: 2 | D31: 4
B32: 5 | C32: 1 | D32: 2
B33: 5 | C33: 1 | D33: 3
B34: 4 | C34: 3 | D34: 3
C35: 3 | D35: 4
C36: 4 | D36: 2
C37: 4 | D37: 2
C38: 3 | D38: 2
C39: 3 | D39: 1
C40: 3 | D40: 3
...

Sheet 1985
B1: January | C1: April | D1: July | E1: October | H1: parfumes: | N1: small luxury
A2: all the data | B2: 4 | C2: 4 | D2: 4 | E2: 4 | H2: cosmetics | I2: 1 | N2: =SUM(I1:L6) -> 3
A3: skkirt lengths | B3: 4 | C3: 3 | D3: 4 | E3: 4 | H3: lipstick
B4: 4 | C4: 4 | D4: 4 | E4: 4 | H4: lotions, skin care, hand creams | L4: 2
B5: 4 | C5: 4 | D5: 4 | E5: 4 | H5: nail polist,
B6: 4 | C6: 4 | D6: 4 | E6: 3 | H6: candles
B7: 4 | C7: 5 | D7: 4 | E7: 4
B8: 5 | C8: 4 | D8: 4 | E8: 4 | H8: bags | I8: 3 | J8: 1 | K8: 3 | N8: high luxury
B9: 4 | C9: 5 | D9: 5 | E9: 4 | H9: watches | N9: =SUM(I8:L13) -> 129
B10: 5 | C10: 4 | D10: 5 | E10: 4 | H10: dining | I10: 3 | K10: 1 | L10: 1
B11: 4 | C11: 4 | E11: 4 | H11: jewellery | I11: 5 | K11: 12 | L11: 8
B12: 4 | C12: 4 | E12: 5 | H12: travel
B13: 4 | C13: 4 | E13: 6 | H13: hats | I13: 22 | J13: 31 | K13: 10 | L13: 29
B14: 4 | C14: 4 | E14: 6
B15: 4 | C15: 3 | E15: 5
B16: 4 | C16: 4 | E16: 5
B17: 4 | C17: 4 | E17: 4
B18: 4 | C18: 4 | E18: 4
B19: 4 | C19: 5 | E19: 4
B20: 4 | C20: 3 | E20: 4
B21: 4 | C21: 3 | E21: 5
B22: 4 | C22: 3 | E22: 5
B23: 4 | C23: 4 | E23: 5
B24: 4 | C24: 4
B25: 4 | C25: 4
B26: 4
B27: 4
B28: 4
B29: 4
B30: 4
B31: 4
B32: 5
B33: 4
B34: 4
B35: 3
B36: 3
G38: hemline index
A39: AVERAGE | B39: =AVERAGE(B2:B37) -> 4.0285714 | C39: =AVERAGE(C2:C37) -> 3.9166667 | D39: =AVERAGE(D2:D37) -> 4.2222222 | E39: =AVERAGE(E2:E37) -> 4.4090909 | G39: =AVERAGE(B39:E39) -> 4.1441378

Sheet 1986
B1: January | C1: April | D1: July | E1: October | H1: parfumes: | J1: 3 | K1: 1 | N1: small luxury
A2: all the data | B2: 5 | C2: 4 | D2: 4 | E2: 4 | H2: cosmetics | J2: 1 | L2: 1 | N2: =SUM(I1:L6) -> 7
A3: skkirt lengths | B3: 4 | C3: 4 | D3: 4 | E3: 3 | H3: lipstick
B4: 4 | C4: 3 | D4: 4 | E4: 4 | H4: lotions, skin care, hand creams
B5: 5 | C5: 3 | D5: 3 | E5: 3 | H5: nail polist,
B6: 3 | C6: 3 | D6: 3 | E6: 5 | H6: candles | K6: 1
B7: 6 | C7: 3 | D7: 2 | E7: 5
B8: 2 | C8: 5 | D8: 4 | E8: 4 | H8: bags | I8: 1 | L8: 6 | N8: high luxury
B9: 4 | C9: 4 | D9: 4 | E9: 5 | H9: watches | J9: 2 | N9: =SUM(I8:L13) -> 211
B10: 4 | C10: 3 | D10: 4 | E10: 4 | H10: dining | I10: 1 | J10: 2 | K10: 2 | L10: 1
B11: 4 | C11: 3 | D11: 4 | E11: 4 | H11: jewellery | I11: 18 | J11: 24 | K11: 44 | L11: 29
C12: 3 | D12: 5 | E12: 3 | H12: travel
C13: 4 | D13: 4 | E13: 3 | H13: hats | I13: 26 | J13: 21 | K13: 17 | L13: 17
C14: 5 | D14: 4 | E14: 4
C15: 4 | D15: 4 | E15: 4
C16: 4 | D16: 4 | E16: 4
C17: 4 | D17: 4 | E17: 4
C18: 4 | D18: 3 | E18: 4
D19: 4 | E19: 4
D20: 2 | E20: 4
D21: 3 | E21: 4
D22: 4 | E22: 4
D23: 4 | E23: 4
D24: 5 | E24: 4
G27: hemline index
A28: AVERAGE | B28: =AVERAGE(B2:B26) -> 4.1 | C28: =AVERAGE(C2:C26) -> 3.7058824 | D28: =AVERAGE(D2:D26) -> 3.7391304 | E28: =AVERAGE(E2:E26) -> 3.9565217 | G28: =AVERAGE(B28:E28) -> 3.8753836

Sheet 1987
B1: January | C1: April | D1: July | E1: October | H1: parfumes: | J1: 3 | N1: small luxury
A2: all the data | B2: 3 | C2: 3 | D2: 4 | E2: 4 | H2: cosmetics | J2: 2 | N2: =SUM(I1:L6) -> 6
A3: skkirt lengths | B3: 3 | C3: 4 | D3: 4 | E3: 4 | H3: lipstick | J3: 1
B4: 3 | C4: 4 | D4: 4 | E4: 5 | H4: lotions, skin care, hand creams
B5: 3 | C5: 3 | D5: 3 | E5: 4 | H5: nail polist,
B6: 3 | C6: 3 | D6: 4 | E6: 4 | H6: candles
B7: 4 | C7: 4 | D7: 5 | E7: 4
B8: 3 | C8: 3 | D8: 5 | E8: 4 | H8: bags | J8: 2 | K8: 2 | L8: 1 | N8: high luxury
B9: 4 | C9: 3 | D9: 5 | E9: 4 | H9: watches | L9: 1 | N9: =SUM(I8:L13) -> 295
B10: 4 | C10: 3 | D10: 4 | E10: 4 | H10: dining | J10: 1 | K10: 1 | L10: 1
B11: 4 | C11: 4 | D11: 4 | E11: 4 | H11: jewellery | I11: 46 | J11: 42 | K11: 40 | L11: 64
B12: 4 | C12: 4 | D12: 4 | E12: 4 | H12: travel
B13: 5 | C13: 4 | D13: 4 | E13: 4 | H13: hats | I13: 25 | J13: 38 | K13: 19 | L13: 12
B14: 3 | C14: 4 | D14: 4 | E14: 4
B15: 4 | C15: 4 | D15: 4 | E15: 4
B16: 4 | C16: 3 | D16: 4 | E16: 4
B17: 4 | C17: 3 | D17: 4 | E17: 4
B18: 3 | C18: 3 | D18: 4 | E18: 4
B19: 4 | C19: 3 | D19: 3 | E19: 4
B20: 4 | C20: 3 | D20: 4 | E20: 4
B21: 4 | C21: 3 | D21: 4
C22: 3 | D22: 5
C23: 4 | D23: 4
C24: 3 | D24: 4
C25: 4 | D25: 4
C26: 3 | D26: 4
C27: 3 | D27: 4
G30: hemline index
A31: AVERAGE | B31: =AVERAGE(B2:B29) -> 3.65 | C31: =AVERAGE(C2:C29) -> 3.3846154 | D31: =AVERAGE(D2:D29) -> 4.0769231 | E31: =AVERAGE(E2:E29) -> 4.0526316 | G31: =AVERAGE(B31:E31) -> 3.7910425

Sheet 1988
B1: January | C1: April | D1: July | E1: October | H1: parfumes: | N1: small luxury
A2: all the data | B2: 4 | C2: 4 | D2: 2 | E2: 2 | H2: cosmetics | I2: 1 | K2: 2 | L2: 1 | N2: =SUM(I1:L6) -> 6
A3: skkirt lengths | B3: 4 | C3: 3 | D3: 2 | E3: 2 | H3: lipstick | K3: 2
B4: 4 | C4: 5 | D4: 3 | E4: 4 | H4: lotions, skin care, hand creams
B5: 3 | C5: 4 | D5: 4 | E5: 4 | H5: nail polist,
B6: 3 | C6: 5 | D6: 4 | E6: 4 | H6: candles
B7: 3 | C7: 2 | D7: 4 | E7: 4
B8: 2 | C8: 2 | D8: 3 | E8: 4 | H8: bags | J8: 5 | K8: 3 | L8: 2 | N8: high luxury
B9: 2 | C9: 2 | D9: 3 | E9: 4 | H9: watches | J9: 2 | N9: =SUM(I8:L13) -> 225
B10: 2 | C10: 2 | D10: 3 | E10: 4 | H10: dining | I10: 2 | K10: 1 | L10: 1
B11: 2 | C11: 2 | D11: 3 | E11: 5 | H11: jewellery | I11: 11 | J11: 36 | K11: 26 | L11: 18
B12: 3 | C12: 2 | D12: 4 | E12: 3 | H12: travel
B13: 3 | C13: 5 | D13: 3 | E13: 3 | H13: hats | I13: 30 | J13: 33 | K13: 28 | L13: 27
B14: 4 | C14: 4 | D14: 3 | E14: 3
B15: 5 | C15: 4 | D15: 3 | E15: 3
B16: 3 | C16: 4 | D16: 3 | E16: 3
B17: 4 | C17: 4 | D17: 4 | E17: 4
B18: 4 | C18: 3 | D18: 2 | E18: 4
B19: 5 | C19: 4 | D19: 3 | E19: 4
B20: 4 | C20: 5 | D20: 2 | E20: 4
B21: 4 | C21: 5 | D21: 4 | E21: 4
B22: 4 | C22: 5 | D22: 3 | E22: 4
B23: 4 | C23: 4 | D23: 3
B24: 4 | C24: 3 | D24: 3
B25: 4 | C25: 4 | D25: 4
B26: 4 | C26: 4 | D26: 4
B27: 4 | C27: 4 | D27: 4
B28: 4 | C28: 4 | D28: 3
B29: 4 | C29: 4 | D29: 4
B30: 5 | C30: 4 | D30: 4
B31: 3 | C31: 4 | D31: 4
B32: 4 | C32: 4 | D32: 4
B33: 3 | C33: 4 | D33: 2
C34: 4 | D34: 2
C35: 5 | D35: 3
C36: 5
C37: 3
C38: 4
C39: 5
C40: 5
...

Sheet 1989
B1: January | C1: April | D1: July | E1: October | H1: parfumes: | I1: 1 | K1: 1 | N1: small luxury
A2: all the data | B2: 4 | C2: 3 | D2: 3 | E2: 5 | H2: cosmetics | I2: 4 | J2: 1 | N2: =SUM(I1:L6) -> 10
A3: skkirt lengths | B3: 4 | C3: 3 | D3: 3 | E3: 3 | H3: lipstick | I3: 3
B4: 3 | C4: 3 | D4: 3 | E4: 4 | H4: lotions, skin care, hand creams
B5: 3 | C5: 3 | D5: 4 | E5: 3 | H5: nail polist,
B6: 3 | C6: 3 | D6: 4 | E6: 3 | H6: candles
B7: 3 | C7: 3 | D7: 4 | E7: 3
B8: 4 | C8: 3 | D8: 4 | E8: 3 | H8: bags | I8: 1 | K8: 4 | L8: 2 | N8: high luxury
B9: 3 | C9: 3 | D9: 4 | E9: 2 | H9: watches | I9: 1 | J9: 1 | K9: 2 | L9: 1 | N9: =SUM(I8:L13) -> 264
B10: 4 | C10: 3 | D10: 5 | E10: 5 | H10: dining
B11: 3 | C11: 3 | D11: 3 | E11: 3 | H11: jewellery | I11: 45 | J11: 30 | K11: 23 | L11: 17
B12: 3 | C12: 3 | D12: 3 | E12: 3 | H12: travel
B13: 3 | C13: 3 | D13: 4 | E13: 3 | H13: hats | I13: 68 | J13: 27 | K13: 22 | L13: 20
B14: 5 | C14: 4 | D14: 3 | E14: 4
B15: 3 | C15: 4 | D15: 3 | E15: 4
B16: 4 | C16: 3 | D16: 4 | E16: 4
B17: 3 | C17: 3 | D17: 4 | E17: 4
B18: 3 | C18: 4 | D18: 4 | E18: 3
B19: 4 | C19: 4 | D19: 3 | E19: 6
B20: 3 | C20: 4 | D20: 3 | E20: 4
B21: 3 | C21: 4 | D21: 4 | E21: 5
B22: 3 | C22: 2 | D22: 4 | E22: 4
B23: 3 | C23: 2 | D23: 5
B24: 3 | C24: 2 | D24: 4
B25: 3 | C25: 2 | D25: 4
B26: 3 | C26: 3 | D26: 4
B27: 3 | C27: 3 | D27: 3
B28: 3 | C28: 4 | D28: 3
B29: 3 | C29: 3 | D29: 4
B30: 2 | C30: 5 | D30: 4
B31: 3 | C31: 3 | D31: 2
B32: 3 | C32: 2 | D32: 2
B33: 3 | C33: 3 | D33: 5
B34: 3 | C34: 2 | D34: 2
B35: 3 | D35: 2
B36: 3 | D36: 4
B37: 4 | D37: 3
B38: 4 | D38: 4
B39: 4 | D39: 4
B40: 4 | D40: 5
...

Sheet 1990
B1: January | C1: April | D1: July | E1: October | H1: parfumes: | N1: small luxury
A2: all the data | B2: 2 | C2: 3 | D2: 2 | E2: 2 | H2: cosmetics | I2: 3 | J2: 1 | K2: 1 | L2: 2 | N2: =SUM(I1:L6) -> 10
A3: skkirt lengths | B3: 3 | C3: 3 | D3: 2 | E3: 2 | H3: lipstick | I3: 1
B4: 4 | C4: 3 | D4: 3 | E4: 3 | H4: lotions, skin care, hand creams | J4: 1 | K4: 1
B5: 3 | C5: 3 | D5: 2 | E5: 4 | H5: nail polist,
B6: 3 | C6: 3 | D6: 2 | E6: 4 | H6: candles
B7: 3 | C7: 3 | D7: 2 | E7: 3
B8: 3 | C8: 4 | D8: 3 | E8: 4 | H8: bags | I8: 5 | J8: 4 | K8: 1 | L8: 1 | N8: high luxury
B9: 4 | C9: 4 | D9: 2 | E9: 4 | H9: watches | J9: 2 | L9: 1 | N9: =SUM(I8:L13) -> 175
B10: 4 | C10: 4 | D10: 3 | E10: 4 | H10: dining | I10: 1
B11: 3 | C11: 4 | D11: 3 | E11: 4 | H11: jewellery | I11: 33 | J11: 32 | K11: 13 | L11: 20
B12: 4 | C12: 4 | D12: 3 | E12: 2 | H12: travel | I12: 1
B13: 4 | C13: 4 | D13: 4 | H13: hats | I13: 27 | J13: 17 | K13: 5 | L13: 12
B14: 4 | C14: 4 | D14: 6
B15: 4 | C15: 4 | D15: 3
B16: 4 | C16: 3 | D16: 5
B17: 4 | C17: 3 | D17: 2
B18: 5 | C18: 2 | D18: 2
B19: 5 | C19: 4 | D19: 2
B20: 6 | C20: 4 | D20: 6
B21: 4 | C21: 4 | D21: 4
B22: 4 | C22: 4 | D22: 4
B23: 4 | C23: 4 | D23: 4
B24: 3 | C24: 4 | D24: 4
B25: 4 | C25: 4 | D25: 5
... B27: 6 | C27: 4 | D27: 4
B28: 3 | C28: 5
B29: 3 | C29: 5
B30: 6 | C30: 4
B31: 6 | C31: 4
B32: 6 | C32: 4
B33: 6 | C33: 1
B34: 6 | C34: 1
B35: 6 | C35: 5
B36: 2 | C36: 2
B37: 2 | C37: 1
B38: 4 | C38: 3
B39: 6 | C39: 3
... B46: 2 | C46: 5
C47: 5
...

Sheet 1991
B1: January | C1: April | D1: July | E1: October | H1: parfumes: | N1: small luxury
A2: all the data | B2: 2 | C2: 2 | D2: 2 | E2: 3 | H2: cosmetics | K2: 2 | L2: 1 | N2: =SUM(I1:L6) -> 3
A3: skkirt lengths | B3: 2 | C3: 2 | D3: 2 | E3: 3 | H3: lipstick
B4: 2 | C4: 2 | D4: 3 | E4: 4 | H4: lotions, skin care, hand creams
B5: 3 | C5: 2 | D5: 3 | E5: 3 | H5: nail polist,
B6: 3 | C6: 6 | D6: 3 | E6: 3 | H6: candles
B7: 3 | C7: 6 | D7: 3 | E7: 3
B8: 6 | C8: 2 | D8: 2 | E8: 3 | H8: bags | I8: 1 | J8: 2 | K8: 2 | L8: 6 | N8: high luxury
B9: 2 | C9: 3 | D9: 2 | E9: 3 | H9: watches | I9: 2 | J9: 1 | L9: 1 | N9: =SUM(I8:L13) -> 221
B10: 3 | C10: 3 | D10: 3 | E10: 3 | H10: dining
B11: 3 | C11: 3 | D11: 3 | E11: 3 | H11: jewellery | I11: 25 | J11: 35 | K11: 38 | L11: 37
B12: 5 | C12: 3 | D12: 2 | E12: 3 | H12: travel
B13: 5 | C13: 2 | D13: 2 | E13: 3 | H13: hats | I13: 13 | J13: 39 | K13: 12 | L13: 7
B14: 2 | C14: 3 | D14: 2 | E14: 5
B15: 2 | C15: 5 | D15: 2 | E15: 5
B16: 3 | C16: 5 | D16: 2 | E16: 3
B17: 6 | C17: 2 | D17: 2 | E17: 3
B18: 5 | C18: 2 | D18: 2 | E18: 4
B19: 3 | C19: 3 | D19: 2 | E19: 4
B20: 3 | C20: 4 | D20: 3 | E20: 4
B21: 3 | C21: 4 | D21: 3 | E21: 4
B22: 3 | C22: 4 | D22: 3 | E22: 2
B23: 3 | C23: 5 | D23: 6 | E23: 2
B24: 4 | C24: 4 | D24: 2 | E24: 2
B25: 2 | C25: 5 | D25: 2 | E25: 2
B26: 3 | C26: 5 | D26: 2 | E26: 2
C27: 4 | D27: 2 | E27: 2
C28: 5 | D28: 4 | E28: 2
C29: 6 | D29: 2 | E29: 2
C30: 3 | D30: 3 | E30: 2
C31: 4 | D31: 3 | E31: 2
C32: 3 | D32: 3 | E32: 2
C33: 3 | D33: 2 | E33: 2
C34: 3 | D34: 2 | E34: 4
C35: 4 | D35: 3 | E35: 3
C36: 4 | D36: 3 | E36: 3
C37: 4 | D37: 3 | E37: 3
C38: 5 | D38: 3 | E38: 3
... C40: 4 | D40: 3 | E40: 2
C41: 4 | D41: 3
...

Sheet 1992
B1: January | C1: April | D1: July | E1: October | H1: parfumes: | K1: 4 | N1: small luxury
A2: all the data | B2: 2 | C2: 1 | D2: 2 | E2: 1 | H2: cosmetics | J2: 9 | K2: 2 | L2: 4 | N2: =SUM(I1:L6) -> 29
A3: skkirt lengths | B3: 2 | C3: 2 | D3: 4 | E3: 3 | H3: lipstick | J3: 6 | L3: 1
B4: 2 | C4: 2 | D4: 2 | E4: 2 | H4: lotions, skin care, hand creams | L4: 3
B5: 2 | C5: 2 | D5: 2 | E5: 3 | H5: nail polist,
B6: 2 | C6: 2 | D6: 2 | E6: 4 | H6: candles
B7: 4 | C7: 2 | D7: 2 | E7: 2
B8: 3 | C8: 2 | D8: 1 | E8: 1 | H8: bags | J8: 4 | K8: 4 | L8: 1 | N8: high luxury
B9: 3 | C9: 2 | D9: 2 | E9: 2 | H9: watches | L9: 1 | N9: =SUM(I8:L13) -> 163
B10: 6 | C10: 2 | D10: 2 | E10: 3 | H10: dining | I10: 5 | K10: 1
B11: 6 | C11: 2 | D11: 4 | E11: 3 | H11: jewellery | I11: 28 | J11: 39 | K11: 19 | L11: 6
B12: 6 | C12: 2 | D12: 2 | H12: travel | K12: 1 | L12: 1
B13: 6 | C13: 2 | D13: 4 | H13: hats | I13: 18 | J13: 24 | K13: 6 | L13: 5
B14: 5 | C14: 2 | D14: 2
B15: 5 | C15: 2 | D15: 2
B16: 5 | C16: 2 | D16: 2
B17: 5 | C17: 2 | D17: 3
B18: 5 | C18: 2
B19: 6 | C19: 2
B20: 2 | C20: 2
B21: 2 | C21: 2
B22: 2 | C22: 2
B23: 2 | C23: 2
B24: 2 | C24: 2
B25: 2 | C25: 2
B26: 4 | C26: 2
B27: 2 | C27: 2
B28: 2 | C28: 2
B29: 2 | C29: 2
... B32: 6 | C32: 2
C33: 3
C34: 2
C35: 2
C36: 2
C37: 2
C38: 2
C39: 2
G42: hemline index
A43: AVERAGE | B43: =AVERAGE(B2:B41) -> 3.516129 | C43: =AVERAGE(C2:C41) -> 2 | D43: =AVERAGE(D2:D41) -> 2.375 | E43: =AVERAGE(E2:E41) -> 2.4 | G43: =AVERAGE(B43:E43) -> 2.5727823

Sheet 1993
B1: January | C1: April | D1: July | E1: October | H1: parfumes: | J1: 1 | L1: 2 | N1: small luxury
A2: all the data | B2: 6 | C2: 2 | D2: 3 | E2: 3 | H2: cosmetics | I2: 2 | J2: 3 | K2: 4 | N2: =SUM(I1:L6) -> 16
A3: skkirt lengths | B3: 2 | C3: 2 | D3: 3 | E3: 3 | H3: lipstick
B4: 2 | C4: 2 | D4: 3 | E4: 4 | H4: lotions, skin care, hand creams | J4: 2 | L4: 2
B5: 6 | C5: 2 | D5: 3 | E5: 4 | H5: nail polist,
B6: 2 | C6: 2 | D6: 3 | E6: 3 | H6: candles
B7: 5 | C7: 2 | D7: 4 | E7: 3
B8: 6 | C8: 2 | D8: 2 | E8: 3 | H8: bags | I8: 1 | J8: 6 | K8: 1 | L8: 2 | N8: high luxury
B9: 6 | C9: 1 | D9: 2 | E9: 3 | H9: watches | L9: 6 | N9: =SUM(I8:L13) -> 166
B10: 6 | C10: 1 | D10: 2 | E10: 3 | H10: dining | J10: 1
B11: 6 | C11: 2 | D11: 4 | E11: 3 | H11: jewellery | I11: 19 | J11: 14 | K11: 14 | L11: 29
B12: 2 | C12: 3 | D12: 5 | E12: 3 | H12: travel | L12: 1
B13: 2 | C13: 3 | D13: 5 | E13: 2 | H13: hats | I13: 9 | J13: 9 | K13: 16 | L13: 38
B14: 6 | C14: 6 | D14: 5 | E14: 2
B15: 2 | C15: 6 | D15: 5 | E15: 2
B16: 2 | C16: 6 | D16: 2 | E16: 2
B17: 2 | C17: 6 | D17: 4 | E17: 4
B18: 3 | C18: 6 | D18: 4 | E18: 4
