Workbook

Sheet BASE
A2: Concluded dataset from the years of hemline index | G2: from 1957 - 1992
A4: HEMLINE VALUES | L4: Reverse Hemline Index
A5: 1957 | B5: =VALUE('1957'!F73) -> 4.5069925 | L5: =VALUE(6-B5) -> 1.4930075
A6: 1958 | B6: =VALUE('1958'!F106) -> 3.3896613 | L6: =VALUE(6-B6) -> 2.6103387
A7: 1959 | B7: =VALUE('1959'!F66) -> 3.6084597 | L7: =VALUE(6-B7) -> 2.3915403
A8: 1960 | B8: =VALUE('1960'!F75) -> 3.8824658 | L8: =VALUE(6-B8) -> 2.1175342
A9: 1961 | B9: =VALUE('1961'!F77) -> 3.6971655 | L9: =VALUE(6-B9) -> 2.3028345
A10: 1962 | B10: =VALUE('1962'!F73) -> 3.5887503 | L10: =VALUE(6-B10) -> 2.4112497
A11: 1963 | B11: =VALUE('1963'!F74) -> 3.8915476 | L11: =VALUE(6-B11) -> 2.1084524
A12: 1964 | B12: =VALUE('1964'!F77) -> 3.8921547 | L12: =VALUE(6-B12) -> 2.1078453
A13: 1965 | B13: =VALUE('1965'!F92) -> 3.9067996 | L13: =VALUE(6-B13) -> 2.0932004
A14: 1966 | B14: =VALUE('1966'!F91) -> 3.6269817 | L14: =VALUE(6-B14) -> 2.3730183
A15: 1967 | B15: =VALUE('1967'!F126) -> 2.67675 | L15: =VALUE(6-B15) -> 3.32325
A16: 1968 | B16: =VALUE('1968'!F135) -> 2.8725887 | L16: =VALUE(6-B16) -> 3.1274113
A17: 1969 | B17: =VALUE('1969'!F143) -> 3.096517 | L17: =VALUE(6-B17) -> 2.903483
A18: 1970 | B18: =VALUE('1970'!F119) -> 3.5081642 | L18: =VALUE(6-B18) -> 2.4918358
A19: 1971 | B19: =VALUE('1971'!F67) -> 3.9991792 | L19: =VALUE(6-B19) -> 2.0008208
A20: 1972 | B20: =VALUE('1972'!F47) -> 4.0442082 | L20: =VALUE(6-B20) -> 1.9557918
A21: 1973 | B21: =VALUE('1973'!F77) -> 3.7884355 | L21: =VALUE(6-B21) -> 2.2115645
A22: 1974 | B22: =VALUE('1974'!F69) -> 3.9653262 | L22: =VALUE(6-B22) -> 2.0346738
A23: 1975 | B23: =VALUE('1975'!F108) -> 4.2362554 | L23: =VALUE(6-B23) -> 1.7637446
A24: 1976 | B24: =VALUE('1976'!F76) -> 4.3291879 | L24: =VALUE(6-B24) -> 1.6708121
A25: 1977 | B25: =VALUE('1977'!F86) -> 4.002422 | L25: =VALUE(6-B25) -> 1.997578
A26: 1978 | B26: =VALUE('1978'!F72) -> 4.2721004 | L26: =VALUE(6-B26) -> 1.7278996
A27: 1979 | B27: =VALUE('1979'!F87) -> 3.8169387 | L27: =VALUE(6-B27) -> 2.1830613
A28: 1980 | B28: =VALUE('1980'!F65) -> 3.3644849 | L28: =VALUE(6-B28) -> 2.6355151
A29: 1981 | B29: =VALUE('1981'!F84) -> 3.5915665 | L29: =VALUE(6-B29) -> 2.4084335
A30: 1982 | B30: =VALUE('1982'!F97) -> 3.4245834 | L30: =VALUE(6-B30) -> 2.5754166
A31: 1983 | B31: =VALUE('1983'!F94) -> 3.4872194 | L31: =VALUE(6-B31) -> 2.5127806
A32: 1984 | B32: =VALUE('1984'!F108) -> 3.8565631 | L32: =VALUE(6-B32) -> 2.1434369
A33: 1985 | B33: =VALUE('1985'!F102) -> 3.6185334 | L33: =VALUE(6-B33) -> 2.3814666
A34: 1986 | B34: =VALUE('1986'!F99) -> 3.746521 | L34: =VALUE(6-B34) -> 2.253479
A35: 1987 | B35: =VALUE('1987'!F115) -> 2.9568527 | L35: =VALUE(6-B35) -> 3.0431473
A36: 1988 | B36: =VALUE('1988'!F84) -> 2.6739755 | L36: =VALUE(6-B36) -> 3.3260245
A37: 1989 | B37: =VALUE('1989'!F114) -> 3.1976534 | L37: =VALUE(6-B37) -> 2.8023466
A38: 1990 | B38: =VALUE('1990'!F88) -> 2.3771555 | L38: =VALUE(6-B38) -> 3.6228445
A39: 1991 | B39: =VALUE('1991'!F75) -> 1.7672543 | L39: =VALUE(6-B39) -> 4.2327457
A40: 1992 | B40: =VALUE('1992'!F81) -> 3.1885319 | L40: =VALUE(6-B40) -> 2.8114681
A46: LIPSTICK INDEX | C46: High | D46: Low | E46: Subtracting low luxuries from high value luxuries
A47: 1957 | C47: =VALUE('1957'!N9) -> 510 | D47: =VALUE('1957'!N2) -> 148 | E47: =C47-D47 -> 362
...

Sheet 1930
A1: 30 | B1: January | C1: April | D1: July | E1: October | J1: parfumes: | M1: 3 | N1: 2
A2: all the data | B2: 3 | C2: 6 | D2: 3 | E2: 4 | J2: cosmetics | M2: 4 | N2: 4
A3: skkirt lengths | B3: 4 | C3: 2 | D3: 1 | E3: 6 | J3: lipstick
B4: 4 | C4: 5 | D4: 2 | E4: 2 | J4: lotions | M4: 1 | N4: 6
B5: 5 | C5: 4 | D5: 6 | E5: 5
B6: 5 | C6: 4 | D6: 4 | E6: 6
B7: 3 | C7: 4 | D7: 3 | E7: 4
B8: 3 | C8: 2 | D8: 4 | E8: 5 | J8: bags | N8: 5
B9: 4 | C9: 1 | D9: 4 | E9: 6 | J9: shoes | M9: 1 | N9: 9
B10: 4 | C10: 5 | D10: 5 | E10: 4 | J10: dresses
B11: 2 | C11: 4 | D11: 5 | E11: 3 | J11: jewellery | N11: 4
B12: 4 | C12: 4 | D12: 4 | E12: 4
B13: 5 | C13: 4 | D13: 4 | E13: 4
B14: 6 | C14: 4 | D14: 4 | E14: 3
B15: 4 | C15: 4 | D15: 4 | E15: 3
B16: 5 | C16: 3 | D16: 3 | E16: 4
B17: 4 | C17: 3 | D17: 3 | E17: 4
B18: 4 | C18: 4 | D18: 4 | E18: 5
B19: 2 | C19: 4 | D19: 4 | E19: 4
B20: 5 | C20: 3 | D20: 4 | E20: 6
B21: 5 | C21: 4 | D21: 4 | E21: 4
B22: 3 | C22: 3 | D22: 4 | E22: 5
B23: 6 | C23: 1 | D23: 4 | E23: 5
... B34: 3 | C34: 6 | D34: 3 | E34: 6
B35: 4 | C35: 3 | E35: 3
B36: 4 | C36: 4 | E36: 3
B37: 4 | C37: 4 | E37: 4
B38: 5 | C38: 4 | E38: 4
B39: 5 | C39: 4 | E39: 5
B40: 4 | C40: 6 | E40: 4
B41: 3 | C41: 4 | E41: 4
B42: 5 | C42: 4 | E42: 5
B43: 6 | C43: 4 | E43: 3
B44: 3 | C44: 4 | E44: 4
B45: 3 | C45: 6 | E45: 4
C46: 6 | E46: 4
C47: 6 | E47: 5
C48: 6 | E48: 6
C49: 5 | E49: 4
C50: 4 | E50: 3
...

Sheet 1932
A1: January | B1: April | C1: July | D1: October
A2: 4 | B2: 4 | C2: 1 | D2: 4 | I2: parfumes: | J2: 1 | K2: 2 | L2: 3 | M2: 3 | O2: small luxury
A3: 1 | B3: 5 | C3: 3 | D3: 4 | I3: cosmetics | K3: 4 | L3: 7 | M3: 4 | O3: =SUM(J2:M7) -> 27
A4: 4 | B4: 4 | C4: 5 | D4: 6 | I4: lipstick | J4: 1
A5: 4 | B5: 4 | C5: 6 | D5: 6 | I5: lotions, skin care, hand creams | J5: 1 | K5: 1
A6: 5 | B6: 4 | C6: 5 | D6: 6 | I6: nail polist,
A7: 4 | B7: 4 | C7: 4 | D7: 4 | I7: candles
A8: 4 | B8: 4 | C8: 1 | D8: 4
A9: 4 | B9: 4 | C9: 1 | D9: 3 | I9: bags | J9: 3 | M9: 2 | O9: high luxury
A10: 4 | B10: 4 | C10: 5 | D10: 4 | I10: watches | O10: =SUM(J9:M14) -> 15
A11: 5 | B11: 5 | C11: 6 | D11: 4 | I11: dining
A12: 6 | B12: 4 | C12: 5 | D12: 6 | I12: jewellery | J12: 1
A13: 6 | B13: 6 | C13: 6 | D13: 4 | I13: travel | J13: 4 | L13: 1 | M13: 1
A14: 4 | B14: 4 | C14: 5 | D14: 5 | I14: hats | K14: 1 | M14: 2
A15: 5 | B15: 6 | C15: 6 | D15: 4
A16: 6 | B16: 5 | C16: 4 | D16: 5
A17: 5 | B17: 5 | C17: 4 | D17: 6
A18: 5 | B18: 5 | C18: 4 | D18: 6
A19: 6 | B19: 6 | C19: 6 | D19: 4 | I19: Non categorized
A20: 4 | B20: 6 | C20: 5 | D20: 4 | I20: gloves | K20: 2 | M20: 1
A21: 3 | B21: 4 | C21: 6 | D21: 6 | I21: glasses | K21: 1 | L21: 2
A22: 4 | B22: 4 | C22: 1 | D22: 6 | I22: shoes | J22: 3 | K22: 6 | L22: 1 | M22: 6
A23: 4 | B23: 4 | C23: 6 | D23: 3
A24: 6 | B24: 6 | C24: 1 | D24: 4
A25: 6 | B25: 6 | C25: 5 | D25: 6
A26: 6 | B26: 6 | C26: 4 | D26: 5
A27: 6 | B27: 5 | C27: 4 | D27: 5
A28: 6 | B28: 5 | C28: 5 | D28: 6
A29: 4 | B29: 5 | D29: 4
A30: 5 | B30: 5 | D30: 4
A31: 4 | B31: 4 | D31: 4
A32: 4 | B32: 4 | D32: 6
A33: 4 | B33: 4 | D33: 5
A34: 4 | B34: 4 | D34: 4
A35: 5 | B35: 4 | D35: 6
A36: 1 | B36: 4 | D36: 6
A37: 3 | B37: 5 | D37: 4
A38: 1 | B38: 4 | D38: 4
A39: 4 | B39: 4 | D39: 4
A40: 3 | B40: 4 | D40: 4
...

Sheet 1957
A1: January | B1: April | C1: July | D1: October | H1: parfumes: | J1: 5 | K1: 4 | L1: 8 | N1: small luxury
A2: 4 | B2: 4 | C2: 5 | D2: 4 | H2: cosmetics | J2: 7 | K2: 9 | L2: 8 | N2: =SUM(I1:L6) -> 148
A3: 4 | B3: 5 | C3: 6 | D3: 4 | H3: lipstick | I3: 30 | J3: 14 | K3: 14 | L3: 23
A4: 3 | B4: 4 | C4: 4 | D4: 6 | H4: lotions, skin care, hand creams | L4: 2
A5: 4 | B5: 4 | C5: 4 | D5: 6 | H5: nail polist, | I5: 5 | J5: 7 | K5: 8 | L5: 3
A6: 6 | B6: 6 | C6: 5 | D6: 5 | H6: candles | J6: 1
A7: 4 | B7: 4 | C7: 6 | D7: 4
A8: 3 | B8: 4 | C8: 4 | D8: 4 | H8: bags | I8: 14 | J8: 16 | K8: 15 | L8: 25 | N8: high luxury
A9: 4 | B9: 6 | C9: 6 | D9: 4 | H9: watches | J9: 3 | N9: =SUM(I8:L13) -> 510
A10: 4 | B10: 4 | C10: 5 | D10: 4 | H10: dining | J10: 2 | K10: 5 | L10: 2
A11: 4 | B11: 4 | C11: 5 | D11: 5 | H11: jewellery | I11: 74 | J11: 77 | K11: 35 | L11: 57
A12: 4 | B12: 4 | C12: 4 | D12: 4 | H12: travel | J12: 2 | K12: 2 | L12: 5
A13: 4 | B13: 4 | C13: 4 | D13: 6 | H13: hats | I13: 47 | J13: 40 | K13: 24 | L13: 65
A14: 4 | B14: 4 | C14: 5 | D14: 4
A15: 4 | B15: 4 | C15: 4 | D15: 4
A16: 4 | B16: 4 | C16: 4 | D16: 6
A17: 4 | B17: 4 | C17: 5 | D17: 4
A18: 4 | B18: 4 | C18: 6 | D18: 4
A19: 4 | B19: 4 | C19: 5 | D19: 4
A20: 4 | B20: 4 | C20: 5 | D20: 4
A21: 5 | B21: 6 | C21: 4 | D21: 5
A22: 4 | B22: 4 | C22: 4 | D22: 5
A23: 4 | B23: 5 | C23: 5 | D23: 4
A24: 4 | B24: 5 | C24: 4 | D24: 4
A25: 3 | B25: 4 | C25: 4 | D25: 4
... A45: 3 | B45: 5 | C45: 6 | D45: 5
A46: 3 | B46: 6 | D46: 4
A47: 3 | B47: 6 | D47: 4
A48: 3 | B48: 6 | D48: 4
A49: 4 | B49: 6 | D49: 4
A50: 4 | B50: 6
A51: 6 | B51: 5
A52: 6 | B52: 5
A53: 4 | B53: 5
A54: 4 | B54: 5
A55: 4 | B55: 6
A56: 2
A57: 2
A58: 3
A59: 4
...

Sheet 1958
A1: January | B1: April | C1: July | D1: October | H1: parfumes: | I1: 1 | J1: 3 | K1: 2 | L1: 11 | N1: small luxury
A2: 3 | B2: 3 | C2: 6 | D2: 3 | H2: cosmetics | I2: 3 | J2: 5 | K2: 5 | L2: 14 | N2: =SUM(I1:L6) -> 78
A3: 4 | B3: 4 | C3: 3 | D3: 4 | H3: lipstick | I3: 3 | J3: 5 | K3: 12 | L3: 5
A4: 3 | B4: 3 | C4: 3 | D4: 4 | H4: lotions, skin care, hand creams | J4: 1
A5: 4 | B5: 3 | C5: 6 | D5: 4 | H5: nail polist, | I5: 1 | J5: 3 | K5: 3 | L5: 1
A6: 1 | B6: 3 | C6: 4 | D6: 3 | H6: candles
A7: 1 | B7: 5 | C7: 4 | D7: 4
A8: 4 | B8: 4 | C8: 4 | D8: 3 | H8: bags | I8: 13 | J8: 7 | K8: 6 | L8: 17 | N8: high luxury
A9: 1 | B9: 4 | C9: 3 | D9: 3 | H9: watches | I9: 1 | J9: 4 | N9: =SUM(I8:L13) -> 274
A10: 1 | B10: 4 | C10: 4 | D10: 3 | H10: dining
A11: 1 | B11: 4 | C11: 3 | D11: 5 | H11: jewellery | I11: 32 | J11: 28 | K11: 9 | L11: 24
A12: 1 | B12: 1 | C12: 4 | D12: 3 | H12: travel | I12: 1 | L12: 2
A13: 3 | B13: 3 | C13: 3 | D13: 4 | H13: hats | I13: 23 | J13: 48 | K13: 7 | L13: 52
A14: 1 | B14: 3 | C14: 3 | D14: 4
A15: 4 | B15: 4 | C15: 4 | D15: 3
A16: 1 | B16: 4 | C16: 3 | D16: 3
A17: 1 | B17: 3 | C17: 6 | D17: 3
A18: 1 | B18: 4 | C18: 5 | D18: 3
A19: 2 | B19: 4 | C19: 5 | D19: 3
A20: 3 | B20: 6 | C20: 4 | D20: 3
A21: 3 | B21: 3 | C21: 6 | D21: 4
A22: 3 | B22: 3 | C22: 6 | D22: 3
A23: 1 | B23: 3 | C23: 1 | D23: 4
A24: 3 | B24: 1 | C24: 1 | D24: 4
A25: 3 | B25: 3 | C25: 1 | D25: 6
... A55: 3 | B55: 3 | C55: 2 | D55: 3
A56: 5 | B56: 3 | D56: 4
A57: 6 | B57: 3 | D57: 3
A58: 1 | B58: 3 | D58: 5
A59: 4 | B59: 3 | D59: 4
A60: 4 | B60: 3 | D60: 5
A61: 3 | B61: 4 | D61: 4
A62: 5 | B62: 3 | D62: 4
A63: 5 | B63: 3 | D63: 6
A64: 4 | B64: 3 | D64: 4
A65: 3 | B65: 3 | D65: 3
A66: 3 | B66: 3 | D66: 3
A67: 3 | B67: 3 | D67: 3
B68: 3 | D68: 3
B69: 4 | D69: 3
...

Sheet 1959
A1: January | B1: April | C1: July | D1: October | H1: parfumes: | J1: 2 | K1: 4 | L1: 3 | N1: small luxury
A2: 4 | B2: 3 | C2: 3 | D2: 3 | H2: cosmetics | I2: 2 | J2: 5 | K2: 8 | L2: 6 | N2: =SUM(I1:L6) -> 99
A3: 4 | B3: 3 | C3: 4 | D3: 3 | H3: lipstick | I3: 14 | J3: 9 | K3: 9 | L3: 13
A4: 4 | B4: 4 | C4: 3 | D4: 5 | H4: lotions, skin care, hand creams | I4: 3 | J4: 3 | K4: 1 | L4: 4
A5: 2 | B5: 3 | C5: 4 | D5: 3 | H5: nail polist, | I5: 4 | J5: 3 | K5: 3 | L5: 3
A6: 2 | B6: 4 | C6: 4 | D6: 3 | H6: candles
A7: 4 | B7: 4 | C7: 3 | D7: 4
A8: 3 | B8: 6 | C8: 3 | D8: 3 | H8: bags | I8: 26 | J8: 22 | K8: 28 | L8: 33 | N8: high luxury
A9: 4 | B9: 4 | C9: 3 | D9: 3 | H9: watches | L9: 1 | N9: =SUM(I8:L13) -> 485
A10: 4 | B10: 4 | C10: 3 | D10: 3 | H10: dining | J10: 1 | K10: 6 | L10: 3
A11: 4 | B11: 3 | C11: 3 | D11: 4 | H11: jewellery | I11: 53 | J11: 43 | K11: 34 | L11: 59
A12: 4 | B12: 3 | C12: 3 | D12: 3 | H12: travel | I12: 7 | J12: 3 | K12: 5 | L12: 4
A13: 4 | B13: 3 | C13: 3 | D13: 4 | H13: hats | I13: 39 | J13: 23 | K13: 39 | L13: 56
A14: 5 | B14: 3 | C14: 3 | D14: 4
A15: 4 | B15: 4 | C15: 3 | D15: 4
A16: 6 | B16: 4 | C16: 4 | D16: 4
A17: 5 | B17: 4 | C17: 4 | D17: 4
A18: 3 | B18: 3 | C18: 3 | D18: 4
A19: 3 | B19: 3 | C19: 3 | D19: 4
A20: 3 | B20: 2 | C20: 3 | D20: 5
A21: 3 | B21: 4 | C21: 3 | D21: 6
A22: 3 | B22: 4 | C22: 3 | D22: 5
A23: 3 | B23: 2 | C23: 6 | D23: 6
A24: 3 | B24: 3 | C24: 6 | D24: 5
A25: 4 | B25: 3 | C25: 3 | D25: 4
... A34: 3 | B34: 4 | C34: 4 | D34: 5
A35: 3 | B35: 4 | D35: 4
A36: 3 | B36: 4 | D36: 4
A37: 3 | B37: 6 | D37: 4
A38: 3 | B38: 2 | D38: 3
A39: 3 | B39: 2 | D39: 3
A40: 3 | B40: 6 | D40: 6
A41: 4 | B41: 5 | D41: 6
A42: 3 | B42: 5 | D42: 6
A43: 4 | B43: 3 | D43: 5
A44: 3 | B44: 6 | D44: 3
A45: 3 | B45: 6 | D45: 3
A46: 3 | B46: 5 | D46: 3
... A56: 3 | B56: 3 | D56: 3
A57: 3 | D57: 3
...

Sheet 1960
A1: January | B1: April | C1: July | D1: October | H1: parfumes: | J1: 3 | K1: 1 | L1: 5 | N1: small luxury
A2: 4 | B2: 4 | C2: 5 | D2: 3 | H2: cosmetics | I2: 5 | J2: 11 | K2: 13 | L2: 16 | N2: =SUM(I1:L6) -> 119
A3: 3 | B3: 3 | C3: 3 | D3: 3 | H3: lipstick | I3: 3 | J3: 19 | K3: 18 | L3: 10
A4: 3 | B4: 3 | C4: 3 | D4: 3 | H4: lotions, skin care, hand creams | I4: 2 | J4: 1 | L4: 2
A5: 3 | B5: 4 | C5: 4 | D5: 6 | H5: nail polist, | I5: 2 | J5: 3 | K5: 3 | L5: 2
A6: 4 | B6: 4 | C6: 5 | D6: 3 | H6: candles
A7: 3 | B7: 4 | C7: 6 | D7: 4
A8: 3 | B8: 4 | C8: 3 | D8: 4 | H8: bags | I8: 22 | J8: 17 | K8: 20 | L8: 27 | N8: high luxury
A9: 3 | B9: 3 | C9: 3 | D9: 6 | H9: watches | N9: =SUM(I8:L13) -> 461
A10: 4 | B10: 4 | C10: 3 | D10: 3 | H10: dining | K10: 2 | L10: 2
A11: 3 | B11: 4 | C11: 6 | D11: 3 | H11: jewellery | I11: 57 | J11: 42 | K11: 36 | L11: 67
A12: 3 | B12: 6 | C12: 3 | D12: 6 | H12: travel | I12: 8 | J12: 5 | K12: 4 | L12: 6
A13: 4 | B13: 2 | C13: 3 | D13: 6 | H13: hats | I13: 37 | J13: 40 | K13: 37 | L13: 32
A14: 3 | B14: 4 | C14: 6 | D14: 6
A15: 3 | B15: 4 | C15: 6 | D15: 3
A16: 3 | B16: 4 | C16: 6 | D16: 3
A17: 3 | B17: 4 | C17: 3 | D17: 4
A18: 3 | B18: 4 | C18: 3 | D18: 4
A19: 3 | B19: 3 | C19: 6 | D19: 4
A20: 4 | B20: 4 | C20: 6 | D20: 4
A21: 3 | B21: 4 | C21: 6 | D21: 5
A22: 4 | B22: 4 | C22: 3 | D22: 4
A23: 4 | B23: 4 | C23: 3 | D23: 6
A24: 4 | B24: 3 | C24: 3 | D24: 3
A25: 4 | B25: 3 | C25: 3 | D25: 3
... A41: 3 | B41: 4 | C41: 4 | D41: 3
A42: 2 | B42: 4 | D42: 3
A43: 2 | B43: 4 | D43: 3
A44: 3 | B44: 4 | D44: 3
A45: 2 | B45: 4 | D45: 3
A46: 4 | B46: 4 | D46: 3
A47: 4 | B47: 6 | D47: 3
A48: 4 | B48: 4 | D48: 4
A49: 4 | B49: 6 | D49: 6
A50: 2 | B50: 6 | D50: 6
A51: 4 | B51: 5 | D51: 3
A52: 4 | B52: 5 | D52: 3
A53: 4 | D53: 6
A54: 4 | D54: 6
A55: 4 | D55: 6
...

Sheet 1961
A1: January | B1: April | C1: July | D1: October | H1: parfumes: | I1: 1 | J1: 2 | L1: 5 | N1: small luxury
A2: 3 | B2: 3 | C2: 4 | D2: 3 | H2: cosmetics | I2: 4 | J2: 13 | K2: 5 | L2: 8 | N2: =SUM(I1:L6) -> 92
A3: 3 | B3: 3 | C3: 6 | D3: 3 | H3: lipstick | I3: 11 | J3: 14 | K3: 4 | L3: 7
A4: 5 | B4: 4 | C4: 3 | D4: 3 | H4: lotions, skin care, hand creams | I4: 2 | J4: 5
A5: 5 | B5: 3 | C5: 6 | D5: 3 | H5: nail polist, | J5: 2 | K5: 5 | L5: 3
A6: 4 | B6: 3 | C6: 6 | D6: 5 | H6: candles | K6: 1
A7: 4 | B7: 3 | C7: 4 | D7: 4
A8: 4 | B8: 3 | C8: 4 | D8: 4 | H8: bags | I8: 10 | J8: 17 | K8: 3 | L8: 12 | N8: high luxury
A9: 4 | B9: 3 | C9: 3 | D9: 3 | H9: watches | N9: =SUM(I8:L13) -> 362
A10: 4 | B10: 3 | C10: 4 | D10: 6 | H10: dining | I10: 1 | J10: 1 | K10: 6 | L10: 4
A11: 4 | B11: 3 | C11: 4 | D11: 4 | H11: jewellery | I11: 49 | J11: 49 | K11: 22 | L11: 46
A12: 5 | B12: 3 | C12: 4 | D12: 3 | H12: travel | I12: 3 | J12: 9 | K12: 6 | L12: 3
A13: 3 | B13: 3 | C13: 4 | D13: 4 | H13: hats | I13: 29 | J13: 48 | K13: 16 | L13: 28
A14: 3 | B14: 3 | C14: 3 | D14: 3
A15: 3 | B15: 3 | C15: 3 | D15: 3
A16: 4 | B16: 3 | C16: 3 | D16: 3
A17: 4 | B17: 3 | C17: 3 | D17: 5
A18: 4 | B18: 3 | C18: 3 | D18: 3
A19: 3 | B19: 4 | C19: 4 | D19: 3
A20: 3 | B20: 3 | C20: 4 | D20: 3
A21: 3 | B21: 3 | C21: 4 | D21: 5
A22: 3 | B22: 4 | C22: 4 | D22: 4
A23: 3 | B23: 4 | C23: 4 | D23: 4
A24: 4 | B24: 2 | C24: 4 | D24: 3
A25: 4 | B25: 4 | C25: 5 | D25: 4
A26: 3 | B26: 3 | C26: 3 | D26: 5
A27: 3 | B27: 4 | D27: 4
A28: 3 | B28: 4 | D28: 4
A29: 4 | B29: 4 | D29: 5
A30: 4 | B30: 4 | D30: 6
A31: 3 | B31: 6 | D31: 6
A32: 3 | B32: 4 | D32: 6
A33: 3 | B33: 3 | D33: 6
A34: 4 | B34: 4 | D34: 5
A35: 3 | B35: 4 | D35: 5
A36: 3 | B36: 4 | D36: 5
A37: 4 | B37: 4 | D37: 4
A38: 3 | B38: 2 | D38: 4
... A43: 3 | B43: 4 | D43: 4
A44: 3 | B44: 4
...

Sheet 1962
A1: January | B1: April | C1: July | D1: October | G1: parfumes: | H1: 1 | I1: 4 | J1: 1 | K1: 5 | M1: small luxury
A2: 3 | B2: 3 | C2: 3 | D2: 3 | G2: cosmetics | H2: 6 | I2: 9 | J2: 8 | K2: 19 | M2: =SUM(H1:K6) -> 114
A3: 3 | B3: 3 | C3: 3 | D3: 3 | G3: lipstick | H3: 7 | I3: 21 | J3: 7 | K3: 13
A4: 3 | B4: 3 | C4: 3 | D4: 3 | G4: lotions, skin care, hand creams
A5: 3 | B5: 3 | C5: 4 | D5: 4 | G5: nail polist, | H5: 2 | I5: 6 | J5: 1 | K5: 4
A6: 3 | B6: 3 | C6: 3 | D6: 6 | G6: candles
A7: 3 | B7: 3 | C7: 3 | D7: 3
A8: 3 | B8: 4 | C8: 6 | D8: 3 | G8: bags | H8: 4 | I8: 23 | J8: 5 | K8: 5 | M8: high luxury
A9: 3 | B9: 4 | C9: 2 | D9: 3 | G9: watches | M9: =SUM(H8:K13) -> 326
A10: 3 | B10: 4 | C10: 3 | D10: 6 | G10: dining | H10: 1 | I10: 2 | J10: 5 | K10: 6
A11: 4 | B11: 4 | C11: 3 | D11: 6 | G11: jewellery | H11: 18 | I11: 55 | J11: 18 | K11: 49
A12: 4 | B12: 3 | C12: 3 | D12: 3 | G12: travel | H12: 7 | I12: 8 | J12: 8 | K12: 9
A13: 3 | B13: 3 | C13: 3 | D13: 3 | G13: hats | H13: 17 | I13: 33 | J13: 18 | K13: 35
A14: 3 | B14: 3 | C14: 3 | D14: 6
A15: 3 | B15: 3 | C15: 3 | D15: 6
A16: 3 | B16: 3 | C16: 3 | D16: 6
A17: 3 | B17: 3 | C17: 3 | D17: 3
A18: 3 | B18: 6 | C18: 3 | D18: 3
A19: 2 | B19: 3 | C19: 3 | D19: 3
A20: 2 | B20: 3 | C20: 3 | D20: 3
A21: 3 | B21: 3 | C21: 3 | D21: 3
A22: 3 | B22: 4 | C22: 3 | D22: 6
A23: 3 | B23: 3 | C23: 3 | D23: 3
A24: 3 | B24: 3 | C24: 4 | D24: 3
A25: 4 | B25: 3 | C25: 5 | D25: 3
... A28: 4 | B28: 3 | C28: 6 | D28: 3
A29: 5 | B29: 6 | D29: 6
A30: 5 | B30: 3 | D30: 3
B31: 4 | D31: 3
B32: 3 | D32: 3
B33: 4 | D33: 3
B34: 4 | D34: 3
B35: 4 | D35: 3
B36: 4 | D36: 3
B37: 3 | D37: 3
B38: 3 | D38: 3
B39: 3 | D39: 3
B40: 4 | D40: 3
B41: 4 | D41: 4
B42: 4 | D42: 3
...

Sheet 1963
A1: January | B1: April | C1: July | D1: October | G1: parfumes: | H1: 1 | I1: 6 | J1: 1 | K1: 12 | M1: small luxury
A2: 4 | B2: 3 | C2: 3 | D2: 6 | G2: cosmetics | H2: 3 | I2: 11 | J2: 6 | K2: 21 | M2: =SUM(H1:K6) -> 117
A3: 4 | B3: 4 | C3: 5 | D3: 4 | G3: lipstick | H3: 6 | I3: 16 | J3: 4 | K3: 17
A4: 3 | B4: 4 | C4: 3 | D4: 4 | G4: lotions, skin care, hand creams | I4: 1 | K4: 5
A5: 3 | B5: 6 | C5: 6 | D5: 4 | G5: nail polist, | H5: 1 | I5: 2 | J5: 1 | K5: 3
A6: 3 | B6: 3 | C6: 6 | D6: 4 | G6: candles
A7: 3 | B7: 3 | C7: 5 | D7: 3
A8: 3 | B8: 5 | C8: 6 | D8: 5 | G8: bags | H8: 8 | I8: 17 | J8: 1 | K8: 4 | M8: high luxury
A9: 3 | B9: 5 | C9: 5 | D9: 4 | G9: watches | K9: 7 | M9: =SUM(H8:K13) -> 296
A10: 3 | B10: 3 | C10: 5 | D10: 3 | G10: dining | H10: 3 | J10: 4 | K10: 8
A11: 3 | B11: 3 | C11: 4 | D11: 3 | G11: jewellery | H11: 30 | I11: 22 | J11: 20 | K11: 43
A12: 3 | B12: 6 | C12: 4 | D12: 5 | G12: travel | H12: 9 | I12: 6 | J12: 6 | K12: 5
A13: 5 | B13: 5 | C13: 4 | D13: 5 | G13: hats | H13: 29 | I13: 34 | J13: 10 | K13: 30
A14: 4 | B14: 5 | C14: 3 | D14: 3
A15: 3 | B15: 3 | C15: 4 | D15: 6
A16: 3 | B16: 3 | C16: 4 | D16: 5
A17: 3 | B17: 3 | C17: 3 | D17: 5
A18: 3 | B18: 3 | C18: 3 | D18: 5
A19: 3 | B19: 5 | C19: 6 | D19: 3
A20: 4 | B20: 5 | C20: 5 | D20: 5
A21: 3 | B21: 4 | C21: 5 | D21: 3
A22: 3 | B22: 5 | C22: 3 | D22: 3
A23: 3 | B23: 4 | C23: 3 | D23: 4
A24: 4 | B24: 3 | C24: 3 | D24: 3
A25: 4 | B25: 4 | C25: 4 | D25: 5
A26: 4 | B26: 3 | C26: 4 | D26: 6
A27: 4 | B27: 4 | D27: 6
A28: 6 | B28: 4 | D28: 5
A29: 3 | B29: 4 | D29: 5
A30: 3 | B30: 3 | D30: 5
A31: 2 | B31: 3 | D31: 4
A32: 2 | B32: 3 | D32: 5
A33: 2 | B33: 3 | D33: 5
A34: 3 | B34: 4 | D34: 5
A35: 3 | B35: 4 | D35: 5
A36: 3 | B36: 3 | D36: 3
A37: 4 | B37: 3 | D37: 5
A38: 4 | B38: 3 | D38: 3
... A41: 4 | B41: 3 | D41: 5
A42: 4 | D42: 5
...

Sheet 1964
A1: January | B1: April | C1: July | D1: October | G1: parfumes: | H1: 1 | I1: 5 | J1: 1 | K1: 11 | M1: small luxury
A2: 6 | B2: 2 | C2: 3 | D2: 5 | G2: cosmetics | H2: 1 | I2: 17 | J2: 10 | K2: 17 | M2: =SUM(H1:K6) -> 123
A3: 3 | B3: 3 | C3: 3 | D3: 5 | G3: lipstick | H3: 2 | I3: 14 | J3: 7 | K3: 11
A4: 3 | B4: 6 | C4: 3 | D4: 6 | G4: lotions, skin care, hand creams | H4: 5 | I4: 6 | J4: 1 | K4: 6
A5: 6 | B5: 3 | C5: 3 | D5: 4 | G5: nail polist, | I5: 3 | J5: 3 | K5: 2
A6: 4 | B6: 6 | C6: 3 | D6: 4 | G6: candles
A7: 3 | B7: 4 | C7: 3 | D7: 3
A8: 3 | B8: 3 | C8: 3 | D8: 3 | G8: bags | H8: 5 | I8: 8 | J8: 3 | K8: 11 | M8: high luxury
A9: 4 | B9: 5 | C9: 3 | D9: 4 | G9: watches | M9: =SUM(H8:K13) -> 273
A10: 3 | B10: 4 | C10: 3 | D10: 4 | G10: dining | I10: 7 | J10: 4 | K10: 6
A11: 3 | B11: 3 | C11: 3 | D11: 5 | G11: jewellery | H11: 13 | I11: 46 | J11: 13 | K11: 40
A12: 3 | B12: 3 | C12: 3 | D12: 5 | G12: travel | H12: 12 | I12: 6 | J12: 4 | K12: 5
A13: 5 | B13: 4 | C13: 3 | D13: 5 | G13: hats | H13: 30 | I13: 32 | J13: 13 | K13: 15
A14: 3 | B14: 3 | C14: 5 | D14: 3
A15: 3 | B15: 3 | C15: 3 | D15: 3
A16: 4 | B16: 4 | C16: 3 | D16: 3
A17: 5 | B17: 4 | C17: 3 | D17: 6
A18: 3 | B18: 5 | C18: 5 | D18: 5
A19: 6 | B19: 5 | C19: 3 | D19: 5
A20: 2 | B20: 3 | C20: 6 | D20: 3
A21: 2 | B21: 4 | C21: 5 | D21: 3
A22: 2 | B22: 3 | C22: 6 | D22: 3
A23: 2 | B23: 2 | C23: 6 | D23: 3
A24: 3 | B24: 5 | C24: 6 | D24: 3
A25: 3 | B25: 4 | C25: 6 | D25: 3
... A31: 3 | B31: 3 | C31: 3 | D31: 6
A32: 3 | B32: 5 | D32: 3
A33: 3 | B33: 3 | D33: 4
A34: 4 | B34: 3 | D34: 3
A35: 4 | B35: 5 | D35: 3
A36: 4 | B36: 6 | D36: 3
A37: 3 | B37: 3 | D37: 5
A38: 6 | B38: 3 | D38: 5
A39: 3 | B39: 2 | D39: 5
A40: 4 | B40: 3 | D40: 4
A41: 3 | B41: 3 | D41: 3
A42: 5 | B42: 3 | D42: 3
A43: 3 | B43: 3 | D43: 3
... A55: 6 | B55: 3 | D55: 3
B56: 6 | D56: 3
...

Sheet 1965
A1: January | B1: April | C1: July | D1: October | G1: parfumes: | H1: 1 | I1: 9 | J1: 3 | K1: 10 | M1: small luxury
A2: 6 | B2: 6 | C2: 3 | D2: 3 | G2: cosmetics | H2: 6 | I2: 14 | J2: 11 | K2: 18 | M2: =SUM(H1:K6) -> 150
A3: 3 | B3: 3 | C3: 3 | D3: 3 | G3: lipstick | H3: 7 | I3: 19 | J3: 12 | K3: 18
A4: 3 | B4: 3 | C4: 3 | G4: lotions, skin care, hand creams | J4: 1 | K4: 4
A5: 3 | B5: 3 | C5: 3 | D5: 5 | G5: nail polist, | I5: 7 | J5: 3 | K5: 4
A6: 2 | B6: 3 | C6: 6 | D6: 3 | G6: candles | J6: 1 | K6: 2
A7: 3 | B7: 3 | C7: 2 | D7: 3
A8: 3 | B8: 3 | C8: 3 | D8: 3 | G8: bags | H8: 8 | I8: 13 | J8: 1 | K8: 15 | M8: high luxury
A9: 3 | B9: 3 | C9: 6 | D9: 5 | G9: watches | M9: =SUM(H8:K13) -> 382
A10: 3 | B10: 3 | C10: 3 | D10: 4 | G10: dining | I10: 7 | J10: 5 | K10: 13
A11: 3 | B11: 3 | C11: 3 | D11: 5 | G11: jewellery | H11: 20 | I11: 71 | J11: 19 | K11: 84
A12: 2 | B12: 3 | C12: 3 | D12: 3 | G12: travel | H12: 11 | I12: 18 | J12: 3 | K12: 5
A13: 3 | B13: 3 | C13: 3 | D13: 6 | G13: hats | H13: 16 | I13: 26 | J13: 12 | K13: 35
A14: 3 | B14: 3 | C14: 3 | D14: 5
A15: 5 | B15: 6 | C15: 3 | D15: 3
A16: 3 | B16: 4 | C16: 3 | D16: 6
A17: 3 | B17: 3 | C17: 3 | D17: 3
A18: 3 | B18: 3 | C18: 3 | D18: 3
A19: 3 | B19: 3 | C19: 4 | D19: 3
A20: 3 | B20: 4 | C20: 4 | D20: 3
A21: 3 | B21: 3 | C21: 3 | D21: 5
A22: 3 | B22: 3 | C22: 4 | D22: 4
A23: 3 | B23: 2 | C23: 4 | D23: 3
A24: 3 | B24: 3 | C24: 3 | D24: 4
A25: 2 | B25: 3 | C25: 4 | D25: 3
... A34: 4 | B34: 3 | C34: 5 | D34: 3
A35: 4 | B35: 3 | D35: 5
A36: 2 | B36: 3 | D36: 6
A37: 2 | B37: 3 | D37: 5
A38: 3 | B38: 4 | D38: 3
A39: 3 | B39: 3 | D39: 6
A40: 5 | B40: 3 | D40: 5
A41: 5 | B41: 3 | D41: 5
A42: 3 | B42: 5 | D42: 5
A43: 3 | B43: 3 | D43: 5
A44: 6 | B44: 3 | D44: 3
A45: 6 | B45: 4 | D45: 3
A46: 6 | B46: 3 | D46: 3
... A68: 5 | B68: 3 | D68: 6
B69: 4 | D69: 3
...

Sheet 1966
A1: January | B1: April | C1: July | D1: October | G1: parfumes: | H1: 1 | I1: 15 | J1: 3 | K1: 25 | M1: small luxury
A2: 3 | B2: 3 | C2: 3 | D2: 3 | G2: cosmetics | H2: 5 | I2: 14 | J2: 10 | K2: 17 | M2: =SUM(H1:K6) -> 163
A3: 3 | B3: 3 | C3: 4 | D3: 3 | G3: lipstick | H3: 3 | I3: 15 | J3: 8 | K3: 13
A4: 3 | B4: 4 | C4: 3 | D4: 6 | G4: lotions, skin care, hand creams | J4: 7 | K4: 4
A5: 3 | B5: 4 | C5: 6 | D5: 6 | G5: nail polist, | I5: 5 | K5: 16
A6: 3 | B6: 3 | C6: 3 | D6: 3 | G6: candles | K6: 2
A7: 3 | B7: 6 | C7: 3 | D7: 3
A8: 3 | B8: 3 | C8: 3 | D8: 3 | G8: bags | H8: 12 | I8: 17 | J8: 5 | K8: 4 | M8: high luxury
A9: 3 | B9: 3 | C9: 3 | D9: 3 | G9: watches | K9: 2 | M9: =SUM(H8:K13) -> 349
A10: 3 | B10: 3 | C10: 3 | D10: 3 | G10: dining | H10: 1 | I10: 6 | J10: 3 | K10: 15
A11: 3 | B11: 6 | C11: 3 | D11: 3 | G11: jewellery | H11: 29 | I11: 46 | J11: 10 | K11: 58
A12: 3 | B12: 3 | C12: 4 | D12: 3 | G12: travel | H12: 11 | I12: 14 | J12: 7 | K12: 15
A13: 3 | B13: 3 | C13: 3 | D13: 3 | G13: hats | H13: 31 | I13: 39 | J13: 14 | K13: 10
A14: 3 | B14: 5 | C14: 3 | D14: 3
A15: 3 | B15: 4 | C15: 3 | D15: 5
A16: 4 | B16: 3 | C16: 3 | D16: 5
A17: 3 | B17: 3 | C17: 3 | D17: 3
A18: 3 | B18: 3 | C18: 3 | D18: 3
A19: 3 | B19: 2 | C19: 5 | D19: 5
A20: 3 | B20: 2 | C20: 5 | D20: 5
A21: 3 | B21: 5 | C21: 4 | D21: 3
A22: 3 | B22: 3 | C22: 4 | D22: 6
A23: 3 | B23: 3 | C23: 5 | D23: 6
A24: 3 | B24: 3 | C24: 5 | D24: 6
A25: 2 | B25: 3 | C25: 5 | D25: 3
... A43: 3 | B43: 3 | C43: 4 | D43: 3
A44: 3 | B44: 3 | D44: 3
A45: 2 | B45: 3 | D45: 3
A46: 3 | B46: 3 | D46: 3
A47: 3 | B47: 3 | D47: 3
A48: 3 | B48: 3 | D48: 5
A49: 3 | B49: 3 | D49: 6
A50: 5 | B50: 3 | D50: 3
A51: 3 | B51: 3 | D51: 3
A52: 3 | B52: 3 | D52: 2
A53: 3 | B53: 3 | D53: 3
A54: 3 | B54: 3 | D54: 5
A55: 3 | B55: 3 | D55: 3
... A76: 6 | B76: 6 | D76: 6
B77: 6 | D77: 3
...

Sheet 1967
A1: January | B1: April | C1: July | D1: October | G1: parfumes: | H1: 1 | I1: 3 | J1: 1 | K1: 12 | M1: small luxury
A2: 3 | B2: 3 | C2: 3 | D2: 2 | G2: cosmetics | H2: 8 | I2: 15 | J2: 2 | K2: 33 | M2: =SUM(H1:K6) -> 152
A3: 2 | B3: 2 | C3: 1 | D3: 2 | G3: lipstick | I3: 14 | J3: 10 | K3: 25
A4: 2 | B4: 3 | C4: 1 | D4: 6 | G4: lotions, skin care, hand creams | I4: 5 | J4: 2 | K4: 18
A5: 3 | B5: 3 | C5: 2 | D5: 3 | G5: nail polist, | H5: 1 | I5: 1 | K5: 1
A6: 2 | B6: 1 | C6: 2 | D6: 2 | G6: candles
A7: 2 | B7: 3 | C7: 1 | D7: 3
A8: 3 | B8: 5 | C8: 6 | D8: 5 | G8: bags | H8: 5 | I8: 2 | J8: 1 | K8: 38 | M8: high luxury
A9: 2 | B9: 2 | C9: 2 | D9: 3 | G9: watches | H9: 1 | I9: 1 | M9: =SUM(H8:K13) -> 319
A10: 2 | B10: 2 | C10: 2 | D10: 3 | G10: dining
A11: 1 | B11: 5 | C11: 6 | D11: 1 | G11: jewellery | H11: 25 | I11: 62 | J11: 37 | K11: 62
A12: 3 | B12: 6 | C12: 2 | D12: 6 | G12: travel | H12: 2 | I12: 8 | K12: 4
A13: 3 | B13: 5 | C13: 1 | D13: 6 | G13: hats | H13: 18 | I13: 16 | J13: 5 | K13: 32
A14: 3 | B14: 6 | C14: 1 | D14: 6
A15: 3 | B15: 5 | C15: 1 | D15: 2
A16: 3 | B16: 3 | C16: 1 | D16: 2
A17: 4 | B17: 6 | C17: 6 | D17: 3
A18: 2 | B18: 3 | C18: 1 | D18: 1
A19: 3 | B19: 3 | C19: 3 | D19: 2
A20: 3 | B20: 6 | C20: 2 | D20: 3
A21: 3 | B21: 6 | C21: 2 | D21: 6
A22: 5 | B22: 6 | C22: 1 | D22: 2
A23: 3 | B23: 3 | C23: 2 | D23: 1
A24: 1 | B24: 3 | C24: 3 | D24: 3
A25: 1 | B25: 2 | C25: 2 | D25: 2
... A53: 3 | B53: 1 | C53: 6 | D53: 3
A54: 2 | B54: 1 | D54: 4
A55: 1 | B55: 1 | D55: 3
A56: 1 | B56: 1 | D56: 2
A57: 3 | B57: 2 | D57: 3
A58: 3 | B58: 2 | D58: 4
A59: 3 | B59: 2 | D59: 2
A60: 2 | B60: 1 | D60: 3
A61: 3 | B61: 2 | D61: 3
A62: 1 | B62: 6 | D62: 2
A63: 2 | B63: 2 | D63: 6
A64: 4 | B64: 3 | D64: 5
A65: 1 | B65: 2 | D65: 3
... A70: 2 | B70: 2 | D70: 5
B71: 1 | D71: 6
...

Sheet 1968
A1: January | B1: April | C1: July | D1: October | G1: parfumes: | H1: 2 | I1: 9 | J1: 3 | K1: 16 | M1: small luxury
A2: 2 | B2: 2 | C2: 3 | D2: 3 | G2: cosmetics | H2: 18 | I2: 23 | J2: 5 | K2: 17 | M2: =SUM(H1:K6) -> 171
A3: 2 | B3: 2 | C3: 2 | D3: 3 | G3: lipstick | H3: 3 | I3: 11 | K3: 22
A4: 2 | B4: 2 | C4: 2 | D4: 5 | G4: lotions, skin care, hand creams | I4: 8 | J4: 2 | K4: 23
A5: 1 | B5: 3 | C5: 3 | D5: 3 | G5: nail polist, | J5: 2 | K5: 7
A6: 2 | B6: 2 | C6: 2 | D6: 6 | G6: candles
A7: 3 | B7: 2 | C7: 3 | D7: 6
A8: 3 | B8: 4 | C8: 2 | D8: 6 | G8: bags | I8: 15 | K8: 10 | M8: high luxury
A9: 1 | B9: 6 | C9: 2 | D9: 3 | G9: watches | K9: 2 | M9: =SUM(H8:K13) -> 247
A10: 3 | B10: 3 | C10: 6 | D10: 3 | G10: dining
A11: 2 | B11: 3 | C11: 3 | D11: 3 | G11: jewellery | H11: 35 | I11: 56 | J11: 11 | K11: 25
A12: 2 | B12: 4 | C12: 1 | D12: 6 | G12: travel
A13: 2 | B13: 3 | C13: 1 | D13: 3 | G13: hats | H13: 18 | I13: 32 | J13: 13 | K13: 30
A14: 1 | B14: 3 | C14: 4 | D14: 3
A15: 1 | B15: 3 | C15: 4 | D15: 3
A16: 1 | B16: 3 | C16: 4 | D16: 3
A17: 1 | B17: 2 | C17: 4 | D17: 1
A18: 1 | B18: 1 | C18: 3 | D18: 2
A19: 1 | B19: 2 | C19: 4 | D19: 3
A20: 1 | B20: 3 | C20: 4 | D20: 3
A21: 1 | B21: 4 | C21: 3 | D21: 1
A22: 3 | B22: 2 | C22: 3 | D22: 1
A23: 2 | B23: 2 | C23: 3 | D23: 1
A24: 1 | B24: 2 | C24: 2 | D24: 2
A25: 2 | B25: 2 | C25: 1 | D25: 3
... A51: 3 | B51: 3 | C51: 1 | D51: 1
A52: 2 | B52: 2 | D52: 4
A53: 2 | B53: 2 | D53: 4
A54: 2 | B54: 3 | D54: 4
A55: 5 | B55: 3 | D55: 4
A56: 6 | B56: 3 | D56: 4
A57: 1 | B57: 2 | D57: 5
A58: 2 | B58: 2 | D58: 2
A59: 2 | B59: 3 | D59: 5
A60: 2 | B60: 3 | D60: 5
A61: 2 | B61: 2 | D61: 3
A62: 1 | B62: 3 | D62: 2
A63: 2 | B63: 1 | D63: 2
... A103: 6 | B103: 2 | D103: 6
B104: 6 | D104: 6
...

Sheet 1969
A1: January | B1: April | C1: July | D1: October | G1: parfumes: | H1: 3 | I1: 19 | J1: 4 | K1: 5 | M1: small luxury
A2: 2 | B2: 6 | C2: 2 | D2: 2 | G2: cosmetics | H2: 9 | I2: 6 | J2: 6 | K2: 42 | M2: =SUM(H1:K6) -> 174
A3: 2 | B3: 3 | C3: 6 | D3: 2 | G3: lipstick | I3: 12
A4: 3 | B4: 3 | C4: 2 | D4: 2 | G4: lotions, skin care, hand creams | I4: 35 | K4: 22
A5: 2 | B5: 2 | C5: 6 | D5: 2 | G5: nail polist, | I5: 7 | J5: 3 | K5: 1
A6: 6 | B6: 6 | C6: 1 | D6: 2 | G6: candles
A7: 3 | B7: 6 | C7: 2 | D7: 6
A8: 2 | B8: 6 | C8: 2 | D8: 2 | G8: bags | H8: 6 | I8: 12 | J8: 1 | K8: 2 | M8: high luxury
A9: 2 | B9: 3 | C9: 3 | D9: 3 | G9: watches | K9: 1 | M9: =SUM(H8:K13) -> 228
A10: 2 | B10: 3 | C10: 3 | D10: 2 | G10: dining
A11: 6 | B11: 3 | C11: 5 | D11: 5 | G11: jewellery | H11: 36 | I11: 45 | J11: 11 | K11: 25
A12: 6 | B12: 2 | C12: 3 | D12: 2 | G12: travel
A13: 3 | B13: 2 | C13: 3 | D13: 6 | G13: hats | H13: 23 | I13: 17 | J13: 27 | K13: 22
A14: 2 | B14: 3 | C14: 3 | D14: 3
A15: 2 | B15: 3 | C15: 3 | D15: 5
A16: 5 | B16: 2 | C16: 2 | D16: 2
A17: 3 | B17: 2 | C17: 2 | D17: 2
A18: 3 | B18: 2 | C18: 1 | D18: 4
A19: 3 | B19: 2 | C19: 6 | D19: 2
A20: 2 | B20: 2 | C20: 6 | D20: 2
A21: 2 | B21: 2 | C21: 4 | D21: 6
A22: 2 | B22: 5 | C22: 2 | D22: 3
A23: 2 | B23: 5 | C23: 2 | D23: 3
A24: 2 | B24: 3 | C24: 5 | D24: 6
A25: 2 | B25: 2 | C25: 2 | D25: 2
... A77: 2 | B77: 1 | C77: 6 | D77: 4
A78: 2 | B78: 6 | D78: 3
A79: 2 | B79: 2 | D79: 3
A80: 2 | B80: 3 | D80: 3
A81: 2 | B81: 3 | D81: 2
A82: 3 | B82: 1 | D82: 2
A83: 2 | B83: 2 | D83: 1
A84: 2 | B84: 2 | D84: 2
A85: 2 | B85: 2 | D85: 2
A86: 2 | B86: 3 | D86: 2
A87: 2 | B87: 3 | D87: 2
A88: 2 | B88: 2 | D88: 2
A89: 2 | B89: 3 | D89: 1
... A102: 6 | B102: 2 | D102: 1
B103: 6 | D103: 6
...

Sheet 1970
A1: January | B1: April | C1: July | D1: October | G1: parfumes: | H1: 5 | I1: 21 | K1: 6 | M1: small luxury
A2: 2 | B2: 2 | C2: 3 | D2: 6 | G2: cosmetics | H2: 19 | I2: 32 | J2: 25 | K2: 2 | M2: =SUM(H1:K6) -> 195
A3: 2 | B3: 3 | C3: 4 | D3: 4 | G3: lipstick | I3: 8 | J3: 5 | K3: 27
A4: 2 | B4: 2 | C4: 4 | D4: 4 | G4: lotions, skin care, hand creams | H4: 9 | I4: 8 | J4: 1 | K4: 20
A5: 2 | B5: 4 | C5: 3 | D5: 4 | G5: nail polist, | I5: 7
A6: 2 | B6: 2 | C6: 4 | D6: 4 | G6: candles
A7: 2 | B7: 2 | C7: 4 | D7: 4
A8: 5 | B8: 2 | C8: 4 | D8: 3 | G8: bags | H8: 6 | J8: 1 | K8: 2 | M8: high luxury
A9: 3 | B9: 2 | C9: 4 | D9: 5 | G9: watches | K9: 2 | M9: =SUM(H8:K13) -> 161
A10: 5 | B10: 2 | C10: 4 | D10: 4 | G10: dining
A11: 2 | B11: 6 | C11: 5 | D11: 4 | G11: jewellery | H11: 16 | I11: 30 | J11: 25 | K11: 11
A12: 5 | B12: 6 | C12: 4 | D12: 6 | G12: travel
A13: 1 | B13: 2 | C13: 5 | D13: 3 | G13: hats | H13: 6 | I13: 17 | J13: 20 | K13: 25
A14: 1 | B14: 2 | C14: 5 | D14: 3
A15: 6 | B15: 1 | C15: 3 | D15: 3
A16: 6 | B16: 2 | C16: 6 | D16: 4
A17: 2 | B17: 2 | C17: 6 | D17: 2 | G17: more pickily defining what is a hat, not a skarf, not a jacket kapucni.
A18: 2 | B18: 2 | C18: 2 | D18: 1
A19: 2 | B19: 2 | C19: 1 | D19: 4 | G19: varying length of clothing do not matter in the sense of administration of hemline, uncategorized
A20: 1 | B20: 2 | C20: 2 | D20: 5
A21: 2 | B21: 2 | C21: 4 | D21: 4
A22: 2 | B22: 2 | C22: 4 | D22: 5
A23: 6 | B23: 2 | C23: 6 | D23: 1
A24: 3 | B24: 2 | C24: 3 | D24: 4
A25: 3 | B25: 2 | C25: 4 | D25: 5
A26: 2 | B26: 1 | C26: 4 | D26: 5
A27: 1 | B27: 1 | C27: 4 | D27: 4
A28: 5 | B28: 2 | C28: 5 | D28: 5
A29: 2 | B29: 6 | C29: 5 | D29: 5
A30: 1 | B30: 5 | C30: 6 | D30: 3
A31: 3 | B31: 2 | C31: 4 | D31: 3
... A69: 2 | B69: 2 | C69: 5 | D69: 3
A70: 4 | B70: 4 | D70: 3
A71: 5 | B71: 4 | D71: 4
A72: 6 | B72: 4 | D72: 4
A73: 2 | B73: 4 | D73: 2
A74: 5 | B74: 5 | D74: 4
A75: 4 | B75: 4 | D75: 5
A76: 2 | B76: 4 | D76: 4
A77: 2 | B77: 4 | D77: 6
...

Sheet 1971
A1: January | B1: April | C1: July | D1: October | G1: parfumes: | I1: 5 | K1: 4 | M1: small luxury
A2: 3 | B2: 4 | C2: 6 | D2: 3 | G2: cosmetics | H2: 7 | I2: 16 | J2: 6 | K2: 26 | M2: =SUM(H1:K6) -> 150
A3: 3 | B3: 6 | C3: 3 | D3: 3 | G3: lipstick | I3: 16 | K3: 17
A4: 3 | B4: 5 | C4: 3 | D4: 4 | G4: lotions, skin care, hand creams | H4: 8 | I4: 21 | J4: 4 | K4: 15
A5: 3 | B5: 4 | C5: 4 | D5: 3 | G5: nail polist, | J5: 5
A6: 3 | B6: 5 | C6: 5 | D6: 5 | G6: candles
A7: 4 | B7: 4 | C7: 4 | D7: 3
A8: 6 | B8: 5 | C8: 4 | D8: 3 | G8: bags | H8: 4 | I8: 1 | J8: 2 | K8: 1 | M8: high luxury
A9: 3 | B9: 3 | C9: 1 | D9: 3 | G9: watches | H9: 6 | I9: 1 | M9: =SUM(H8:K13) -> 113
A10: 3 | B10: 3 | C10: 1 | D10: 6 | G10: dining
A11: 4 | B11: 5 | C11: 3 | D11: 4 | G11: jewellery | H11: 7 | I11: 12 | K11: 7
A12: 5 | B12: 3 | C12: 6 | D12: 3 | G12: travel
A13: 4 | B13: 3 | C13: 6 | D13: 5 | G13: hats | H13: 19 | I13: 9 | J13: 16 | K13: 28
A14: 5 | B14: 3 | C14: 3 | D14: 4
A15: 1 | B15: 4 | C15: 3 | D15: 4
A16: 3 | B16: 5 | C16: 3 | D16: 4 | G16: mid monthly issues were introduced making an issues much shorter. Aka. Less data can be gathered
A17: 4 | B17: 6 | C17: 2 | D17: 5
A18: 5 | B18: 6 | C18: 4 | D18: 4
A19: 5 | B19: 3 | C19: 3 | D19: 6
A20: 6 | B20: 6 | C20: 4 | D20: 6
A21: 6 | B21: 5 | C21: 3 | D21: 5
A22: 4 | B22: 6 | C22: 6 | D22: 6
A23: 5 | B23: 6 | C23: 4 | D23: 2
A24: 4 | B24: 2 | C24: 1 | D24: 2
A25: 5 | B25: 2 | C25: 1 | D25: 4
A26: 4 | B26: 5 | C26: 4 | D26: 5
A27: 4 | B27: 5 | C27: 3 | D27: 4
A28: 4 | B28: 5 | C28: 3 | D28: 4
... A38: 5 | B38: 1 | C38: 6 | D38: 5
A39: 2 | B39: 4 | D39: 5
A40: 3 | B40: 4 | D40: 5
A41: 1 | B41: 5 | D41: 4
A42: 5 | B42: 6 | D42: 2
A43: 5 | B43: 4 | D43: 4
A44: 5 | B44: 4 | D44: 4
A45: 4 | B45: 3 | D45: 5
A46: 4 | B46: 4 | D46: 6
A47: 3 | B47: 4 | D47: 3
A48: 3 | B48: 1 | D48: 5
A49: 4 | B49: 3 | D49: 3
...

Sheet 1972
A1: January | B1: April | C1: July | D1: October | G1: parfumes: | H1: 1 | I1: 10 | J1: 2 | K1: 10 | M1: small luxury
A2: 2 | B2: 5 | C2: 6 | D2: 3 | G2: cosmetics | H2: 5 | I2: 17 | J2: 10 | K2: 19 | M2: =SUM(H1:K6) -> 192
A3: 3 | B3: 3 | C3: 3 | D3: 3 | G3: lipstick | H3: 7 | I3: 25 | J3: 15 | K3: 15
A4: 5 | B4: 5 | C4: 3 | D4: 5 | G4: lotions, skin care, hand creams | H4: 2 | I4: 19 | J4: 4 | K4: 20
A5: 3 | B5: 5 | C5: 5 | D5: 3 | G5: nail polist, | I5: 5 | J5: 3 | K5: 2
A6: 3 | B6: 5 | C6: 3 | D6: 6 | G6: candles | I6: 1
A7: 3 | B7: 5 | C7: 5 | D7: 4
A8: 3 | B8: 5 | C8: 2 | D8: 6 | G8: bags | H8: 6 | I8: 3 | J8: 9 | K8: 3 | M8: high luxury
A9: 3 | B9: 5 | C9: 2 | D9: 3 | G9: watches | I9: 6 | J9: 2 | K9: 2 | M9: =SUM(H8:K13) -> 259
A10: 3 | B10: 5 | C10: 5 | D10: 5 | G10: dining | H10: 4 | I10: 2 | J10: 1 | K10: 7
A11: 3 | B11: 3 | C11: 3 | D11: 5 | G11: jewellery | H11: 24 | I11: 44 | J11: 27 | K11: 26
A12: 3 | B12: 5 | C12: 2 | D12: 3 | G12: travel | H12: 8 | I12: 3 | J12: 1 | K12: 6
A13: 5 | B13: 5 | C13: 3 | D13: 5 | G13: hats | H13: 10 | I13: 23 | J13: 23 | K13: 19
A14: 4 | B14: 5 | C14: 5 | D14: 3
A15: 5 | B15: 5 | C15: 3 | D15: 5
A16: 5 | B16: 5 | C16: 3 | D16: 3
A17: 3 | B17: 5 | C17: 3 | D17: 5
A18: 3 | B18: 5 | C18: 3 | D18: 2
A19: 5 | B19: 5 | C19: 3 | D19: 5
A20: 5 | B20: 3 | C20: 4 | D20: 5
A21: 5 | B21: 3 | C21: 3 | D21: 5
A22: 3 | B22: 5 | C22: 3 | D22: 5
A23: 5 | B23: 6 | C23: 6 | D23: 5
A24: 5 | B24: 6 | C24: 6 | D24: 6
A25: 3 | B25: 3 | C25: 3 | D25: 6
... A29: 2 | B29: 3 | C29: 5 | D29: 5
A30: 2 | B30: 3 | D30: 5
A31: 4 | B31: 3
A32: 1 | B32: 3
A33: 1 | B33: 3
A34: 4 | B34: 5
A35: 4 | B35: 5
A36: 4 | B36: 5
A37: 4 | B37: 3
A38: 5 | B38: 3
A39: 5 | B39: 5
A40: 4 | B40: 3
A41: 4 | B41: 3
B42: 6
B43: 5
...

Sheet 1973
A1: January | B1: April | C1: July | D1: October | G1: parfumes: | H1: 4 | I1: 9 | J1: 3 | K1: 19 | M1: small luxury
A2: 3 | B2: 3 | C2: 5 | D2: 4 | G2: cosmetics | H2: 7 | I2: 16 | J2: 5 | K2: 17 | M2: =SUM(H1:K6) -> 213
A3: 6 | B3: 5 | C3: 3 | D3: 3 | G3: lipstick | H3: 9 | I3: 6 | J3: 13 | K3: 18
A4: 3 | B4: 3 | C4: 3 | D4: 5 | G4: lotions, skin care, hand creams | H4: 8 | I4: 31 | J4: 6 | K4: 22
A5: 3 | B5: 5 | C5: 2 | D5: 3 | G5: nail polist, | H5: 7 | I5: 8 | K5: 4
A6: 5 | B6: 3 | C6: 3 | D6: 5 | G6: candles | K6: 1
A7: 3 | B7: 5 | C7: 5 | D7: 5
A8: 3 | B8: 5 | C8: 5 | D8: 6 | G8: bags | H8: 8 | I8: 21 | J8: 1 | K8: 7 | M8: high luxury
A9: 3 | B9: 3 | C9: 5 | D9: 3 | G9: watches | H9: 1 | I9: 10 | K9: 1 | M9: =SUM(H8:K13) -> 328
A10: 3 | B10: 6 | C10: 5 | D10: 3 | G10: dining | H10: 5 | I10: 11 | J10: 2 | K10: 8
A11: 4 | B11: 3 | C11: 3 | D11: 3 | G11: jewellery | H11: 35 | I11: 52 | J11: 23 | K11: 50
A12: 3 | B12: 3 | C12: 3 | D12: 3 | G12: travel | H12: 13 | I12: 6 | J12: 2 | K12: 3
A13: 4 | B13: 6 | C13: 3 | D13: 3 | G13: hats | H13: 23 | I13: 19 | J13: 12 | K13: 15
A14: 3 | B14: 6 | C14: 3 | D14: 5
A15: 5 | B15: 3 | C15: 3 | D15: 3
A16: 5 | B16: 3 | C16: 4 | D16: 3
A17: 5 | B17: 3 | C17: 3 | D17: 5
A18: 3 | B18: 3 | C18: 2 | D18: 5
A19: 5 | B19: 3 | C19: 2 | D19: 5
A20: 3 | B20: 5 | C20: 3 | D20: 3
A21: 5 | B21: 5 | C21: 5 | D21: 3
A22: 3 | B22: 3 | C22: 3 | D22: 3
A23: 3 | B23: 5 | C23: 3 | D23: 3
A24: 3 | B24: 6 | C24: 3 | D24: 3
A25: 3 | B25: 3 | C25: 3 | D25: 2
... A28: 6 | B28: 5 | C28: 4 | D28: 4
A29: 5 | B29: 3 | D29: 5
A30: 2 | B30: 5 | D30: 5
A31: 2 | B31: 6 | D31: 6
A32: 2 | B32: 3 | D32: 5
A33: 2 | B33: 3 | D33: 5
A34: 1 | B34: 5 | D34: 6
A35: 2 | B35: 3 | D35: 3
A36: 6 | B36: 3 | D36: 4
A37: 3 | B37: 3 | D37: 4
A38: 3 | B38: 5 | D38: 4
A39: 5 | B39: 5 | D39: 4
A40: 5 | B40: 3 | D40: 5
... A48: 3 | B48: 6 | D48: 6
A49: 3 | B49: 6
...

Sheet 1974
A1: January | B1: April | C1: July | D1: October | G1: parfumes: | I1: 5 | J1: 1 | K1: 14 | M1: small luxury
A2: 3 | B2: 5 | C2: 3 | D2: 4 | G2: cosmetics | H2: 4 | I2: 13 | J2: 13 | K2: 15 | M2: =SUM(H1:K6) -> 169
A3: 3 | B3: 3 | C3: 3 | D3: 3 | G3: lipstick | H3: 4 | I3: 10 | J3: 16 | K3: 18
A4: 6 | B4: 3 | C4: 6 | D4: 3 | G4: lotions, skin care, hand creams | H4: 9 | I4: 10 | J4: 1 | K4: 19
A5: 6 | B5: 4 | C5: 5 | D5: 3 | G5: nail polist, | I5: 2 | J5: 5 | K5: 10
A6: 2 | B6: 5 | C6: 3 | D6: 3 | G6: candles
A7: 2 | B7: 4 | C7: 3 | D7: 6
A8: 3 | B8: 5 | C8: 3 | D8: 6 | G8: bags | H8: 8 | I8: 17 | J8: 6 | K8: 15 | M8: high luxury
A9: 3 | B9: 6 | C9: 3 | D9: 3 | G9: watches | H9: 1 | I9: 10 | K9: 10 | M9: =SUM(H8:K13) -> 324
A10: 3 | B10: 5 | C10: 5 | D10: 3 | G10: dining | I10: 4 | J10: 2 | K10: 8
A11: 3 | B11: 3 | C11: 5 | D11: 3 | G11: jewellery | H11: 25 | I11: 50 | J11: 27 | K11: 49
A12: 3 | B12: 6 | C12: 3 | D12: 5 | G12: travel | H12: 7 | I12: 2 | J12: 4 | K12: 8
A13: 5 | B13: 3 | C13: 3 | D13: 4 | G13: hats | H13: 15 | I13: 31 | J13: 10 | K13: 15
A14: 3 | B14: 3 | C14: 3 | D14: 6
A15: 3 | B15: 3 | C15: 4 | D15: 3
A16: 2 | B16: 6 | C16: 3 | D16: 3
A17: 2 | B17: 6 | C17: 3 | D17: 3
A18: 3 | B18: 6 | C18: 3 | D18: 3
A19: 3 | B19: 6 | C19: 3 | D19: 3
A20: 3 | B20: 5 | C20: 4 | D20: 4
A21: 5 | B21: 5 | C21: 3 | D21: 4
A22: 3 | B22: 5 | C22: 6 | D22: 3
A23: 3 | B23: 3 | C23: 6 | D23: 5
A24: 5 | B24: 3 | C24: 6 | D24: 5
A25: 3 | B25: 3 | C25: 5 | D25: 5
A26: 3 | B26: 5 | D26: 6
A27: 3 | B27: 3 | D27: 6
A28: 3 | B28: 6 | D28: 6
A29: 3 | B29: 6 | D29: 6
A30: 4 | B30: 3 | D30: 3
A31: 5 | B31: 3 | D31: 6
A32: 3 | B32: 5 | D32: 3
A33: 3 | B33: 3 | D33: 3
A34: 6 | B34: 3 | D34: 4
A35: 3 | B35: 3 | D35: 6
A36: 3 | B36: 3 | D36: 6
A37: 4 | B37: 3 | D37: 5
... A49: 3 | B49: 6 | D49: 5
A50: 4 | D50: 5
A51: 5 | D51: 5
...

Sheet 1975
A1: January | B1: April | C1: July | D1: October | G1: parfumes: | H1: 3 | I1: 12 | J1: 1 | K1: 17 | M1: small luxury
A2: 4 | B2: 3 | C2: 6 | D2: 6 | G2: cosmetics | H2: 13 | I2: 20 | J2: 30 | K2: 32 | M2: =SUM(H1:K6) -> 189
A3: 4 | B3: 4 | C3: 5 | D3: 5 | G3: lipstick | H3: 3 | I3: 12 | K3: 15
A4: 5 | B4: 5 | C4: 4 | D4: 6 | G4: lotions, skin care, hand creams | H4: 3 | I4: 4 | K4: 8
A5: 6 | B5: 5 | C5: 4 | D5: 4 | G5: nail polist, | H5: 3 | I5: 3 | J5: 2 | K5: 8
A6: 5 | B6: 6 | C6: 4 | D6: 5 | G6: candles
A7: 4 | B7: 6 | C7: 4 | D7: 4
A8: 4 | B8: 4 | C8: 4 | D8: 4 | G8: bags | H8: 11 | I8: 32 | J8: 14 | K8: 12 | M8: high luxury
A9: 4 | B9: 4 | C9: 4 | D9: 4 | G9: watches | H9: 6 | I9: 10 | K9: 8 | M9: =SUM(H8:K13) -> 307
A10: 4 | B10: 4 | C10: 4 | D10: 6 | G10: dining
A11: 6 | B11: 4 | C11: 4 | D11: 6 | G11: jewellery | H11: 10 | I11: 13 | J11: 15 | K11: 43
A12: 1 | B12: 4 | C12: 3 | D12: 4 | G12: travel
A13: 5 | B13: 6 | C13: 3 | D13: 4 | G13: hats | H13: 47 | I13: 27 | J13: 8 | K13: 51
A14: 6 | B14: 4 | C14: 5 | D14: 4
A15: 2 | B15: 4 | C15: 6 | D15: 5
A16: 2 | B16: 4 | C16: 5 | D16: 4
A17: 3 | B17: 4 | C17: 6 | D17: 3
A18: 3 | B18: 4 | C18: 4 | D18: 4
A19: 3 | B19: 3 | C19: 3 | D19: 6
A20: 6 | B20: 3 | C20: 3 | D20: 5
A21: 3 | B21: 1 | C21: 4 | D21: 3
A22: 3 | B22: 1 | C22: 6 | D22: 4
A23: 1 | B23: 3 | C23: 4 | D23: 5
A24: 6 | B24: 6 | C24: 4 | D24: 4
A25: 4 | B25: 4 | C25: 4 | D25: 4
... A45: 4 | B45: 4 | C45: 4 | D45: 6
A46: 4 | B46: 2 | D46: 4
A47: 5 | B47: 6 | D47: 4
A48: 5 | B48: 3 | D48: 5
A49: 5 | B49: 3 | D49: 4
A50: 5 | B50: 3 | D50: 6
A51: 4 | B51: 3 | D51: 4
A52: 5 | B52: 6 | D52: 4
A53: 3 | B53: 4 | D53: 4
A54: 3 | B54: 5 | D54: 4
A55: 5 | B55: 4 | D55: 4
A56: 5 | B56: 3 | D56: 6
A57: 6 | B57: 3 | D57: 4
... A78: 4 | B78: 4 | D78: 4
A79: 5 | B79: 4
...

Sheet 1976
A1: January | B1: April | C1: July | D1: October | G1: parfumes: | H1: 3 | I1: 19 | J1: 2 | K1: 16 | M1: small luxury
A2: 6 | B2: 4 | C2: 5 | D2: 5 | G2: cosmetics | H2: 10 | I2: 25 | J2: 14 | K2: 60 | M2: =SUM(H1:K6) -> 276
A3: 4 | B3: 5 | C3: 5 | D3: 4 | G3: lipstick | I3: 3 | J3: 8 | K3: 10
A4: 4 | B4: 3 | C4: 4 | D4: 6 | G4: lotions, skin care, hand creams | H4: 6 | I4: 28 | J4: 20 | K4: 20
A5: 5 | B5: 5 | C5: 5 | D5: 6 | G5: nail polist, | H5: 3 | I5: 14 | J5: 12 | K5: 3
A6: 4 | B6: 6 | C6: 6 | D6: 6 | G6: candles
A7: 4 | B7: 4 | C7: 5 | D7: 6
A8: 3 | B8: 4 | C8: 5 | D8: 4 | G8: bags | H8: 3 | I8: 25 | J8: 6 | K8: 3 | M8: high luxury
A9: 4 | B9: 6 | C9: 4 | D9: 4 | G9: watches | H9: 7 | I9: 5 | K9: 19 | M9: =SUM(H8:K13) -> 211
A10: 6 | B10: 6 | C10: 4 | D10: 5 | G10: dining
A11: 5 | B11: 5 | C11: 4 | D11: 4 | G11: jewellery | H11: 17 | I11: 41 | J11: 8 | K11: 20
A12: 5 | B12: 1 | C12: 5 | D12: 5 | G12: travel | H12: 1 | I12: 2
A13: 5 | B13: 4 | C13: 3 | D13: 6 | G13: hats | H13: 17 | I13: 14 | J13: 6 | K13: 17
A14: 5 | B14: 5 | C14: 5 | D14: 5
A15: 3 | B15: 6 | C15: 4 | D15: 4
A16: 5 | B16: 4 | C16: 5 | D16: 4
A17: 5 | B17: 4 | C17: 6 | D17: 4
A18: 3 | B18: 6 | C18: 4 | D18: 4
A19: 1 | B19: 4 | C19: 5 | D19: 4
A20: 3 | B20: 5 | C20: 4 | D20: 6
A21: 4 | B21: 5 | C21: 4 | D21: 6
A22: 3 | B22: 6 | C22: 4 | D22: 4
A23: 1 | B23: 2 | C23: 3 | D23: 4
A24: 1 | B24: 2 | C24: 1 | D24: 4
A25: 2 | B25: 5 | C25: 4 | D25: 4
... A46: 4 | B46: 1 | C46: 4 | D46: 6
A47: 4 | B47: 1 | D47: 1
A48: 5 | B48: 4 | D48: 6
A49: 3 | B49: 6 | D49: 5
A50: 3 | B50: 5 | D50: 5
A51: 3 | B51: 4 | D51: 6
B52: 6 | D52: 6
B53: 3 | D53: 6
B54: 5 | D54: 5
B55: 5 | D55: 5
B56: 4 | D56: 4
B57: 2 | D57: 4
B58: 4 | D58: 4
B59: 4 | D59: 4
B60: 5 | D60: 6
...

Sheet 1977
A1: January | B1: April | C1: July | D1: October | G1: parfumes: | H1: 3 | I1: 18 | J1: 4 | K1: 30 | M1: small luxury
A2: 4 | B2: 4 | C2: 4 | D2: 4 | G2: cosmetics | H2: 15 | I2: 49 | J2: 16 | K2: 34 | M2: =SUM(H1:K6) -> 359
A3: 6 | B3: 4 | C3: 2 | D3: 3 | G3: lipstick | H3: 6 | I3: 15 | J3: 5 | K3: 38
A4: 4 | B4: 3 | C4: 6 | D4: 4 | G4: lotions, skin care, hand creams | H4: 6 | I4: 20 | J4: 8 | K4: 27
A5: 2 | B5: 3 | C5: 4 | D5: 5 | G5: nail polist, | H5: 7 | I5: 39 | J5: 4 | K5: 15
A6: 6 | B6: 4 | C6: 4 | D6: 6 | G6: candles
A7: 3 | B7: 4 | C7: 6 | D7: 4
A8: 3 | B8: 3 | C8: 4 | D8: 6 | G8: bags | H8: 4 | I8: 44 | J8: 3 | K8: 23 | M8: high luxury
A9: 4 | B9: 1 | C9: 4 | D9: 4 | G9: watches | H9: 2 | I9: 9 | K9: 8 | M9: =SUM(H8:K13) -> 242
A10: 3 | B10: 1 | C10: 4 | D10: 1 | G10: dining
A11: 4 | B11: 4 | C11: 5 | D11: 4 | G11: jewellery | H11: 16 | I11: 22 | J11: 15 | K11: 51
A12: 4 | B12: 6 | C12: 4 | D12: 5 | G12: travel | K12: 2
A13: 5 | B13: 4 | C13: 3 | D13: 6 | G13: hats | H13: 16 | I13: 8 | J13: 5 | K13: 14
A14: 3 | B14: 3 | C14: 4 | D14: 6
A15: 5 | B15: 6 | C15: 4 | D15: 6
A16: 4 | B16: 6 | C16: 4 | D16: 5
A17: 4 | B17: 5 | C17: 4 | D17: 4
A18: 5 | B18: 4 | C18: 4 | D18: 4
A19: 6 | B19: 3 | C19: 5 | D19: 4
A20: 6 | B20: 3 | C20: 6 | D20: 6
A21: 6 | B21: 3 | C21: 5 | D21: 4
A22: 6 | B22: 3 | C22: 5 | D22: 6
A23: 6 | B23: 3 | C23: 5 | D23: 4
A24: 6 | B24: 5 | C24: 4 | D24: 4
A25: 6 | B25: 3 | C25: 4 | D25: 4
... A33: 2 | B33: 4 | C33: 1 | D33: 4
A34: 6 | C34: 1 | D34: 4
A35: 1 | C35: 1 | D35: 5
A36: 3 | C36: 4 | D36: 4
A37: 3 | C37: 4 | D37: 4
A38: 2 | C38: 4 | D38: 4
A39: 5 | C39: 4 | D39: 3
A40: 6 | C40: 4 | D40: 1
A41: 6 | C41: 5 | D41: 1
A42: 2 | D42: 4
A43: 6 | D43: 4
A44: 5 | D44: 6
A45: 4 | D45: 6
A46: 4 | D46: 6
A47: 5 | D47: 4
...

Sheet 1978
A1: January | B1: April | C1: July | D1: October | G1: parfumes: | H1: 3 | I1: 23 | J1: 5 | K1: 32 | M1: small luxury
A2: 4 | B2: 3 | C2: 5 | D2: 5 | G2: cosmetics | H2: 14 | I2: 36 | J2: 28 | K2: 32 | M2: =SUM(H1:K6) -> 316
A3: 5 | B3: 6 | C3: 4 | D3: 5 | G3: lipstick | H3: 5 | I3: 8 | J3: 2 | K3: 18
A4: 5 | B4: 5 | C4: 4 | D4: 5 | G4: lotions, skin care, hand creams | H4: 10 | I4: 27 | J4: 17 | K4: 30
A5: 4 | B5: 5 | C5: 4 | D5: 4 | G5: nail polist, | H5: 3 | I5: 12 | J5: 3 | K5: 8
A6: 4 | B6: 4 | C6: 4 | D6: 5 | G6: candles
A7: 4 | B7: 3 | C7: 4 | D7: 3
A8: 5 | B8: 4 | C8: 4 | D8: 4 | G8: bags | H8: 1 | I8: 2 | K8: 23 | M8: high luxury
A9: 4 | B9: 4 | C9: 4 | D9: 4 | G9: watches | H9: 1 | I9: 10 | J9: 3 | K9: 9 | M9: =SUM(H8:K13) -> 253
A10: 3 | B10: 6 | C10: 4 | D10: 4 | G10: dining
A11: 5 | B11: 4 | C11: 4 | D11: 4 | G11: jewellery | H11: 30 | I11: 7 | J11: 23 | K11: 35
A12: 5 | B12: 4 | C12: 5 | D12: 5 | G12: travel | H12: 1 | I12: 4
A13: 5 | B13: 4 | C13: 4 | D13: 5 | G13: hats | H13: 14 | I13: 7 | J13: 22 | K13: 61
A14: 5 | B14: 4 | C14: 6 | D14: 5
A15: 4 | B15: 5 | C15: 4 | D15: 5
A16: 4 | B16: 1 | C16: 4 | D16: 4
A17: 5 | B17: 1 | C17: 4 | D17: 4
A18: 4 | B18: 4 | C18: 4 | D18: 5
A19: 4 | B19: 4 | C19: 4 | D19: 3
A20: 5 | B20: 4 | C20: 4 | D20: 4
A21: 6 | B21: 3 | C21: 5 | D21: 5
A22: 5 | B22: 5 | C22: 4 | D22: 4
A23: 6 | B23: 5 | C23: 4 | D23: 4
A24: 4 | B24: 5 | C24: 4 | D24: 4
A25: 4 | B25: 4 | C25: 4 | D25: 4
A26: 4 | B26: 4 | C26: 4 | D26: 4
A27: 3 | B27: 4 | D27: 4
A28: 5 | B28: 6 | D28: 3
A29: 6 | B29: 4 | D29: 3
A30: 6 | B30: 5 | D30: 3
A31: 5 | B31: 2 | D31: 4
A32: 4 | B32: 5 | D32: 5
A33: 4 | B33: 4 | D33: 4
A34: 5 | B34: 4 | D34: 5
A35: 4 | B35: 6 | D35: 4
A36: 4 | B36: 4 | D36: 1
A37: 4 | B37: 4 | D37: 4
A38: 1 | B38: 5 | D38: 4
... A55: 5 | B55: 5 | D55: 4
A56: 4 | D56: 4
...

Sheet 1979
A1: January | B1: April | C1: July | D1: October | G1: parfumes: | H1: 4 | I1: 25 | J1: 3 | K1: 21 | M1: small luxury
A2: 4 | B2: 3 | C2: 5 | D2: 4 | G2: cosmetics | H2: 22 | I2: 30 | J2: 9 | K2: 52 | M2: =SUM(H1:K6) -> 321
A3: 4 | B3: 5 | C3: 3 | D3: 3 | G3: lipstick | H3: 1 | I3: 16 | J3: 20 | K3: 13
A4: 4 | B4: 5 | C4: 3 | D4: 6 | G4: lotions, skin care, hand creams | H4: 13 | I4: 10 | J4: 10 | K4: 30
A5: 4 | B5: 5 | C5: 4 | D5: 6 | G5: nail polist, | H5: 1 | I5: 17 | J5: 12 | K5: 12
A6: 4 | B6: 4 | C6: 4 | D6: 6 | G6: candles
A7: 4 | B7: 4 | C7: 4 | D7: 6
A8: 4 | B8: 4 | C8: 3 | D8: 3 | G8: bags | H8: 4 | I8: 8 | J8: 5 | K8: 22 | M8: high luxury
A9: 4 | B9: 4 | C9: 3 | D9: 4 | G9: watches | H9: 4 | I9: 16 | K9: 42 | M9: =SUM(H8:K13) -> 307
A10: 4 | B10: 5 | C10: 5 | D10: 4 | G10: dining
A11: 6 | B11: 4 | C11: 3 | D11: 6 | G11: jewellery | H11: 17 | I11: 27 | J11: 15 | K11: 32
A12: 5 | B12: 4 | C12: 3 | D12: 4 | G12: travel | J12: 16
A13: 4 | B13: 5 | C13: 3 | D13: 4 | G13: hats | H13: 21 | I13: 32 | J13: 13 | K13: 33
A14: 6 | B14: 5 | C14: 3 | D14: 5
A15: 6 | B15: 4 | C15: 3 | D15: 3
A16: 6 | B16: 4 | C16: 3 | D16: 5
A17: 5 | B17: 5 | C17: 3 | D17: 4
A18: 5 | B18: 3 | C18: 3 | D18: 5
A19: 4 | B19: 3 | C19: 4 | D19: 4
A20: 5 | B20: 5 | C20: 4 | D20: 5
A21: 3 | B21: 5 | C21: 3 | D21: 4
A22: 5 | B22: 3 | C22: 4 | D22: 4
A23: 1 | B23: 5 | C23: 3 | D23: 4
A24: 6 | B24: 4 | C24: 3 | D24: 5
A25: 3 | B25: 4 | C25: 3 | D25: 6
... A51: 3 | B51: 4 | C51: 3 | D51: 6
B52: 4 | D52: 4
B53: 3 | D53: 4
B54: 4 | D54: 3
B55: 4 | D55: 6
B56: 4 | D56: 6
D57: 6
D58: 6
D59: 6
D60: 3
D61: 3
D62: 3
D63: 3
D64: 3
D65: 3
...

Sheet 1980
A1: January | B1: April | C1: July | D1: October | G1: parfumes: | H1: 2 | I1: 13 | K1: 36 | M1: small luxury
A2: 4 | B2: 5 | C2: 3 | D2: 4 | G2: cosmetics | H2: 18 | I2: 34 | J2: 29 | K2: 41 | M2: =SUM(H1:K6) -> 355
A3: 4 | B3: 4 | C3: 3 | D3: 4 | G3: lipstick | H3: 22 | I3: 9 | J3: 15 | K3: 31
A4: 4 | B4: 3 | C4: 2 | D4: 5 | G4: lotions, skin care, hand creams | H4: 18 | I4: 20 | J4: 7 | K4: 23
A5: 4 | B5: 3 | C5: 4 | D5: 5 | G5: nail polist, | H5: 2 | I5: 8 | J5: 2 | K5: 25
A6: 3 | B6: 3 | C6: 3 | D6: 5 | G6: candles
A7: 4 | B7: 3 | C7: 2 | D7: 4
A8: 1 | B8: 5 | C8: 2 | D8: 3 | G8: bags | H8: 5 | I8: 1 | J8: 3 | K8: 5 | M8: high luxury
A9: 6 | B9: 4 | C9: 1 | D9: 5 | G9: watches | H9: 3 | I9: 8 | J9: 1 | K9: 16 | M9: =SUM(H8:K13) -> 218
A10: 5 | B10: 4 | C10: 3 | D10: 6 | G10: dining
A11: 4 | B11: 4 | C11: 4 | D11: 5 | G11: jewellery | H11: 17 | I11: 42 | J11: 6 | K11: 45
A12: 3 | B12: 4 | C12: 4 | D12: 3 | G12: travel | I12: 2
A13: 3 | B13: 6 | C13: 3 | D13: 5 | G13: hats | H13: 15 | I13: 10 | J13: 4 | K13: 35
A14: 4 | B14: 3 | C14: 3 | D14: 3
A15: 4 | B15: 4 | C15: 3 | D15: 3
A16: 3 | B16: 4 | C16: 3 | D16: 3
A17: 2 | B17: 1 | C17: 3 | D17: 4
A18: 3 | B18: 1 | C18: 3 | D18: 4
A19: 2 | B19: 1 | C19: 2 | D19: 3
A20: 4 | B20: 1 | C20: 6 | D20: 3
A21: 3 | B21: 2 | C21: 4 | D21: 5
A22: 3 | B22: 2 | C22: 3 | D22: 3
A23: 3 | B23: 3 | C23: 3 | D23: 3
A24: 4 | B24: 3 | C24: 3 | D24: 3
A25: 3 | B25: 5 | C25: 4 | D25: 3
... A31: 4 | B31: 2 | C31: 2 | D31: 5
B32: 3 | D32: 3
B33: 4 | D33: 3
B34: 3 | D34: 3
B35: 3 | D35: 3
B36: 3 | D36: 4
B37: 2 | D37: 4
B38: 3 | D38: 1
B39: 2 | D39: 4
B40: 2 | D40: 4
B41: 3 | D41: 4
B42: 3 | D42: 5
B43: 3 | D43: 6
B44: 2 | D44: 5
D45: 4
...

Sheet 1981
A1: January | B1: April | C1: July | D1: October | G1: parfumes: | H1: 2 | I1: 22 | J1: 6 | K1: 27 | M1: small luxury
A2: 1 | B2: 5 | C2: 4 | D2: 3 | G2: cosmetics | H2: 15 | I2: 31 | J2: 16 | K2: 62 | M2: =SUM(H1:K6) -> 347
A3: 4 | B3: 5 | C3: 3 | D3: 5 | G3: lipstick | H3: 20 | I3: 14 | J3: 5 | K3: 12
A4: 3 | B4: 6 | C4: 2 | D4: 5 | G4: lotions, skin care, hand creams | H4: 5 | I4: 32 | J4: 11 | K4: 35
A5: 4 | B5: 4 | C5: 3 | D5: 5 | G5: nail polist, | H5: 2 | I5: 15 | J5: 4 | K5: 11
A6: 4 | B6: 4 | C6: 5 | D6: 5 | G6: candles
A7: 3 | B7: 4 | C7: 3 | D7: 6
A8: 4 | B8: 6 | C8: 3 | D8: 5 | G8: bags | H8: 1 | I8: 42 | J8: 3 | K8: 43 | M8: high luxury
A9: 3 | B9: 5 | C9: 3 | D9: 5 | G9: watches | H9: 5 | I9: 17 | J9: 11 | K9: 14 | M9: =SUM(H8:K13) -> 435
A10: 3 | B10: 6 | C10: 3 | D10: 3 | G10: dining
A11: 3 | B11: 3 | C11: 3 | D11: 4 | G11: jewellery | H11: 15 | I11: 40 | J11: 26 | K11: 97
A12: 4 | B12: 3 | C12: 5 | D12: 3 | G12: travel | J12: 3 | K12: 5
A13: 4 | B13: 3 | C13: 5 | D13: 3 | G13: hats | H13: 20 | I13: 24 | J13: 10 | K13: 59
A14: 3 | B14: 4 | C14: 5 | D14: 3
A15: 3 | B15: 4 | C15: 5 | D15: 2
A16: 3 | B16: 4 | C16: 3 | D16: 3
A17: 4 | B17: 4 | C17: 4 | D17: 3
A18: 3 | B18: 4 | C18: 4 | D18: 3
A19: 3 | B19: 3 | C19: 5 | D19: 6
A20: 3 | B20: 2 | C20: 3 | D20: 2
A21: 2 | B21: 5 | C21: 3 | D21: 4
A22: 3 | B22: 5 | C22: 3 | D22: 4
A23: 3 | B23: 4 | C23: 5 | D23: 3
A24: 3 | B24: 4 | C24: 4 | D24: 4
A25: 3 | B25: 4 | C25: 4 | D25: 3
... A34: 3 | B34: 4 | C34: 4 | D34: 4
A35: 4 | B35: 4 | D35: 4
A36: 2 | B36: 3 | D36: 3
A37: 3 | B37: 3 | D37: 4
A38: 3 | B38: 3 | D38: 4
A39: 5 | B39: 3 | D39: 3
A40: 1 | B40: 2 | D40: 2
A41: 2 | B41: 2 | D41: 4
A42: 3 | B42: 3 | D42: 3
A43: 2 | B43: 3 | D43: 6
A44: 1 | B44: 2 | D44: 4
A45: 4 | B45: 2 | D45: 3
A46: 3 | B46: 3 | D46: 3
A47: 3 | B47: 2 | D47: 3
A48: 2 | D48: 3
...

Sheet 1982
A1: January | B1: April | C1: July | D1: October | G1: parfumes: | H1: 5 | I1: 17 | J1: 3 | K1: 28 | M1: small luxury
A2: 6 | B2: 2 | C2: 2 | D2: 4 | G2: cosmetics | H2: 25 | I2: 37 | J2: 20 | K2: 46 | M2: =SUM(H1:K6) -> 373
A3: 4 | B3: 5 | C3: 2 | D3: 4 | G3: lipstick | H3: 2 | I3: 9 | J3: 10 | K3: 23
A4: 4 | B4: 4 | C4: 3 | D4: 5 | G4: lotions, skin care, hand creams | H4: 28 | I4: 27 | J4: 16 | K4: 42
A5: 5 | B5: 3 | C5: 4 | D5: 5 | G5: nail polist, | H5: 9 | I5: 10 | J5: 1 | K5: 15
A6: 2 | B6: 3 | C6: 4 | D6: 4 | G6: candles
A7: 3 | B7: 3 | C7: 4 | D7: 6
A8: 3 | B8: 4 | C8: 4 | D8: 3 | G8: bags | H8: 14 | I8: 14 | J8: 4 | K8: 15 | M8: high luxury
A9: 3 | B9: 3 | C9: 3 | D9: 3 | G9: watches | H9: 2 | I9: 14 | J9: 2 | K9: 46 | M9: =SUM(H8:K13) -> 443
A10: 1 | B10: 2 | C10: 3 | D10: 3 | G10: dining
A11: 2 | B11: 1 | C11: 5 | D11: 5 | G11: jewellery | H11: 35 | I11: 51 | J11: 25 | K11: 75
A12: 3 | B12: 3 | C12: 5 | D12: 5 | G12: travel
A13: 2 | B13: 2 | C13: 3 | D13: 3 | G13: hats | H13: 23 | I13: 32 | J13: 30 | K13: 61
A14: 4 | B14: 2 | C14: 3 | D14: 4
A15: 4 | B15: 3 | C15: 1 | D15: 5
A16: 3 | B16: 4 | C16: 4 | D16: 3
A17: 3 | B17: 4 | C17: 6 | D17: 4
A18: 2 | B18: 4 | C18: 5 | D18: 4
A19: 3 | B19: 4 | C19: 5 | D19: 4
A20: 3 | B20: 3 | C20: 4 | D20: 2
A21: 2 | B21: 3 | C21: 5 | D21: 3
A22: 2 | B22: 3 | C22: 5 | D22: 3
A23: 4 | B23: 4 | C23: 3 | D23: 3
A24: 3 | B24: 4 | C24: 5 | D24: 5
A25: 4 | B25: 3 | C25: 5 | D25: 3
... A34: 5 | B34: 6 | C34: 3 | D34: 4
B35: 6 | C35: 2 | D35: 3
B36: 6 | C36: 3 | D36: 3
B37: 4 | C37: 3 | D37: 3
B38: 4 | C38: 3 | D38: 6
B39: 3 | C39: 3 | D39: 3
B40: 3 | C40: 6 | D40: 2
B41: 3 | C41: 4 | D41: 3
B42: 3 | C42: 3 | D42: 1
B43: 5 | C43: 3 | D43: 5
B44: 3 | C44: 4 | D44: 5
B45: 4 | C45: 3 | D45: 2
B46: 4 | C46: 2 | D46: 2
... B55: 1 | C55: 5 | D55: 2
B56: 3 | D56: 3
...

Sheet 1983
A1: January | B1: April | C1: July | D1: October | G1: parfumes: | H1: 5 | I1: 16 | J1: 1 | K1: 23 | M1: small luxury
A2: 3 | B2: 3 | C2: 2 | D2: 3 | G2: cosmetics | H2: 42 | I2: 54 | J2: 24 | K2: 42 | M2: =SUM(H1:K6) -> 437
A3: 4 | B3: 3 | C3: 3 | D3: 3 | G3: lipstick | H3: 13 | I3: 16 | J3: 18 | K3: 29
A4: 3 | B4: 4 | C4: 3 | D4: 3 | G4: lotions, skin care, hand creams | H4: 32 | I4: 27 | J4: 10 | K4: 29
A5: 3 | B5: 2 | C5: 4 | D5: 3 | G5: nail polist, | H5: 21 | I5: 5 | J5: 17 | K5: 13
A6: 3 | B6: 3 | C6: 3 | D6: 5 | G6: candles
A7: 3 | B7: 2 | C7: 2 | D7: 2
A8: 4 | B8: 2 | C8: 3 | D8: 6 | G8: bags | H8: 14 | I8: 8 | J8: 1 | K8: 25 | M8: high luxury
A9: 4 | B9: 4 | C9: 3 | D9: 3 | G9: watches | H9: 3 | I9: 8 | J9: 5 | K9: 19 | M9: =SUM(H8:K13) -> 442
A10: 3 | B10: 4 | C10: 3 | D10: 5 | G10: dining
A11: 3 | B11: 3 | C11: 4 | D11: 4 | G11: jewellery | H11: 15 | I11: 42 | J11: 38 | K11: 72
A12: 4 | B12: 4 | C12: 5 | D12: 3 | G12: travel
A13: 5 | B13: 6 | C13: 5 | D13: 4 | G13: hats | H13: 23 | I13: 55 | J13: 37 | K13: 77
A14: 3 | B14: 2 | C14: 3 | D14: 5
A15: 3 | B15: 1 | C15: 6 | D15: 5
A16: 3 | B16: 5 | C16: 3 | D16: 2
A17: 2 | B17: 4 | C17: 3 | D17: 3
A18: 3 | B18: 5 | C18: 6 | D18: 3
A19: 5 | B19: 3 | C19: 6 | D19: 2
A20: 5 | B20: 3 | C20: 2 | D20: 2
A21: 4 | B21: 3 | C21: 5 | D21: 2
A22: 3 | B22: 3 | C22: 6 | D22: 1
A23: 2 | B23: 3 | C23: 3 | D23: 3
A24: 3 | B24: 4 | C24: 5 | D24: 3
A25: 2 | B25: 4 | C25: 5 | D25: 2
... A38: 2 | B38: 4 | C38: 3 | D38: 3
B39: 2 | C39: 5 | D39: 1
B40: 2 | C40: 4 | D40: 2
B41: 3 | C41: 3 | D41: 6
B42: 5 | C42: 3 | D42: 4
B43: 2 | C43: 3 | D43: 3
B44: 6 | C44: 3 | D44: 3
B45: 3 | C45: 3 | D45: 3
B46: 4 | C46: 3 | D46: 5
B47: 3 | C47: 3 | D47: 2
B48: 6 | C48: 4 | D48: 3
B49: 4 | C49: 3 | D49: 4
B50: 4 | C50: 3 | D50: 2
... B53: 4 | C53: 5 | D53: 5
B54: 4 | D54: 2
...

Sheet 1984
A1: January | B1: April | C1: July | D1: October | G1: parfumes: | H1: 1 | I1: 24 | J1: 3 | K1: 23 | M1: small luxury
A2: 4 | B2: 2 | C2: 3 | D2: 3 | G2: cosmetics | H2: 26 | I2: 43 | J2: 54 | K2: 60 | M2: =SUM(H1:K6) -> 426
A3: 5 | B3: 2 | C3: 3 | D3: 5 | G3: lipstick | H3: 19 | I3: 6 | J3: 12 | K3: 22
A4: 5 | B4: 2 | C4: 4 | D4: 5 | G4: lotions, skin care, hand creams | H4: 36 | I4: 8 | J4: 22 | K4: 9
A5: 5 | B5: 3 | C5: 3 | D5: 3 | G5: nail polist, | H5: 1 | I5: 22 | J5: 23 | K5: 12
A6: 4 | B6: 3 | C6: 4 | D6: 4 | G6: candles
A7: 5 | B7: 3 | C7: 2 | D7: 5
A8: 3 | B8: 4 | C8: 2 | D8: 5 | G8: bags | H8: 6 | I8: 9 | J8: 3 | K8: 12 | M8: high luxury
A9: 3 | B9: 3 | C9: 4 | D9: 3 | G9: watches | H9: 2 | I9: 10 | J9: 3 | K9: 49 | M9: =SUM(H8:K13) -> 445
A10: 3 | B10: 3 | C10: 4 | D10: 4 | G10: dining
A11: 5 | B11: 3 | C11: 4 | D11: 4 | G11: jewellery | H11: 5 | I11: 38 | J11: 31 | K11: 82
A12: 5 | B12: 4 | C12: 3 | D12: 3 | G12: travel | J12: 1
A13: 3 | B13: 4 | C13: 4 | D13: 3 | G13: hats | H13: 19 | I13: 62 | J13: 32 | K13: 81
A14: 3 | B14: 5 | C14: 5 | D14: 3
A15: 3 | B15: 5 | C15: 4 | D15: 4
A16: 3 | B16: 4 | C16: 4 | D16: 5
A17: 3 | B17: 2 | C17: 3 | D17: 4
A18: 4 | B18: 5 | C18: 4 | D18: 5
A19: 5 | B19: 4 | C19: 5 | D19: 4
A20: 2 | B20: 5 | C20: 5 | D20: 4
A21: 2 | B21: 6 | C21: 5 | D21: 4
A22: 4 | B22: 6 | C22: 5 | D22: 3
A23: 6 | B23: 5 | C23: 3 | D23: 4
A24: 6 | B24: 3 | C24: 3 | D24: 4
A25: 6 | B25: 6 | C25: 4 | D25: 3
... A33: 4 | B33: 4 | C33: 4 | D33: 3
A34: 5 | B34: 4 | D34: 2
A35: 2 | B35: 2 | D35: 2
A36: 5 | B36: 5 | D36: 4
A37: 5 | B37: 4 | D37: 4
A38: 5 | B38: 4 | D38: 3
A39: 3 | B39: 5 | D39: 4
A40: 4 | B40: 4 | D40: 4
A41: 3 | B41: 3 | D41: 6
A42: 3 | B42: 5 | D42: 4
A43: 3 | B43: 2 | D43: 2
B44: 3 | D44: 3
B45: 3 | D45: 3
B46: 3 | D46: 5
B47: 4 | D47: 5
...

Sheet 1985
A1: January | B1: April | C1: July | D1: October | G1: parfumes: | H1: 4 | I1: 13 | J1: 3 | K1: 32 | M1: small luxury
A2: 4 | B2: 3 | C2: 3 | D2: 5 | G2: cosmetics | H2: 30 | I2: 79 | J2: 48 | K2: 72 | M2: =SUM(H1:K6) -> 563
A3: 5 | B3: 3 | C3: 4 | D3: 3 | G3: lipstick | H3: 13 | I3: 33 | J3: 16 | K3: 17
A4: 3 | B4: 6 | C4: 3 | D4: 2 | G4: lotions, skin care, hand creams | H4: 29 | I4: 2 | J4: 1 | K4: 52
A5: 5 | B5: 2 | C5: 3 | D5: 2 | G5: nail polist, | H5: 36 | I5: 31 | J5: 33 | K5: 19
A6: 5 | B6: 4 | C6: 6 | D6: 5 | G6: candles
A7: 5 | B7: 4 | C7: 6 | D7: 5
A8: 5 | B8: 3 | C8: 1 | D8: 5 | G8: bags | H8: 7 | I8: 7 | J8: 6 | K8: 17 | M8: high luxury
A9: 4 | B9: 5 | C9: 6 | D9: 5 | G9: watches | H9: 9 | I9: 14 | J9: 2 | K9: 28 | M9: =SUM(H8:K13) -> 424
A10: 3 | B10: 3 | C10: 4 | D10: 5 | G10: dining
A11: 3 | B11: 3 | C11: 6 | D11: 6 | G11: jewellery | H11: 30 | I11: 50 | J11: 41 | K11: 78
A12: 4 | B12: 4 | C12: 6 | D12: 6 | G12: travel | I12: 4 | J12: 5
A13: 4 | B13: 5 | C13: 6 | D13: 5 | G13: hats | H13: 12 | I13: 35 | J13: 28 | K13: 51
A14: 3 | B14: 3 | C14: 5 | D14: 5
A15: 5 | B15: 4 | C15: 4 | D15: 4
A16: 3 | B16: 4 | C16: 5 | D16: 5
A17: 3 | B17: 5 | C17: 5 | D17: 4
A18: 4 | B18: 3 | C18: 6 | D18: 4
A19: 3 | B19: 5 | C19: 2 | D19: 3
A20: 4 | B20: 6 | C20: 2 | D20: 4
A21: 5 | B21: 3 | C21: 2 | D21: 4
A22: 3 | B22: 3 | C22: 3 | D22: 3
A23: 5 | B23: 5 | C23: 4 | D23: 2
A24: 3 | B24: 6 | C24: 3 | D24: 3
A25: 3 | B25: 5 | C25: 2 | D25: 2
... A34: 3 | B34: 5 | C34: 1 | D34: 5
A35: 3 | B35: 5 | D35: 4
A36: 2 | B36: 3 | D36: 3
A37: 2 | B37: 3 | D37: 3
A38: 3 | B38: 4 | D38: 3
A39: 3 | B39: 3 | D39: 3
A40: 2 | B40: 5 | D40: 3
A41: 5 | B41: 3 | D41: 3
A42: 4 | B42: 1 | D42: 4
A43: 3 | B43: 4 | D43: 4
A44: 3 | B44: 3 | D44: 3
A45: 3 | B45: 4 | D45: 2
A46: 2 | B46: 3 | D46: 3
... A48: 3 | B48: 4 | D48: 3
A49: 3 | D49: 4
...

Sheet 1986
A1: January | B1: April | C1: July | D1: October | G1: parfumes: | H1: 3 | I1: 15 | K1: 23 | M1: small luxury
A2: 3 | B2: 2 | C2: 1 | D2: 6 | G2: cosmetics | H2: 46 | I2: 51 | J2: 38 | K2: 61 | M2: =SUM(H1:K6) -> 416
A3: 5 | B3: 5 | C3: 3 | D3: 5 | G3: lipstick | H3: 7 | I3: 9 | K3: 19
A4: 3 | B4: 6 | C4: 4 | D4: 3 | G4: lotions, skin care, hand creams | H4: 12 | I4: 20 | J4: 27 | K4: 39
A5: 3 | B5: 5 | C5: 3 | D5: 6 | G5: nail polist, | H5: 4 | I5: 29 | K5: 13
A6: 4 | B6: 4 | C6: 3 | D6: 4 | G6: candles
A7: 3 | B7: 6 | C7: 3 | D7: 4
A8: 6 | B8: 5 | C8: 2 | D8: 3 | G8: bags | H8: 10 | I8: 5 | J8: 2 | K8: 15 | M8: high luxury
A9: 5 | B9: 3 | C9: 3 | D9: 4 | G9: watches | I9: 14 | K9: 55 | M9: =SUM(H8:K13) -> 467
